Workbook

Sheet HTTK1
A1: HỆ THỐNG TÀI KHOẢN CẤP 1
A3: TK | B3: Loại TK | C3: TÊN TK | D3: SDDK1 | E3: DKNO1 | F3: DKCO1
A4: 1 | B4: 2 | C4: 3 | D4: 4 | E4: 5 | F4: 6
A5: 111 | B5: N | C5: Tiền Mặt
A6: 112 | B6: N | C6: Tiền gửi Ngân Hàng
A7: 113 | B7: N | C7: Tiền đang chuyển
A8: 121 | B8: N | C8: Chứng khoán kinh doanh
A9: 128 | B9: N | C9: Đầu tư nắm giữ đến ngày đáo hạn
A10: 131 | B10: N | C10: Phải thu của khách hàng
A11: 133 | B11: N | C11: Thuế GTGT được khấu trừ
A12: 136 | B12: N | C12: Phải thu nội bộ
A13: 138 | B13: N | C13: Phải thu khác
A14: 141 | B14: N | C14: Tạm ứng
A15: 151 | B15: N | C15: Hàng mua đang đi đường
A16: 152 | B16: N | C16: Nguyên liệu, vật liệu
... A80: 911 | B80: C | C80: Xác định kết quả kinh doanh
E81: =SUM(E5:E80) -> 0 | F81: =SUM(F5:F80) -> 0

Sheet DMTK
E1: BẢNG DANH MỤC TÀI KHOẢN
A3: MÃ TS-NV | B3: SHTK | C3: Loại TK | D3: TÊN TK | E3: TỒN DK | F3: SDD | G3: PSNO | H3: PSCO | I3: TỒN CK | J3: SDC | K3: DDNO | L3: DDCO | M3: MaTSNVDN | N3: SODN | O3: MaTSNVCK | P3: SOCK | Q3: ĐVT
A4: 0 | B4: 1 | C4: 2 | D4: 3 | E4: 4 | F4: 5 | G4: 6 | H4: 7 | I4: 8 | J4: 9 | K4: 10 | L4: 11 | M4: 12 | N4: 13 | O4: 14 | P4: 15 | Q4: 16
A5: 100.110.111 | B5: 1111 | C5: N | D5: Tiền Việt Nam | F5: 400000000 | G5: =SUMIFS(CT!$H$5:$H$143,CT!$D$5:$D$143,DMTK!$B5) -> 25200000 | H5: =SUMIFS(CT!$H$5:$H$143,CT!$E$5:$E$143,DMTK!$B5) -> 404100000 | J5: =IF(C5="N",F5+G5-H5,F5+H5-G5) -> 21100000 | M5: =IF(AND(LEFT(B5,4)="1311",F5<0),"300.310.312",IF(AND(LEFT(B5,3)="138",F5<0),"300.310.319",IF(AND(LEFT(B5,4)="3311",F5<0),"100.130.132",IF(AND(LEFT(B5,3)="333",F5<0),"100.150.153",IF(AND(LEFT(B5,3)="337",F5<0),"100.130.134",A5))))) -> 100.110.111 | N5: =IF(OR(AND(LEFT(B5,4)="1311",F5<0),AND(LEFT(B5,3)="138",F5<0),AND(LEFT(B5,4)="3311",F5<0),AND(LEFT(B5,3)="333",F5<0),AND(LEFT(B5,3)="337",F5<0),LEFT(B5,3)="214",LEFT(B5,3)="229",LEFT(B5,3)="419",AND(LEFT(B5,3)="421",F5<0)),-1,1)*F5 -> 400000000 | O5: =IF(AND(LEFT(B5,4)="1311",J5<0),"300.310.312",IF(AND(LEFT(B5,3)="138",J5<0),"300.310.319",IF(AND(LEFT(B5,4)="3311",J5<0),"100.130.132",IF(AND(LEFT(B5,3)="333",J5<0),"100.150.153",IF(AND(LEFT(B5,3)="337",J5<0),"100.130.134",A5))))) -> 100.110.111 | P5: =IF(OR(AND(LEFT(B5,4)="1311",J5<0),AND(LEFT(B5,3)="138",J5<0),AND(LEFT(B5,4)="3311",J5<0),AND(LEFT(B5,3)="333",J5<0),AND(LEFT(B5,3)="337",J5<0),LEFT(B5,3)="214",LEFT(B5,3)="229",LEFT(B5,3)="419",AND(LEFT(B5,3)="421",F5<0)),-1,1)*J5 -> 21100000
A6: 100.110.111 | B6: 1112 | C6: N | D6: Ngoại tệ | F6: 0 | G6: =SUMIFS(CT!$H$5:$H$143,CT!$D$5:$D$143,DMTK!$B6) -> 0 | H6: =SUMIFS(CT!$H$5:$H$143,CT!$E$5:$E$143,DMTK!$B6) -> 0 | J6: =IF(C6="N",F6+G6-H6,F6+H6-G6) -> 0 | M6: =IF(AND(LEFT(B6,4)="1311",F6<0),"300.310.312",IF(AND(LEFT(B6,3)="138",F6<0),"300.310.319",IF(AND(LEFT(B6,4)="3311",F6<0),"100.130.132",IF(AND(LEFT(B6,3)="333",F6<0),"100.150.153",IF(AND(LEFT(B6,3)="337",F6<0),"100.130.134",A6))))) -> 100.110.111 | N6: =IF(OR(AND(LEFT(B6,4)="1311",F6<0),AND(LEFT(B6,3)="138",F6<0),AND(LEFT(B6,4)="3311",F6<0),AND(LEFT(B6,3)="333",F6<0),AND(LEFT(B6,3)="337",F6<0),LEFT(B6,3)="214",LEFT(B6,3)="229",LEFT(B6,3)="419",AND(LEFT(B6,3)="421",F6<0)),-1,1)*F6 -> 0 | O6: =IF(AND(LEFT(B6,4)="1311",J6<0),"300.310.312",IF(AND(LEFT(B6,3)="138",J6<0),"300.310.319",IF(AND(LEFT(B6,4)="3311",J6<0),"100.130.132",IF(AND(LEFT(B6,3)="333",J6<0),"100.150.153",IF(AND(LEFT(B6,3)="337",J6<0),"100.130.134",A6))))) -> 100.110.111 | P6: =IF(OR(AND(LEFT(B6,4)="1311",J6<0),AND(LEFT(B6,3)="138",J6<0),AND(LEFT(B6,4)="3311",J6<0),AND(LEFT(B6,3)="333",J6<0),AND(LEFT(B6,3)="337",J6<0),LEFT(B6,3)="214",LEFT(B6,3)="229",LEFT(B6,3)="419",AND(LEFT(B6,3)="421",F6<0)),-1,1)*J6 -> 0
A7: 100.110.111 | B7: 1113 | C7: N | D7: Vàng tiền tệ | F7: 0 | G7: =SUMIFS(CT!$H$5:$H$143,CT!$D$5:$D$143,DMTK!$B7) -> 0 | H7: =SUMIFS(CT!$H$5:$H$143,CT!$E$5:$E$143,DMTK!$B7) -> 0 | J7: =IF(C7="N",F7+G7-H7,F7+H7-G7) -> 0 | M7: =IF(AND(LEFT(B7,4)="1311",F7<0),"300.310.312",IF(AND(LEFT(B7,3)="138",F7<0),"300.310.319",IF(AND(LEFT(B7,4)="3311",F7<0),"100.130.132",IF(AND(LEFT(B7,3)="333",F7<0),"100.150.153",IF(AND(LEFT(B7,3)="337",F7<0),"100.130.134",A7))))) -> 100.110.111 | N7: =IF(OR(AND(LEFT(B7,4)="1311",F7<0),AND(LEFT(B7,3)="138",F7<0),AND(LEFT(B7,4)="3311",F7<0),AND(LEFT(B7,3)="333",F7<0),AND(LEFT(B7,3)="337",F7<0),LEFT(B7,3)="214",LEFT(B7,3)="229",LEFT(B7,3)="419",AND(LEFT(B7,3)="421",F7<0)),-1,1)*F7 -> 0 | O7: =IF(AND(LEFT(B7,4)="1311",J7<0),"300.310.312",IF(AND(LEFT(B7,3)="138",J7<0),"300.310.319",IF(AND(LEFT(B7,4)="3311",J7<0),"100.130.132",IF(AND(LEFT(B7,3)="333",J7<0),"100.150.153",IF(AND(LEFT(B7,3)="337",J7<0),"100.130.134",A7))))) -> 100.110.111 | P7: =IF(OR(AND(LEFT(B7,4)="1311",J7<0),AND(LEFT(B7,3)="138",J7<0),AND(LEFT(B7,4)="3311",J7<0),AND(LEFT(B7,3)="333",J7<0),AND(LEFT(B7,3)="337",J7<0),LEFT(B7,3)="214",LEFT(B7,3)="229",LEFT(B7,3)="419",AND(LEFT(B7,3)="421",F7<0)),-1,1)*J7 -> 0
A8: 100.110.111 | B8: 1121.01 | C8: N | D8: Tiền Việt Nam NH Ngoại Thương | F8: 258221000 | G8: =SUMIFS(CT!$H$5:$H$143,CT!$D$5:$D$143,DMTK!$B8) -> 0 | H8: =SUMIFS(CT!$H$5:$H$143,CT!$E$5:$E$143,DMTK!$B8) -> 90000000 | J8: =IF(C8="N",F8+G8-H8,F8+H8-G8) -> 168221000 | M8: =IF(AND(LEFT(B8,4)="1311",F8<0),"300.310.312",IF(AND(LEFT(B8,3)="138",F8<0),"300.310.319",IF(AND(LEFT(B8,4)="3311",F8<0),"100.130.132",IF(AND(LEFT(B8,3)="333",F8<0),"100.150.153",IF(AND(LEFT(B8,3)="337",F8<0),"100.130.134",A8))))) -> 100.110.111 | N8: =IF(OR(AND(LEFT(B8,4)="1311",F8<0),AND(LEFT(B8,3)="138",F8<0),AND(LEFT(B8,4)="3311",F8<0),AND(LEFT(B8,3)="333",F8<0),AND(LEFT(B8,3)="337",F8<0),LEFT(B8,3)="214",LEFT(B8,3)="229",LEFT(B8,3)="419",AND(LEFT(B8,3)="421",F8<0)),-1,1)*F8 -> 258221000 | O8: =IF(AND(LEFT(B8,4)="1311",J8<0),"300.310.312",IF(AND(LEFT(B8,3)="138",J8<0),"300.310.319",IF(AND(LEFT(B8,4)="3311",J8<0),"100.130.132",IF(AND(LEFT(B8,3)="333",J8<0),"100.150.153",IF(AND(LEFT(B8,3)="337",J8<0),"100.130.134",A8))))) -> 100.110.111 | P8: =IF(OR(AND(LEFT(B8,4)="1311",J8<0),AND(LEFT(B8,3)="138",J8<0),AND(LEFT(B8,4)="3311",J8<0),AND(LEFT(B8,3)="333",J8<0),AND(LEFT(B8,3)="337",J8<0),LEFT(B8,3)="214",LEFT(B8,3)="229",LEFT(B8,3)="419",AND(LEFT(B8,3)="421",F8<0)),-1,1)*J8 -> 168221000
A9: 100.110.111 | B9: 1121.02 | C9: N | D9: Tiền Việt Nam NH Đông Á | F9: 60000000 | G9: =SUMIFS(CT!$H$5:$H$143,CT!$D$5:$D$143,DMTK!$B9) -> 30000000 | H9: =SUMIFS(CT!$H$5:$H$143,CT!$E$5:$E$143,DMTK!$B9) -> 0 | J9: =IF(C9="N",F9+G9-H9,F9+H9-G9) -> 90000000 | M9: =IF(AND(LEFT(B9,4)="1311",F9<0),"300.310.312",IF(AND(LEFT(B9,3)="138",F9<0),"300.310.319",IF(AND(LEFT(B9,4)="3311",F9<0),"100.130.132",IF(AND(LEFT(B9,3)="333",F9<0),"100.150.153",IF(AND(LEFT(B9,3)="337",F9<0),"100.130.134",A9))))) -> 100.110.111 | N9: =IF(OR(AND(LEFT(B9,4)="1311",F9<0),AND(LEFT(B9,3)="138",F9<0),AND(LEFT(B9,4)="3311",F9<0),AND(LEFT(B9,3)="333",F9<0),AND(LEFT(B9,3)="337",F9<0),LEFT(B9,3)="214",LEFT(B9,3)="229",LEFT(B9,3)="419",AND(LEFT(B9,3)="421",F9<0)),-1,1)*F9 -> 60000000 | O9: =IF(AND(LEFT(B9,4)="1311",J9<0),"300.310.312",IF(AND(LEFT(B9,3)="138",J9<0),"300.310.319",IF(AND(LEFT(B9,4)="3311",J9<0),"100.130.132",IF(AND(LEFT(B9,3)="333",J9<0),"100.150.153",IF(AND(LEFT(B9,3)="337",J9<0),"100.130.134",A9))))) -> 100.110.111 | P9: =IF(OR(AND(LEFT(B9,4)="1311",J9<0),AND(LEFT(B9,3)="138",J9<0),AND(LEFT(B9,4)="3311",J9<0),AND(LEFT(B9,3)="333",J9<0),AND(LEFT(B9,3)="337",J9<0),LEFT(B9,3)="214",LEFT(B9,3)="229",LEFT(B9,3)="419",AND(LEFT(B9,3)="421",F9<0)),-1,1)*J9 -> 90000000
A10: 100.110.111 | B10: 1121.03 | C10: N | D10: Tiền Việt Nam NH Á Châu | F10: 40000000 | G10: =SUMIFS(CT!$H$5:$H$143,CT!$D$5:$D$143,DMTK!$B10) -> 0 | H10: =SUMIFS(CT!$H$5:$H$143,CT!$E$5:$E$143,DMTK!$B10) -> 0 | J10: =IF(C10="N",F10+G10-H10,F10+H10-G10) -> 40000000 | M10: =IF(AND(LEFT(B10,4)="1311",F10<0),"300.310.312",IF(AND(LEFT(B10,3)="138",F10<0),"300.310.319",IF(AND(LEFT(B10,4)="3311",F10<0),"100.130.132",IF(AND(LEFT(B10,3)="333",F10<0),"100.150.153",IF(AND(LEFT(B10,3)="337",F10<0),"100.130.134",A10))))) -> 100.110.111 | N10: =IF(OR(AND(LEFT(B10,4)="1311",F10<0),AND(LEFT(B10,3)="138",F10<0),AND(LEFT(B10,4)="3311",F10<0),AND(LEFT(B10,3)="333",F10<0),AND(LEFT(B10,3)="337",F10<0),LEFT(B10,3)="214",LEFT(B10,3)="229",LEFT(B10,3)="419",AND(LEFT(B10,3)="421",F10<0)),-1,1)*F10 -> 40000000 | O10: =IF(AND(LEFT(B10,4)="1311",J10<0),"300.310.312",IF(AND(LEFT(B10,3)="138",J10<0),"300.310.319",IF(AND(LEFT(B10,4)="3311",J10<0),"100.130.132",IF(AND(LEFT(B10,3)="333",J10<0),"100.150.153",IF(AND(LEFT(B10,3)="337",J10<0),"100.130.134",A10))))) -> 100.110.111 | P10: =IF(OR(AND(LEFT(B10,4)="1311",J10<0),AND(LEFT(B10,3)="138",J10<0),AND(LEFT(B10,4)="3311",J10<0),AND(LEFT(B10,3)="333",J10<0),AND(LEFT(B10,3)="337",J10<0),LEFT(B10,3)="214",LEFT(B10,3)="229",LEFT(B10,3)="419",AND(LEFT(B10,3)="421",F10<0)),-1,1)*J10 -> 40000000
A11: 100.110.111 | B11: 1122 | C11: N | D11: Ngoại tệ | F11: 0 | G11: =SUMIFS(CT!$H$5:$H$143,CT!$D$5:$D$143,DMTK!$B11) -> 0 | H11: =SUMIFS(CT!$H$5:$H$143,CT!$E$5:$E$143,DMTK!$B11) -> 0 | J11: =IF(C11="N",F11+G11-H11,F11+H11-G11) -> 0 | M11: =IF(AND(LEFT(B11,4)="1311",F11<0),"300.310.312",IF(AND(LEFT(B11,3)="138",F11<0),"300.310.319",IF(AND(LEFT(B11,4)="3311",F11<0),"100.130.132",IF(AND(LEFT(B11,3)="333",F11<0),"100.150.153",IF(AND(LEFT(B11,3)="337",F11<0),"100.130.134",A11))))) -> 100.110.111 | N11: =IF(OR(AND(LEFT(B11,4)="1311",F11<0),AND(LEFT(B11,3)="138",F11<0),AND(LEFT(B11,4)="3311",F11<0),AND(LEFT(B11,3)="333",F11<0),AND(LEFT(B11,3)="337",F11<0),LEFT(B11,3)="214",LEFT(B11,3)="229",LEFT(B11,3)="419",AND(LEFT(B11,3)="421",F11<0)),-1,1)*F11 -> 0 | O11: =IF(AND(LEFT(B11,4)="1311",J11<0),"300.310.312",IF(AND(LEFT(B11,3)="138",J11<0),"300.310.319",IF(AND(LEFT(B11,4)="3311",J11<0),"100.130.132",IF(AND(LEFT(B11,3)="333",J11<0),"100.150.153",IF(AND(LEFT(B11,3)="337",J11<0),"100.130.134",A11))))) -> 100.110.111 | P11: =IF(OR(AND(LEFT(B11,4)="1311",J11<0),AND(LEFT(B11,3)="138",J11<0),AND(LEFT(B11,4)="3311",J11<0),AND(LEFT(B11,3)="333",J11<0),AND(LEFT(B11,3)="337",J11<0),LEFT(B11,3)="214",LEFT(B11,3)="229",LEFT(B11,3)="419",AND(LEFT(B11,3)="421",F11<0)),-1,1)*J11 -> 0
A12: 100.110.111 | B12: 1123 | C12: N | D12: Vàng tiền tệ | F12: 0 | G12: =SUMIFS(CT!$H$5:$H$143,CT!$D$5:$D$143,DMTK!$B12) -> 0 | H12: =SUMIFS(CT!$H$5:$H$143,CT!$E$5:$E$143,DMTK!$B12) -> 0 | J12: =IF(C12="N",F12+G12-H12,F12+H12-G12) -> 0 | M12: =IF(AND(LEFT(B12,4)="1311",F12<0),"300.310.312",IF(AND(LEFT(B12,3)="138",F12<0),"300.310.319",IF(AND(LEFT(B12,4)="3311",F12<0),"100.130.132",IF(AND(LEFT(B12,3)="333",F12<0),"100.150.153",IF(AND(LEFT(B12,3)="337",F12<0),"100.130.134",A12))))) -> 100.110.111 | N12: =IF(OR(AND(LEFT(B12,4)="1311",F12<0),AND(LEFT(B12,3)="138",F12<0),AND(LEFT(B12,4)="3311",F12<0),AND(LEFT(B12,3)="333",F12<0),AND(LEFT(B12,3)="337",F12<0),LEFT(B12,3)="214",LEFT(B12,3)="229",LEFT(B12,3)="419",AND(LEFT(B12,3)="421",F12<0)),-1,1)*F12 -> 0 | O12: =IF(AND(LEFT(B12,4)="1311",J12<0),"300.310.312",IF(AND(LEFT(B12,3)="138",J12<0),"300.310.319",IF(AND(LEFT(B12,4)="3311",J12<0),"100.130.132",IF(AND(LEFT(B12,3)="333",J12<0),"100.150.153",IF(AND(LEFT(B12,3)="337",J12<0),"100.130.134",A12))))) -> 100.110.111 | P12: =IF(OR(AND(LEFT(B12,4)="1311",J12<0),AND(LEFT(B12,3)="138",J12<0),AND(LEFT(B12,4)="3311",J12<0),AND(LEFT(B12,3)="333",J12<0),AND(LEFT(B12,3)="337",J12<0),LEFT(B12,3)="214",LEFT(B12,3)="229",LEFT(B12,3)="419",AND(LEFT(B12,3)="421",F12<0)),-1,1)*J12 -> 0
A13: 100.110.111 | B13: 1131 | C13: N | D13: Tiền Việt Nam | F13: 0 | G13: =SUMIFS(CT!$H$5:$H$143,CT!$D$5:$D$143,DMTK!$B13) -> 0 | H13: =SUMIFS(CT!$H$5:$H$143,CT!$E$5:$E$143,DMTK!$B13) -> 0 | J13: =IF(C13="N",F13+G13-H13,F13+H13-G13) -> 0 | M13: =IF(AND(LEFT(B13,4)="1311",F13<0),"300.310.312",IF(AND(LEFT(B13,3)="138",F13<0),"300.310.319",IF(AND(LEFT(B13,4)="3311",F13<0),"100.130.132",IF(AND(LEFT(B13,3)="333",F13<0),"100.150.153",IF(AND(LEFT(B13,3)="337",F13<0),"100.130.134",A13))))) -> 100.110.111 | N13: =IF(OR(AND(LEFT(B13,4)="1311",F13<0),AND(LEFT(B13,3)="138",F13<0),AND(LEFT(B13,4)="3311",F13<0),AND(LEFT(B13,3)="333",F13<0),AND(LEFT(B13,3)="337",F13<0),LEFT(B13,3)="214",LEFT(B13,3)="229",LEFT(B13,3)="419",AND(LEFT(B13,3)="421",F13<0)),-1,1)*F13 -> 0 | O13: =IF(AND(LEFT(B13,4)="1311",J13<0),"300.310.312",IF(AND(LEFT(B13,3)="138",J13<0),"300.310.319",IF(AND(LEFT(B13,4)="3311",J13<0),"100.130.132",IF(AND(LEFT(B13,3)="333",J13<0),"100.150.153",IF(AND(LEFT(B13,3)="337",J13<0),"100.130.134",A13))))) -> 100.110.111 | P13: =IF(OR(AND(LEFT(B13,4)="1311",J13<0),AND(LEFT(B13,3)="138",J13<0),AND(LEFT(B13,4)="3311",J13<0),AND(LEFT(B13,3)="333",J13<0),AND(LEFT(B13,3)="337",J13<0),LEFT(B13,3)="214",LEFT(B13,3)="229",LEFT(B13,3)="419",AND(LEFT(B13,3)="421",F13<0)),-1,1)*J13 -> 0
A14: 100.110.111 | B14: 1132 | C14: N | D14: Ngoại tệ | G14: =SUMIFS(CT!$H$5:$H$143,CT!$D$5:$D$143,DMTK!$B14) -> 0 | H14: =SUMIFS(CT!$H$5:$H$143,CT!$E$5:$E$143,DMTK!$B14) -> 0 | J14: =IF(C14="N",F14+G14-H14,F14+H14-G14) -> 0 | M14: =IF(AND(LEFT(B14,4)="1311",F14<0),"300.310.312",IF(AND(LEFT(B14,3)="138",F14<0),"300.310.319",IF(AND(LEFT(B14,4)="3311",F14<0),"100.130.132",IF(AND(LEFT(B14,3)="333",F14<0),"100.150.153",IF(AND(LEFT(B14,3)="337",F14<0),"100.130.134",A14))))) -> 100.110.111 | N14: =IF(OR(AND(LEFT(B14,4)="1311",F14<0),AND(LEFT(B14,3)="138",F14<0),AND(LEFT(B14,4)="3311",F14<0),AND(LEFT(B14,3)="333",F14<0),AND(LEFT(B14,3)="337",F14<0),LEFT(B14,3)="214",LEFT(B14,3)="229",LEFT(B14,3)="419",AND(LEFT(B14,3)="421",F14<0)),-1,1)*F14 -> 0 | O14: =IF(AND(LEFT(B14,4)="1311",J14<0),"300.310.312",IF(AND(LEFT(B14,3)="138",J14<0),"300.310.319",IF(AND(LEFT(B14,4)="3311",J14<0),"100.130.132",IF(AND(LEFT(B14,3)="333",J14<0),"100.150.153",IF(AND(LEFT(B14,3)="337",J14<0),"100.130.134",A14))))) -> 100.110.111 | P14: =IF(OR(AND(LEFT(B14,4)="1311",J14<0),AND(LEFT(B14,3)="138",J14<0),AND(LEFT(B14,4)="3311",J14<0),AND(LEFT(B14,3)="333",J14<0),AND(LEFT(B14,3)="337",J14<0),LEFT(B14,3)="214",LEFT(B14,3)="229",LEFT(B14,3)="419",AND(LEFT(B14,3)="421",F14<0)),-1,1)*J14 -> 0
A15: 100.120.121 | B15: 1211 | C15: N | D15: Cổ phiếu | F15: 0 | G15: =SUMIFS(CT!$H$5:$H$143,CT!$D$5:$D$143,DMTK!$B15) -> 0 | H15: =SUMIFS(CT!$H$5:$H$143,CT!$E$5:$E$143,DMTK!$B15) -> 0 | J15: =IF(C15="N",F15+G15-H15,F15+H15-G15) -> 0 | M15: =IF(AND(LEFT(B15,4)="1311",F15<0),"300.310.312",IF(AND(LEFT(B15,3)="138",F15<0),"300.310.319",IF(AND(LEFT(B15,4)="3311",F15<0),"100.130.132",IF(AND(LEFT(B15,3)="333",F15<0),"100.150.153",IF(AND(LEFT(B15,3)="337",F15<0),"100.130.134",A15))))) -> 100.120.121 | N15: =IF(OR(AND(LEFT(B15,4)="1311",F15<0),AND(LEFT(B15,3)="138",F15<0),AND(LEFT(B15,4)="3311",F15<0),AND(LEFT(B15,3)="333",F15<0),AND(LEFT(B15,3)="337",F15<0),LEFT(B15,3)="214",LEFT(B15,3)="229",LEFT(B15,3)="419",AND(LEFT(B15,3)="421",F15<0)),-1,1)*F15 -> 0 | O15: =IF(AND(LEFT(B15,4)="1311",J15<0),"300.310.312",IF(AND(LEFT(B15,3)="138",J15<0),"300.310.319",IF(AND(LEFT(B15,4)="3311",J15<0),"100.130.132",IF(AND(LEFT(B15,3)="333",J15<0),"100.150.153",IF(AND(LEFT(B15,3)="337",J15<0),"100.130.134",A15))))) -> 100.120.121 | P15: =IF(OR(AND(LEFT(B15,4)="1311",J15<0),AND(LEFT(B15,3)="138",J15<0),AND(LEFT(B15,4)="3311",J15<0),AND(LEFT(B15,3)="333",J15<0),AND(LEFT(B15,3)="337",J15<0),LEFT(B15,3)="214",LEFT(B15,3)="229",LEFT(B15,3)="419",AND(LEFT(B15,3)="421",F15<0)),-1,1)*J15 -> 0
A16: 100.120.121 | B16: 1212 | C16: N | D16: Trái phiếu | F16: 0 | G16: =SUMIFS(CT!$H$5:$H$143,CT!$D$5:$D$143,DMTK!$B16) -> 0 | H16: =SUMIFS(CT!$H$5:$H$143,CT!$E$5:$E$143,DMTK!$B16) -> 0 | J16: =IF(C16="N",F16+G16-H16,F16+H16-G16) -> 0 | M16: =IF(AND(LEFT(B16,4)="1311",F16<0),"300.310.312",IF(AND(LEFT(B16,3)="138",F16<0),"300.310.319",IF(AND(LEFT(B16,4)="3311",F16<0),"100.130.132",IF(AND(LEFT(B16,3)="333",F16<0),"100.150.153",IF(AND(LEFT(B16,3)="337",F16<0),"100.130.134",A16))))) -> 100.120.121 | N16: =IF(OR(AND(LEFT(B16,4)="1311",F16<0),AND(LEFT(B16,3)="138",F16<0),AND(LEFT(B16,4)="3311",F16<0),AND(LEFT(B16,3)="333",F16<0),AND(LEFT(B16,3)="337",F16<0),LEFT(B16,3)="214",LEFT(B16,3)="229",LEFT(B16,3)="419",AND(LEFT(B16,3)="421",F16<0)),-1,1)*F16 -> 0 | O16: =IF(AND(LEFT(B16,4)="1311",J16<0),"300.310.312",IF(AND(LEFT(B16,3)="138",J16<0),"300.310.319",IF(AND(LEFT(B16,4)="3311",J16<0),"100.130.132",IF(AND(LEFT(B16,3)="333",J16<0),"100.150.153",IF(AND(LEFT(B16,3)="337",J16<0),"100.130.134",A16))))) -> 100.120.121 | P16: =IF(OR(AND(LEFT(B16,4)="1311",J16<0),AND(LEFT(B16,3)="138",J16<0),AND(LEFT(B16,4)="3311",J16<0),AND(LEFT(B16,3)="333",J16<0),AND(LEFT(B16,3)="337",J16<0),LEFT(B16,3)="214",LEFT(B16,3)="229",LEFT(B16,3)="419",AND(LEFT(B16,3)="421",F16<0)),-1,1)*J16 -> 0
A17: 100.110.112 | B17: 12811 | C17: N | D17: Tiền gửi có kỳ hạn (không quá 3 tháng) | F17: 100000000 | G17: =SUMIFS(CT!$H$5:$H$143,CT!$D$5:$D$143,DMTK!$B17) -> 0 | H17: =SUMIFS(CT!$H$5:$H$143,CT!$E$5:$E$143,DMTK!$B17) -> 0 | J17: =IF(C17="N",F17+G17-H17,F17+H17-G17) -> 100000000 | M17: =IF(AND(LEFT(B17,4)="1311",F17<0),"300.310.312",IF(AND(LEFT(B17,3)="138",F17<0),"300.310.319",IF(AND(LEFT(B17,4)="3311",F17<0),"100.130.132",IF(AND(LEFT(B17,3)="333",F17<0),"100.150.153",IF(AND(LEFT(B17,3)="337",F17<0),"100.130.134",A17))))) -> 100.110.112 | N17: =IF(OR(AND(LEFT(B17,4)="1311",F17<0),AND(LEFT(B17,3)="138",F17<0),AND(LEFT(B17,4)="3311",F17<0),AND(LEFT(B17,3)="333",F17<0),AND(LEFT(B17,3)="337",F17<0),LEFT(B17,3)="214",LEFT(B17,3)="229",LEFT(B17,3)="419",AND(LEFT(B17,3)="421",F17<0)),-1,1)*F17 -> 100000000 | O17: =IF(AND(LEFT(B17,4)="1311",J17<0),"300.310.312",IF(AND(LEFT(B17,3)="138",J17<0),"300.310.319",IF(AND(LEFT(B17,4)="3311",J17<0),"100.130.132",IF(AND(LEFT(B17,3)="333",J17<0),"100.150.153",IF(AND(LEFT(B17,3)="337",J17<0),"100.130.134",A17))))) -> 100.110.112 | P17: =IF(OR(AND(LEFT(B17,4)="1311",J17<0),AND(LEFT(B17,3)="138",J17<0),AND(LEFT(B17,4)="3311",J17<0),AND(LEFT(B17,3)="333",J17<0),AND(LEFT(B17,3)="337",J17<0),LEFT(B17,3)="214",LEFT(B17,3)="229",LEFT(B17,3)="419",AND(LEFT(B17,3)="421",F17<0)),-1,1)*J17 -> 100000000
A18: 100.120.123 | B18: 12812 | C18: N | D18: Tiền gửi có kỳ hạn (không quá 12 tháng) | G18: =SUMIFS(CT!$H$5:$H$143,CT!$D$5:$D$143,DMTK!$B18) -> 0 | H18: =SUMIFS(CT!$H$5:$H$143,CT!$E$5:$E$143,DMTK!$B18) -> 0 | J18: =IF(C18="N",F18+G18-H18,F18+H18-G18) -> 0 | M18: =IF(AND(LEFT(B18,4)="1311",F18<0),"300.310.312",IF(AND(LEFT(B18,3)="138",F18<0),"300.310.319",IF(AND(LEFT(B18,4)="3311",F18<0),"100.130.132",IF(AND(LEFT(B18,3)="333",F18<0),"100.150.153",IF(AND(LEFT(B18,3)="337",F18<0),"100.130.134",A18))))) -> 100.120.123 | N18: =IF(OR(AND(LEFT(B18,4)="1311",F18<0),AND(LEFT(B18,3)="138",F18<0),AND(LEFT(B18,4)="3311",F18<0),AND(LEFT(B18,3)="333",F18<0),AND(LEFT(B18,3)="337",F18<0),LEFT(B18,3)="214",LEFT(B18,3)="229",LEFT(B18,3)="419",AND(LEFT(B18,3)="421",F18<0)),-1,1)*F18 -> 0 | O18: =IF(AND(LEFT(B18,4)="1311",J18<0),"300.310.312",IF(AND(LEFT(B18,3)="138",J18<0),"300.310.319",IF(AND(LEFT(B18,4)="3311",J18<0),"100.130.132",IF(AND(LEFT(B18,3)="333",J18<0),"100.150.153",IF(AND(LEFT(B18,3)="337",J18<0),"100.130.134",A18))))) -> 100.120.123 | P18: =IF(OR(AND(LEFT(B18,4)="1311",J18<0),AND(LEFT(B18,3)="138",J18<0),AND(LEFT(B18,4)="3311",J18<0),AND(LEFT(B18,3)="333",J18<0),AND(LEFT(B18,3)="337",J18<0),LEFT(B18,3)="214",LEFT(B18,3)="229",LEFT(B18,3)="419",AND(LEFT(B18,3)="421",F18<0)),-1,1)*J18 -> 0
A19: 100.130.135 | B19: 12831 | C19: N | D19: Cho vay (không quá 12 tháng) | G19: =SUMIFS(CT!$H$5:$H$143,CT!$D$5:$D$143,DMTK!$B19) -> 0 | H19: =SUMIFS(CT!$H$5:$H$143,CT!$E$5:$E$143,DMTK!$B19) -> 0 | J19: =IF(C19="N",F19+G19-H19,F19+H19-G19) -> 0 | M19: =IF(AND(LEFT(B19,4)="1311",F19<0),"300.310.312",IF(AND(LEFT(B19,3)="138",F19<0),"300.310.319",IF(AND(LEFT(B19,4)="3311",F19<0),"100.130.132",IF(AND(LEFT(B19,3)="333",F19<0),"100.150.153",IF(AND(LEFT(B19,3)="337",F19<0),"100.130.134",A19))))) -> 100.130.135 | N19: =IF(OR(AND(LEFT(B19,4)="1311",F19<0),AND(LEFT(B19,3)="138",F19<0),AND(LEFT(B19,4)="3311",F19<0),AND(LEFT(B19,3)="333",F19<0),AND(LEFT(B19,3)="337",F19<0),LEFT(B19,3)="214",LEFT(B19,3)="229",LEFT(B19,3)="419",AND(LEFT(B19,3)="421",F19<0)),-1,1)*F19 -> 0 | O19: =IF(AND(LEFT(B19,4)="1311",J19<0),"300.310.312",IF(AND(LEFT(B19,3)="138",J19<0),"300.310.319",IF(AND(LEFT(B19,4)="3311",J19<0),"100.130.132",IF(AND(LEFT(B19,3)="333",J19<0),"100.150.153",IF(AND(LEFT(B19,3)="337",J19<0),"100.130.134",A19))))) -> 100.130.135 | P19: =IF(OR(AND(LEFT(B19,4)="1311",J19<0),AND(LEFT(B19,3)="138",J19<0),AND(LEFT(B19,4)="3311",J19<0),AND(LEFT(B19,3)="333",J19<0),AND(LEFT(B19,3)="337",J19<0),LEFT(B19,3)="214",LEFT(B19,3)="229",LEFT(B19,3)="419",AND(LEFT(B19,3)="421",F19<0)),-1,1)*J19 -> 0
A20: 200.210.215 | B20: 12832 | C20: N | D20: Cho vay (trên 12 tháng) | G20: =SUMIFS(CT!$H$5:$H$143,CT!$D$5:$D$143,DMTK!$B20) -> 0 | H20: =SUMIFS(CT!$H$5:$H$143,CT!$E$5:$E$143,DMTK!$B20) -> 0 | J20: =IF(C20="N",F20+G20-H20,F20+H20-G20) -> 0 | M20: =IF(AND(LEFT(B20,4)="1311",F20<0),"300.310.312",IF(AND(LEFT(B20,3)="138",F20<0),"300.310.319",IF(AND(LEFT(B20,4)="3311",F20<0),"100.130.132",IF(AND(LEFT(B20,3)="333",F20<0),"100.150.153",IF(AND(LEFT(B20,3)="337",F20<0),"100.130.134",A20))))) -> 200.210.215 | N20: =IF(OR(AND(LEFT(B20,4)="1311",F20<0),AND(LEFT(B20,3)="138",F20<0),AND(LEFT(B20,4)="3311",F20<0),AND(LEFT(B20,3)="333",F20<0),AND(LEFT(B20,3)="337",F20<0),LEFT(B20,3)="214",LEFT(B20,3)="229",LEFT(B20,3)="419",AND(LEFT(B20,3)="421",F20<0)),-1,1)*F20 -> 0 | O20: =IF(AND(LEFT(B20,4)="1311",J20<0),"300.310.312",IF(AND(LEFT(B20,3)="138",J20<0),"300.310.319",IF(AND(LEFT(B20,4)="3311",J20<0),"100.130.132",IF(AND(LEFT(B20,3)="333",J20<0),"100.150.153",IF(AND(LEFT(B20,3)="337",J20<0),"100.130.134",A20))))) -> 200.210.215 | P20: =IF(OR(AND(LEFT(B20,4)="1311",J20<0),AND(LEFT(B20,3)="138",J20<0),AND(LEFT(B20,4)="3311",J20<0),AND(LEFT(B20,3)="333",J20<0),AND(LEFT(B20,3)="337",J20<0),LEFT(B20,3)="214",LEFT(B20,3)="229",LEFT(B20,3)="419",AND(LEFT(B20,3)="421",F20<0)),-1,1)*J20 -> 0
A21: 100.110.112 | B21: 12881 | C21: N | D21: Các khoản đầu tư khác nắm giữ đến ngày đáo hạn | F21: 0 | G21: =SUMIFS(CT!$H$5:$H$143,CT!$D$5:$D$143,DMTK!$B21) -> 0 | H21: =SUMIFS(CT!$H$5:$H$143,CT!$E$5:$E$143,DMTK!$B21) -> 0 | J21: =IF(C21="N",F21+G21-H21,F21+H21-G21) -> 0 | M21: =IF(AND(LEFT(B21,4)="1311",F21<0),"300.310.312",IF(AND(LEFT(B21,3)="138",F21<0),"300.310.319",IF(AND(LEFT(B21,4)="3311",F21<0),"100.130.132",IF(AND(LEFT(B21,3)="333",F21<0),"100.150.153",IF(AND(LEFT(B21,3)="337",F21<0),"100.130.134",A21))))) -> 100.110.112 | N21: =IF(OR(AND(LEFT(B21,4)="1311",F21<0),AND(LEFT(B21,3)="138",F21<0),AND(LEFT(B21,4)="3311",F21<0),AND(LEFT(B21,3)="333",F21<0),AND(LEFT(B21,3)="337",F21<0),LEFT(B21,3)="214",LEFT(B21,3)="229",LEFT(B21,3)="419",AND(LEFT(B21,3)="421",F21<0)),-1,1)*F21 -> 0 | O21: =IF(AND(LEFT(B21,4)="1311",J21<0),"300.310.312",IF(AND(LEFT(B21,3)="138",J21<0),"300.310.319",IF(AND(LEFT(B21,4)="3311",J21<0),"100.130.132",IF(AND(LEFT(B21,3)="333",J21<0),"100.150.153",IF(AND(LEFT(B21,3)="337",J21<0),"100.130.134",A21))))) -> 100.110.112 | P21: =IF(OR(AND(LEFT(B21,4)="1311",J21<0),AND(LEFT(B21,3)="138",J21<0),AND(LEFT(B21,4)="3311",J21<0),AND(LEFT(B21,3)="333",J21<0),AND(LEFT(B21,3)="337",J21<0),LEFT(B21,3)="214",LEFT(B21,3)="229",LEFT(B21,3)="419",AND(LEFT(B21,3)="421",F21<0)),-1,1)*J21 -> 0
A22: 100.120.123 | B22: 12882 | C22: N | D22: Các khoản đầu tư khác nắm giữ đến ngày đáo hạn (không quá 12 tháng) | G22: =SUMIFS(CT!$H$5:$H$143,CT!$D$5:$D$143,DMTK!$B22) -> 0 | H22: =SUMIFS(CT!$H$5:$H$143,CT!$E$5:$E$143,DMTK!$B22) -> 0 | J22: =IF(C22="N",F22+G22-H22,F22+H22-G22) -> 0 | M22: =IF(AND(LEFT(B22,4)="1311",F22<0),"300.310.312",IF(AND(LEFT(B22,3)="138",F22<0),"300.310.319",IF(AND(LEFT(B22,4)="3311",F22<0),"100.130.132",IF(AND(LEFT(B22,3)="333",F22<0),"100.150.153",IF(AND(LEFT(B22,3)="337",F22<0),"100.130.134",A22))))) -> 100.120.123 | N22: =IF(OR(AND(LEFT(B22,4)="1311",F22<0),AND(LEFT(B22,3)="138",F22<0),AND(LEFT(B22,4)="3311",F22<0),AND(LEFT(B22,3)="333",F22<0),AND(LEFT(B22,3)="337",F22<0),LEFT(B22,3)="214",LEFT(B22,3)="229",LEFT(B22,3)="419",AND(LEFT(B22,3)="421",F22<0)),-1,1)*F22 -> 0 | O22: =IF(AND(LEFT(B22,4)="1311",J22<0),"300.310.312",IF(AND(LEFT(B22,3)="138",J22<0),"300.310.319",IF(AND(LEFT(B22,4)="3311",J22<0),"100.130.132",IF(AND(LEFT(B22,3)="333",J22<0),"100.150.153",IF(AND(LEFT(B22,3)="337",J22<0),"100.130.134",A22))))) -> 100.120.123 | P22: =IF(OR(AND(LEFT(B22,4)="1311",J22<0),AND(LEFT(B22,3)="138",J22<0),AND(LEFT(B22,4)="3311",J22<0),AND(LEFT(B22,3)="333",J22<0),AND(LEFT(B22,3)="337",J22<0),LEFT(B22,3)="214",LEFT(B22,3)="229",LEFT(B22,3)="419",AND(LEFT(B22,3)="421",F22<0)),-1,1)*J22 -> 0
A23: 100.130.131 | B23: 1311.01 | C23: N | D23: Công ty Quang Minh (ngắn hạn) | F23: 100000000 | G23: =SUMIFS(CT!$H$5:$H$143,CT!$D$5:$D$143,DMTK!$B23) -> 0 | H23: =SUMIFS(CT!$H$5:$H$143,CT!$E$5:$E$143,DMTK!$B23) -> 20000000 | J23: =IF(C23="N",F23+G23-H23,F23+H23-G23) -> 80000000 | M23: =IF(AND(LEFT(B23,4)="1311",F23<0),"300.310.312",IF(AND(LEFT(B23,3)="138",F23<0),"300.310.319",IF(AND(LEFT(B23,4)="3311",F23<0),"100.130.132",IF(AND(LEFT(B23,3)="333",F23<0),"100.150.153",IF(AND(LEFT(B23,3)="337",F23<0),"100.130.134",A23))))) -> 100.130.131 | N23: =IF(OR(AND(LEFT(B23,4)="1311",F23<0),AND(LEFT(B23,3)="138",F23<0),AND(LEFT(B23,4)="3311",F23<0),AND(LEFT(B23,3)="333",F23<0),AND(LEFT(B23,3)="337",F23<0),LEFT(B23,3)="214",LEFT(B23,3)="229",LEFT(B23,3)="419",AND(LEFT(B23,3)="421",F23<0)),-1,1)*F23 -> 100000000 | O23: =IF(AND(LEFT(B23,4)="1311",J23<0),"300.310.312",IF(AND(LEFT(B23,3)="138",J23<0),"300.310.319",IF(AND(LEFT(B23,4)="3311",J23<0),"100.130.132",IF(AND(LEFT(B23,3)="333",J23<0),"100.150.153",IF(AND(LEFT(B23,3)="337",J23<0),"100.130.134",A23))))) -> 100.130.131 | P23: =IF(OR(AND(LEFT(B23,4)="1311",J23<0),AND(LEFT(B23,3)="138",J23<0),AND(LEFT(B23,4)="3311",J23<0),AND(LEFT(B23,3)="333",J23<0),AND(LEFT(B23,3)="337",J23<0),LEFT(B23,3)="214",LEFT(B23,3)="229",LEFT(B23,3)="419",AND(LEFT(B23,3)="421",F23<0)),-1,1)*J23 -> 80000000
A24: 100.130.131 | B24: 1311.02 | C24: N | D24: Cty TNHH TMDV Mai Anh (ngắn hạn) | F24: 70000000 | G24: =SUMIFS(CT!$H$5:$H$143,CT!$D$5:$D$143,DMTK!$B24) -> 0 | H24: =SUMIFS(CT!$H$5:$H$143,CT!$E$5:$E$143,DMTK!$B24) -> 30000000 | J24: =IF(C24="N",F24+G24-H24,F24+H24-G24) -> 40000000 | M24: =IF(AND(LEFT(B24,4)="1311",F24<0),"300.310.312",IF(AND(LEFT(B24,3)="138",F24<0),"300.310.319",IF(AND(LEFT(B24,4)="3311",F24<0),"100.130.132",IF(AND(LEFT(B24,3)="333",F24<0),"100.150.153",IF(AND(LEFT(B24,3)="337",F24<0),"100.130.134",A24))))) -> 100.130.131 | N24: =IF(OR(AND(LEFT(B24,4)="1311",F24<0),AND(LEFT(B24,3)="138",F24<0),AND(LEFT(B24,4)="3311",F24<0),AND(LEFT(B24,3)="333",F24<0),AND(LEFT(B24,3)="337",F24<0),LEFT(B24,3)="214",LEFT(B24,3)="229",LEFT(B24,3)="419",AND(LEFT(B24,3)="421",F24<0)),-1,1)*F24 -> 70000000 | O24: =IF(AND(LEFT(B24,4)="1311",J24<0),"300.310.312",IF(AND(LEFT(B24,3)="138",J24<0),"300.310.319",IF(AND(LEFT(B24,4)="3311",J24<0),"100.130.132",IF(AND(LEFT(B24,3)="333",J24<0),"100.150.153",IF(AND(LEFT(B24,3)="337",J24<0),"100.130.134",A24))))) -> 100.130.131 | P24: =IF(OR(AND(LEFT(B24,4)="1311",J24<0),AND(LEFT(B24,3)="138",J24<0),AND(LEFT(B24,4)="3311",J24<0),AND(LEFT(B24,3)="333",J24<0),AND(LEFT(B24,3)="337",J24<0),LEFT(B24,3)="214",LEFT(B24,3)="229",LEFT(B24,3)="419",AND(LEFT(B24,3)="421",F24<0)),-1,1)*J24 -> 40000000
A25: 100.130.131 | B25: 1311.03 | C25: N | D25: Cty TNHH Phương Nam (ngắn hạn) | F25: 57000000 | G25: =SUMIFS(CT!$H$5:$H$143,CT!$D$5:$D$143,DMTK!$B25) -> 0 | H25: =SUMIFS(CT!$H$5:$H$143,CT!$E$5:$E$143,DMTK!$B25) -> 5000000 | J25: =IF(C25="N",F25+G25-H25,F25+H25-G25) -> 52000000 | M25: =IF(AND(LEFT(B25,4)="1311",F25<0),"300.310.312",IF(AND(LEFT(B25,3)="138",F25<0),"300.310.319",IF(AND(LEFT(B25,4)="3311",F25<0),"100.130.132",IF(AND(LEFT(B25,3)="333",F25<0),"100.150.153",IF(AND(LEFT(B25,3)="337",F25<0),"100.130.134",A25))))) -> 100.130.131 | N25: =IF(OR(AND(LEFT(B25,4)="1311",F25<0),AND(LEFT(B25,3)="138",F25<0),AND(LEFT(B25,4)="3311",F25<0),AND(LEFT(B25,3)="333",F25<0),AND(LEFT(B25,3)="337",F25<0),LEFT(B25,3)="214",LEFT(B25,3)="229",LEFT(B25,3)="419",AND(LEFT(B25,3)="421",F25<0)),-1,1)*F25 -> 57000000 | O25: =IF(AND(LEFT(B25,4)="1311",J25<0),"300.310.312",IF(AND(LEFT(B25,3)="138",J25<0),"300.310.319",IF(AND(LEFT(B25,4)="3311",J25<0),"100.130.132",IF(AND(LEFT(B25,3)="333",J25<0),"100.150.153",IF(AND(LEFT(B25,3)="337",J25<0),"100.130.134",A25))))) -> 100.130.131 | P25: =IF(OR(AND(LEFT(B25,4)="1311",J25<0),AND(LEFT(B25,3)="138",J25<0),AND(LEFT(B25,4)="3311",J25<0),AND(LEFT(B25,3)="333",J25<0),AND(LEFT(B25,3)="337",J25<0),LEFT(B25,3)="214",LEFT(B25,3)="229",LEFT(B25,3)="419",AND(LEFT(B25,3)="421",F25<0)),-1,1)*J25 -> 52000000
A26: 100.130.131 | B26: 1311.04 | C26: N | D26: Cty TNHH Kim Tín (ngắn hạn) | F26: -52000000 | G26: =SUMIFS(CT!$H$5:$H$143,CT!$D$5:$D$143,DMTK!$B26) -> 31500000 | H26: =SUMIFS(CT!$H$5:$H$143,CT!$E$5:$E$143,DMTK!$B26) -> 0 | J26: =IF(C26="N",F26+G26-H26,F26+H26-G26) -> -20500000 | M26: =IF(AND(LEFT(B26,4)="1311",F26<0),"300.310.312",IF(AND(LEFT(B26,3)="138",F26<0),"300.310.319",IF(AND(LEFT(B26,4)="3311",F26<0),"100.130.132",IF(AND(LEFT(B26,3)="333",F26<0),"100.150.153",IF(AND(LEFT(B26,3)="337",F26<0),"100.130.134",A26))))) -> 300.310.312 | N26: =IF(OR(AND(LEFT(B26,4)="1311",F26<0),AND(LEFT(B26,3)="138",F26<0),AND(LEFT(B26,4)="3311",F26<0),AND(LEFT(B26,3)="333",F26<0),AND(LEFT(B26,3)="337",F26<0),LEFT(B26,3)="214",LEFT(B26,3)="229",LEFT(B26,3)="419",AND(LEFT(B26,3)="421",F26<0)),-1,1)*F26 -> 52000000 | O26: =IF(AND(LEFT(B26,4)="1311",J26<0),"300.310.312",IF(AND(LEFT(B26,3)="138",J26<0),"300.310.319",IF(AND(LEFT(B26,4)="3311",J26<0),"100.130.132",IF(AND(LEFT(B26,3)="333",J26<0),"100.150.153",IF(AND(LEFT(B26,3)="337",J26<0),"100.130.134",A26))))) -> 300.310.312 | P26: =IF(OR(AND(LEFT(B26,4)="1311",J26<0),AND(LEFT(B26,3)="138",J26<0),AND(LEFT(B26,4)="3311",J26<0),AND(LEFT(B26,3)="333",J26<0),AND(LEFT(B26,3)="337",J26<0),LEFT(B26,3)="214",LEFT(B26,3)="229",LEFT(B26,3)="419",AND(LEFT(B26,3)="421",F26<0)),-1,1)*J26 -> 20500000
A27: 100.130.131 | B27: 1311.05 | C27: N | D27: Cty TNHH Nam Việt (ngắn hạn) | G27: =SUMIFS(CT!$H$5:$H$143,CT!$D$5:$D$143,DMTK!$B27) -> 31500000 | H27: =SUMIFS(CT!$H$5:$H$143,CT!$E$5:$E$143,DMTK!$B27) -> 0 | J27: =IF(C27="N",F27+G27-H27,F27+H27-G27) -> 31500000 | M27: =IF(AND(LEFT(B27,4)="1311",F27<0),"300.310.312",IF(AND(LEFT(B27,3)="138",F27<0),"300.310.319",IF(AND(LEFT(B27,4)="3311",F27<0),"100.130.132",IF(AND(LEFT(B27,3)="333",F27<0),"100.150.153",IF(AND(LEFT(B27,3)="337",F27<0),"100.130.134",A27))))) -> 100.130.131 | N27: =IF(OR(AND(LEFT(B27,4)="1311",F27<0),AND(LEFT(B27,3)="138",F27<0),AND(LEFT(B27,4)="3311",F27<0),AND(LEFT(B27,3)="333",F27<0),AND(LEFT(B27,3)="337",F27<0),LEFT(B27,3)="214",LEFT(B27,3)="229",LEFT(B27,3)="419",AND(LEFT(B27,3)="421",F27<0)),-1,1)*F27 -> 0 | O27: =IF(AND(LEFT(B27,4)="1311",J27<0),"300.310.312",IF(AND(LEFT(B27,3)="138",J27<0),"300.310.319",IF(AND(LEFT(B27,4)="3311",J27<0),"100.130.132",IF(AND(LEFT(B27,3)="333",J27<0),"100.150.153",IF(AND(LEFT(B27,3)="337",J27<0),"100.130.134",A27))))) -> 100.130.131 | P27: =IF(OR(AND(LEFT(B27,4)="1311",J27<0),AND(LEFT(B27,3)="138",J27<0),AND(LEFT(B27,4)="3311",J27<0),AND(LEFT(B27,3)="333",J27<0),AND(LEFT(B27,3)="337",J27<0),LEFT(B27,3)="214",LEFT(B27,3)="229",LEFT(B27,3)="419",AND(LEFT(B27,3)="421",F27<0)),-1,1)*J27 -> 31500000
A28: 100.130.131 | B28: 1311.06 | C28: N | D28: Cty XNK Vật Tư (ngắn hạn) | F28: 0 | G28: =SUMIFS(CT!$H$5:$H$143,CT!$D$5:$D$143,DMTK!$B28) -> 29400000 | H28: =SUMIFS(CT!$H$5:$H$143,CT!$E$5:$E$143,DMTK!$B28) -> 0 | J28: =IF(C28="N",F28+G28-H28,F28+H28-G28) -> 29400000 | M28: =IF(AND(LEFT(B28,4)="1311",F28<0),"300.310.312",IF(AND(LEFT(B28,3)="138",F28<0),"300.310.319",IF(AND(LEFT(B28,4)="3311",F28<0),"100.130.132",IF(AND(LEFT(B28,3)="333",F28<0),"100.150.153",IF(AND(LEFT(B28,3)="337",F28<0),"100.130.134",A28))))) -> 100.130.131 | N28: =IF(OR(AND(LEFT(B28,4)="1311",F28<0),AND(LEFT(B28,3)="138",F28<0),AND(LEFT(B28,4)="3311",F28<0),AND(LEFT(B28,3)="333",F28<0),AND(LEFT(B28,3)="337",F28<0),LEFT(B28,3)="214",LEFT(B28,3)="229",LEFT(B28,3)="419",AND(LEFT(B28,3)="421",F28<0)),-1,1)*F28 -> 0 | O28: =IF(AND(LEFT(B28,4)="1311",J28<0),"300.310.312",IF(AND(LEFT(B28,3)="138",J28<0),"300.310.319",IF(AND(LEFT(B28,4)="3311",J28<0),"100.130.132",IF(AND(LEFT(B28,3)="333",J28<0),"100.150.153",IF(AND(LEFT(B28,3)="337",J28<0),"100.130.134",A28))))) -> 100.130.131 | P28: =IF(OR(AND(LEFT(B28,4)="1311",J28<0),AND(LEFT(B28,3)="138",J28<0),AND(LEFT(B28,4)="3311",J28<0),AND(LEFT(B28,3)="333",J28<0),AND(LEFT(B28,3)="337",J28<0),LEFT(B28,3)="214",LEFT(B28,3)="229",LEFT(B28,3)="419",AND(LEFT(B28,3)="421",F28<0)),-1,1)*J28 -> 29400000
A29: 100.150.152 | B29: 1331 | C29: N | D29: Thuế GTGT được khấu trừ của hàng hóa, dịch vụ | F29: 0 | G29: =SUMIFS(CT!$H$5:$H$143,CT!$D$5:$D$143,DMTK!$B29) -> 1960000 | H29: =SUMIFS(CT!$H$5:$H$143,CT!$E$5:$E$143,DMTK!$B29) -> 0 | J29: =IF(C29="N",F29+G29-H29,F29+H29-G29) -> 1960000 | M29: =IF(AND(LEFT(B29,4)="1311",F29<0),"300.310.312",IF(AND(LEFT(B29,3)="138",F29<0),"300.310.319",IF(AND(LEFT(B29,4)="3311",F29<0),"100.130.132",IF(AND(LEFT(B29,3)="333",F29<0),"100.150.153",IF(AND(LEFT(B29,3)="337",F29<0),"100.130.134",A29))))) -> 100.150.152 | N29: =IF(OR(AND(LEFT(B29,4)="1311",F29<0),AND(LEFT(B29,3)="138",F29<0),AND(LEFT(B29,4)="3311",F29<0),AND(LEFT(B29,3)="333",F29<0),AND(LEFT(B29,3)="337",F29<0),LEFT(B29,3)="214",LEFT(B29,3)="229",LEFT(B29,3)="419",AND(LEFT(B29,3)="421",F29<0)),-1,1)*F29 -> 0 | O29: =IF(AND(LEFT(B29,4)="1311",J29<0),"300.310.312",IF(AND(LEFT(B29,3)="138",J29<0),"300.310.319",IF(AND(LEFT(B29,4)="3311",J29<0),"100.130.132",IF(AND(LEFT(B29,3)="333",J29<0),"100.150.153",IF(AND(LEFT(B29,3)="337",J29<0),"100.130.134",A29))))) -> 100.150.152 | P29: =IF(OR(AND(LEFT(B29,4)="1311",J29<0),AND(LEFT(B29,3)="138",J29<0),AND(LEFT(B29,4)="3311",J29<0),AND(LEFT(B29,3)="333",J29<0),AND(LEFT(B29,3)="337",J29<0),LEFT(B29,3)="214",LEFT(B29,3)="229",LEFT(B29,3)="419",AND(LEFT(B29,3)="421",F29<0)),-1,1)*J29 -> 1960000
A30: 100.150.152 | B30: 1332 | C30: N | D30: Thuế GTGT được khấu trừ của TSCĐ | F30: 0 | G30: =SUMIFS(CT!$H$5:$H$143,CT!$D$5:$D$143,DMTK!$B30) -> 14000000 | H30: =SUMIFS(CT!$H$5:$H$143,CT!$E$5:$E$143,DMTK!$B30) -> 0 | J30: =IF(C30="N",F30+G30-H30,F30+H30-G30) -> 14000000 | M30: =IF(AND(LEFT(B30,4)="1311",F30<0),"300.310.312",IF(AND(LEFT(B30,3)="138",F30<0),"300.310.319",IF(AND(LEFT(B30,4)="3311",F30<0),"100.130.132",IF(AND(LEFT(B30,3)="333",F30<0),"100.150.153",IF(AND(LEFT(B30,3)="337",F30<0),"100.130.134",A30))))) -> 100.150.152 | N30: =IF(OR(AND(LEFT(B30,4)="1311",F30<0),AND(LEFT(B30,3)="138",F30<0),AND(LEFT(B30,4)="3311",F30<0),AND(LEFT(B30,3)="333",F30<0),AND(LEFT(B30,3)="337",F30<0),LEFT(B30,3)="214",LEFT(B30,3)="229",LEFT(B30,3)="419",AND(LEFT(B30,3)="421",F30<0)),-1,1)*F30 -> 0 | O30: =IF(AND(LEFT(B30,4)="1311",J30<0),"300.310.312",IF(AND(LEFT(B30,3)="138",J30<0),"300.310.319",IF(AND(LEFT(B30,4)="3311",J30<0),"100.130.132",IF(AND(LEFT(B30,3)="333",J30<0),"100.150.153",IF(AND(LEFT(B30,3)="337",J30<0),"100.130.134",A30))))) -> 100.150.152 | P30: =IF(OR(AND(LEFT(B30,4)="1311",J30<0),AND(LEFT(B30,3)="138",J30<0),AND(LEFT(B30,4)="3311",J30<0),AND(LEFT(B30,3)="333",J30<0),AND(LEFT(B30,3)="337",J30<0),LEFT(B30,3)="214",LEFT(B30,3)="229",LEFT(B30,3)="419",AND(LEFT(B30,3)="421",F30<0)),-1,1)*J30 -> 14000000
A31: 200.210.213 | B31: 1361 | C31: N | D31: Vốn kinh doanh ở các đơn vị trực thuộc | G31: =SUMIFS(CT!$H$5:$H$143,CT!$D$5:$D$143,DMTK!$B31) -> 0 | H31: =SUMIFS(CT!$H$5:$H$143,CT!$E$5:$E$143,DMTK!$B31) -> 0 | J31: =IF(C31="N",F31+G31-H31,F31+H31-G31) -> 0 | M31: =IF(AND(LEFT(B31,4)="1311",F31<0),"300.310.312",IF(AND(LEFT(B31,3)="138",F31<0),"300.310.319",IF(AND(LEFT(B31,4)="3311",F31<0),"100.130.132",IF(AND(LEFT(B31,3)="333",F31<0),"100.150.153",IF(AND(LEFT(B31,3)="337",F31<0),"100.130.134",A31))))) -> 200.210.213 | N31: =IF(OR(AND(LEFT(B31,4)="1311",F31<0),AND(LEFT(B31,3)="138",F31<0),AND(LEFT(B31,4)="3311",F31<0),AND(LEFT(B31,3)="333",F31<0),AND(LEFT(B31,3)="337",F31<0),LEFT(B31,3)="214",LEFT(B31,3)="229",LEFT(B31,3)="419",AND(LEFT(B31,3)="421",F31<0)),-1,1)*F31 -> 0 | O31: =IF(AND(LEFT(B31,4)="1311",J31<0),"300.310.312",IF(AND(LEFT(B31,3)="138",J31<0),"300.310.319",IF(AND(LEFT(B31,4)="3311",J31<0),"100.130.132",IF(AND(LEFT(B31,3)="333",J31<0),"100.150.153",IF(AND(LEFT(B31,3)="337",J31<0),"100.130.134",A31))))) -> 200.210.213 | P31: =IF(OR(AND(LEFT(B31,4)="1311",J31<0),AND(LEFT(B31,3)="138",J31<0),AND(LEFT(B31,4)="3311",J31<0),AND(LEFT(B31,3)="333",J31<0),AND(LEFT(B31,3)="337",J31<0),LEFT(B31,3)="214",LEFT(B31,3)="229",LEFT(B31,3)="419",AND(LEFT(B31,3)="421",F31<0)),-1,1)*J31 -> 0
A32: 100.130.133 | B32: 13621 | C32: N | D32: Phải thu nội bộ về chênh lệch tỷ giá (không quá 12 tháng) | G32: =SUMIFS(CT!$H$5:$H$143,CT!$D$5:$D$143,DMTK!$B32) -> 0 | H32: =SUMIFS(CT!$H$5:$H$143,CT!$E$5:$E$143,DMTK!$B32) -> 0 | J32: =IF(C32="N",F32+G32-H32,F32+H32-G32) -> 0 | M32: =IF(AND(LEFT(B32,4)="1311",F32<0),"300.310.312",IF(AND(LEFT(B32,3)="138",F32<0),"300.310.319",IF(AND(LEFT(B32,4)="3311",F32<0),"100.130.132",IF(AND(LEFT(B32,3)="333",F32<0),"100.150.153",IF(AND(LEFT(B32,3)="337",F32<0),"100.130.134",A32))))) -> 100.130.133 | N32: =IF(OR(AND(LEFT(B32,4)="1311",F32<0),AND(LEFT(B32,3)="138",F32<0),AND(LEFT(B32,4)="3311",F32<0),AND(LEFT(B32,3)="333",F32<0),AND(LEFT(B32,3)="337",F32<0),LEFT(B32,3)="214",LEFT(B32,3)="229",LEFT(B32,3)="419",AND(LEFT(B32,3)="421",F32<0)),-1,1)*F32 -> 0 | O32: =IF(AND(LEFT(B32,4)="1311",J32<0),"300.310.312",IF(AND(LEFT(B32,3)="138",J32<0),"300.310.319",IF(AND(LEFT(B32,4)="3311",J32<0),"100.130.132",IF(AND(LEFT(B32,3)="333",J32<0),"100.150.153",IF(AND(LEFT(B32,3)="337",J32<0),"100.130.134",A32))))) -> 100.130.133 | P32: =IF(OR(AND(LEFT(B32,4)="1311",J32<0),AND(LEFT(B32,3)="138",J32<0),AND(LEFT(B32,4)="3311",J32<0),AND(LEFT(B32,3)="333",J32<0),AND(LEFT(B32,3)="337",J32<0),LEFT(B32,3)="214",LEFT(B32,3)="229",LEFT(B32,3)="419",AND(LEFT(B32,3)="421",F32<0)),-1,1)*J32 -> 0
A33: 200.210.214 | B33: 13622 | C33: N | D33: Phải thu nội bộ về chênh lệch tỷ giá (trên 12 tháng) | G33: =SUMIFS(CT!$H$5:$H$143,CT!$D$5:$D$143,DMTK!$B33) -> 0 | H33: =SUMIFS(CT!$H$5:$H$143,CT!$E$5:$E$143,DMTK!$B33) -> 0 | J33: =IF(C33="N",F33+G33-H33,F33+H33-G33) -> 0 | M33: =IF(AND(LEFT(B33,4)="1311",F33<0),"300.310.312",IF(AND(LEFT(B33,3)="138",F33<0),"300.310.319",IF(AND(LEFT(B33,4)="3311",F33<0),"100.130.132",IF(AND(LEFT(B33,3)="333",F33<0),"100.150.153",IF(AND(LEFT(B33,3)="337",F33<0),"100.130.134",A33))))) -> 200.210.214 | N33: =IF(OR(AND(LEFT(B33,4)="1311",F33<0),AND(LEFT(B33,3)="138",F33<0),AND(LEFT(B33,4)="3311",F33<0),AND(LEFT(B33,3)="333",F33<0),AND(LEFT(B33,3)="337",F33<0),LEFT(B33,3)="214",LEFT(B33,3)="229",LEFT(B33,3)="419",AND(LEFT(B33,3)="421",F33<0)),-1,1)*F33 -> 0 | O33: =IF(AND(LEFT(B33,4)="1311",J33<0),"300.310.312",IF(AND(LEFT(B33,3)="138",J33<0),"300.310.319",IF(AND(LEFT(B33,4)="3311",J33<0),"100.130.132",IF(AND(LEFT(B33,3)="333",J33<0),"100.150.153",IF(AND(LEFT(B33,3)="337",J33<0),"100.130.134",A33))))) -> 200.210.214 | P33: =IF(OR(AND(LEFT(B33,4)="1311",J33<0),AND(LEFT(B33,3)="138",J33<0),AND(LEFT(B33,4)="3311",J33<0),AND(LEFT(B33,3)="333",J33<0),AND(LEFT(B33,3)="337",J33<0),LEFT(B33,3)="214",LEFT(B33,3)="229",LEFT(B33,3)="419",AND(LEFT(B33,3)="421",F33<0)),-1,1)*J33 -> 0
A34: 100.130.133 | B34: 13631 | C34: N | D34: Phải thu nội bộ về chi phí đi vay đủ điều kiện được vốn hóa (không quá 12 tháng) | F34: 0 | G34: =SUMIFS(CT!$H$5:$H$143,CT!$D$5:$D$143,DMTK!$B34) -> 0 | H34: =SUMIFS(CT!$H$5:$H$143,CT!$E$5:$E$143,DMTK!$B34) -> 0 | J34: =IF(C34="N",F34+G34-H34,F34+H34-G34) -> 0 | M34: =IF(AND(LEFT(B34,4)="1311",F34<0),"300.310.312",IF(AND(LEFT(B34,3)="138",F34<0),"300.310.319",IF(AND(LEFT(B34,4)="3311",F34<0),"100.130.132",IF(AND(LEFT(B34,3)="333",F34<0),"100.150.153",IF(AND(LEFT(B34,3)="337",F34<0),"100.130.134",A34))))) -> 100.130.133 | N34: =IF(OR(AND(LEFT(B34,4)="1311",F34<0),AND(LEFT(B34,3)="138",F34<0),AND(LEFT(B34,4)="3311",F34<0),AND(LEFT(B34,3)="333",F34<0),AND(LEFT(B34,3)="337",F34<0),LEFT(B34,3)="214",LEFT(B34,3)="229",LEFT(B34,3)="419",AND(LEFT(B34,3)="421",F34<0)),-1,1)*F34 -> 0 | O34: =IF(AND(LEFT(B34,4)="1311",J34<0),"300.310.312",IF(AND(LEFT(B34,3)="138",J34<0),"300.310.319",IF(AND(LEFT(B34,4)="3311",J34<0),"100.130.132",IF(AND(LEFT(B34,3)="333",J34<0),"100.150.153",IF(AND(LEFT(B34,3)="337",J34<0),"100.130.134",A34))))) -> 100.130.133 | P34: =IF(OR(AND(LEFT(B34,4)="1311",J34<0),AND(LEFT(B34,3)="138",J34<0),AND(LEFT(B34,4)="3311",J34<0),AND(LEFT(B34,3)="333",J34<0),AND(LEFT(B34,3)="337",J34<0),LEFT(B34,3)="214",LEFT(B34,3)="229",LEFT(B34,3)="419",AND(LEFT(B34,3)="421",F34<0)),-1,1)*J34 -> 0
A35: 200.210.214 | B35: 13632 | C35: N | D35: Phải thu nội bộ về chi phí đi vay đủ điều kiện được vốn hóa (trên 12 tháng) | G35: =SUMIFS(CT!$H$5:$H$143,CT!$D$5:$D$143,DMTK!$B35) -> 0 | H35: =SUMIFS(CT!$H$5:$H$143,CT!$E$5:$E$143,DMTK!$B35) -> 0 | J35: =IF(C35="N",F35+G35-H35,F35+H35-G35) -> 0 | M35: =IF(AND(LEFT(B35,4)="1311",F35<0),"300.310.312",IF(AND(LEFT(B35,3)="138",F35<0),"300.310.319",IF(AND(LEFT(B35,4)="3311",F35<0),"100.130.132",IF(AND(LEFT(B35,3)="333",F35<0),"100.150.153",IF(AND(LEFT(B35,3)="337",F35<0),"100.130.134",A35))))) -> 200.210.214 | N35: =IF(OR(AND(LEFT(B35,4)="1311",F35<0),AND(LEFT(B35,3)="138",F35<0),AND(LEFT(B35,4)="3311",F35<0),AND(LEFT(B35,3)="333",F35<0),AND(LEFT(B35,3)="337",F35<0),LEFT(B35,3)="214",LEFT(B35,3)="229",LEFT(B35,3)="419",AND(LEFT(B35,3)="421",F35<0)),-1,1)*F35 -> 0 | O35: =IF(AND(LEFT(B35,4)="1311",J35<0),"300.310.312",IF(AND(LEFT(B35,3)="138",J35<0),"300.310.319",IF(AND(LEFT(B35,4)="3311",J35<0),"100.130.132",IF(AND(LEFT(B35,3)="333",J35<0),"100.150.153",IF(AND(LEFT(B35,3)="337",J35<0),"100.130.134",A35))))) -> 200.210.214 | P35: =IF(OR(AND(LEFT(B35,4)="1311",J35<0),AND(LEFT(B35,3)="138",J35<0),AND(LEFT(B35,4)="3311",J35<0),AND(LEFT(B35,3)="333",J35<0),AND(LEFT(B35,3)="337",J35<0),LEFT(B35,3)="214",LEFT(B35,3)="229",LEFT(B35,3)="419",AND(LEFT(B35,3)="421",F35<0)),-1,1)*J35 -> 0
A36: 100.130.133 | B36: 13681 | C36: N | D36: Phải thu nội bộ khác (không quá 12 tháng) | G36: =SUMIFS(CT!$H$5:$H$143,CT!$D$5:$D$143,DMTK!$B36) -> 0 | H36: =SUMIFS(CT!$H$5:$H$143,CT!$E$5:$E$143,DMTK!$B36) -> 0 | J36: =IF(C36="N",F36+G36-H36,F36+H36-G36) -> 0 | M36: =IF(AND(LEFT(B36,4)="1311",F36<0),"300.310.312",IF(AND(LEFT(B36,3)="138",F36<0),"300.310.319",IF(AND(LEFT(B36,4)="3311",F36<0),"100.130.132",IF(AND(LEFT(B36,3)="333",F36<0),"100.150.153",IF(AND(LEFT(B36,3)="337",F36<0),"100.130.134",A36))))) -> 100.130.133 | N36: =IF(OR(AND(LEFT(B36,4)="1311",F36<0),AND(LEFT(B36,3)="138",F36<0),AND(LEFT(B36,4)="3311",F36<0),AND(LEFT(B36,3)="333",F36<0),AND(LEFT(B36,3)="337",F36<0),LEFT(B36,3)="214",LEFT(B36,3)="229",LEFT(B36,3)="419",AND(LEFT(B36,3)="421",F36<0)),-1,1)*F36 -> 0 | O36: =IF(AND(LEFT(B36,4)="1311",J36<0),"300.310.312",IF(AND(LEFT(B36,3)="138",J36<0),"300.310.319",IF(AND(LEFT(B36,4)="3311",J36<0),"100.130.132",IF(AND(LEFT(B36,3)="333",J36<0),"100.150.153",IF(AND(LEFT(B36,3)="337",J36<0),"100.130.134",A36))))) -> 100.130.133 | P36: =IF(OR(AND(LEFT(B36,4)="1311",J36<0),AND(LEFT(B36,3)="138",J36<0),AND(LEFT(B36,4)="3311",J36<0),AND(LEFT(B36,3)="333",J36<0),AND(LEFT(B36,3)="337",J36<0),LEFT(B36,3)="214",LEFT(B36,3)="229",LEFT(B36,3)="419",AND(LEFT(B36,3)="421",F36<0)),-1,1)*J36 -> 0
A37: 200.210.214 | B37: 13682 | C37: N | D37: Phải thu nội bộ khác (trên 12 tháng) | G37: =SUMIFS(CT!$H$5:$H$143,CT!$D$5:$D$143,DMTK!$B37) -> 0 | H37: =SUMIFS(CT!$H$5:$H$143,CT!$E$5:$E$143,DMTK!$B37) -> 0 | J37: =IF(C37="N",F37+G37-H37,F37+H37-G37) -> 0 | M37: =IF(AND(LEFT(B37,4)="1311",F37<0),"300.310.312",IF(AND(LEFT(B37,3)="138",F37<0),"300.310.319",IF(AND(LEFT(B37,4)="3311",F37<0),"100.130.132",IF(AND(LEFT(B37,3)="333",F37<0),"100.150.153",IF(AND(LEFT(B37,3)="337",F37<0),"100.130.134",A37))))) -> 200.210.214 | N37: =IF(OR(AND(LEFT(B37,4)="1311",F37<0),AND(LEFT(B37,3)="138",F37<0),AND(LEFT(B37,4)="3311",F37<0),AND(LEFT(B37,3)="333",F37<0),AND(LEFT(B37,3)="337",F37<0),LEFT(B37,3)="214",LEFT(B37,3)="229",LEFT(B37,3)="419",AND(LEFT(B37,3)="421",F37<0)),-1,1)*F37 -> 0 | O37: =IF(AND(LEFT(B37,4)="1311",J37<0),"300.310.312",IF(AND(LEFT(B37,3)="138",J37<0),"300.310.319",IF(AND(LEFT(B37,4)="3311",J37<0),"100.130.132",IF(AND(LEFT(B37,3)="333",J37<0),"100.150.153",IF(AND(LEFT(B37,3)="337",J37<0),"100.130.134",A37))))) -> 200.210.214 | P37: =IF(OR(AND(LEFT(B37,4)="1311",J37<0),AND(LEFT(B37,3)="138",J37<0),AND(LEFT(B37,4)="3311",J37<0),AND(LEFT(B37,3)="333",J37<0),AND(LEFT(B37,3)="337",J37<0),LEFT(B37,3)="214",LEFT(B37,3)="229",LEFT(B37,3)="419",AND(LEFT(B37,3)="421",F37<0)),-1,1)*J37 -> 0
A38: 100.130.139 | B38: 1381 | C38: N | D38: Tài sản thiếu chờ xử lý | G38: =SUMIFS(CT!$H$5:$H$143,CT!$D$5:$D$143,DMTK!$B38) -> 0 | H38: =SUMIFS(CT!$H$5:$H$143,CT!$E$5:$E$143,DMTK!$B38) -> 0 | J38: =IF(C38="N",F38+G38-H38,F38+H38-G38) -> 0 | M38: =IF(AND(LEFT(B38,4)="1311",F38<0),"300.310.312",IF(AND(LEFT(B38,3)="138",F38<0),"300.310.319",IF(AND(LEFT(B38,4)="3311",F38<0),"100.130.132",IF(AND(LEFT(B38,3)="333",F38<0),"100.150.153",IF(AND(LEFT(B38,3)="337",F38<0),"100.130.134",A38))))) -> 100.130.139 | N38: =IF(OR(AND(LEFT(B38,4)="1311",F38<0),AND(LEFT(B38,3)="138",F38<0),AND(LEFT(B38,4)="3311",F38<0),AND(LEFT(B38,3)="333",F38<0),AND(LEFT(B38,3)="337",F38<0),LEFT(B38,3)="214",LEFT(B38,3)="229",LEFT(B38,3)="419",AND(LEFT(B38,3)="421",F38<0)),-1,1)*F38 -> 0 | O38: =IF(AND(LEFT(B38,4)="1311",J38<0),"300.310.312",IF(AND(LEFT(B38,3)="138",J38<0),"300.310.319",IF(AND(LEFT(B38,4)="3311",J38<0),"100.130.132",IF(AND(LEFT(B38,3)="333",J38<0),"100.150.153",IF(AND(LEFT(B38,3)="337",J38<0),"100.130.134",A38))))) -> 100.130.139 | P38: =IF(OR(AND(LEFT(B38,4)="1311",J38<0),AND(LEFT(B38,3)="138",J38<0),AND(LEFT(B38,4)="3311",J38<0),AND(LEFT(B38,3)="333",J38<0),AND(LEFT(B38,3)="337",J38<0),LEFT(B38,3)="214",LEFT(B38,3)="229",LEFT(B38,3)="419",AND(LEFT(B38,3)="421",F38<0)),-1,1)*J38 -> 0
A39: 100.130.136 | B39: 13851 | C39: N | D39: Phải thu về cổ phần hóa (không quá 12 tháng) | G39: =SUMIFS(CT!$H$5:$H$143,CT!$D$5:$D$143,DMTK!$B39) -> 0 | H39: =SUMIFS(CT!$H$5:$H$143,CT!$E$5:$E$143,DMTK!$B39) -> 0 | J39: =IF(C39="N",F39+G39-H39,F39+H39-G39) -> 0 | M39: =IF(AND(LEFT(B39,4)="1311",F39<0),"300.310.312",IF(AND(LEFT(B39,3)="138",F39<0),"300.310.319",IF(AND(LEFT(B39,4)="3311",F39<0),"100.130.132",IF(AND(LEFT(B39,3)="333",F39<0),"100.150.153",IF(AND(LEFT(B39,3)="337",F39<0),"100.130.134",A39))))) -> 100.130.136 | N39: =IF(OR(AND(LEFT(B39,4)="1311",F39<0),AND(LEFT(B39,3)="138",F39<0),AND(LEFT(B39,4)="3311",F39<0),AND(LEFT(B39,3)="333",F39<0),AND(LEFT(B39,3)="337",F39<0),LEFT(B39,3)="214",LEFT(B39,3)="229",LEFT(B39,3)="419",AND(LEFT(B39,3)="421",F39<0)),-1,1)*F39 -> 0 | O39: =IF(AND(LEFT(B39,4)="1311",J39<0),"300.310.312",IF(AND(LEFT(B39,3)="138",J39<0),"300.310.319",IF(AND(LEFT(B39,4)="3311",J39<0),"100.130.132",IF(AND(LEFT(B39,3)="333",J39<0),"100.150.153",IF(AND(LEFT(B39,3)="337",J39<0),"100.130.134",A39))))) -> 100.130.136 | P39: =IF(OR(AND(LEFT(B39,4)="1311",J39<0),AND(LEFT(B39,3)="138",J39<0),AND(LEFT(B39,4)="3311",J39<0),AND(LEFT(B39,3)="333",J39<0),AND(LEFT(B39,3)="337",J39<0),LEFT(B39,3)="214",LEFT(B39,3)="229",LEFT(B39,3)="419",AND(LEFT(B39,3)="421",F39<0)),-1,1)*J39 -> 0
A40: 200.210.216 | B40: 13852 | C40: N | D40: Phải thu về cổ phần hóa | F40: 0 | G40: =SUMIFS(CT!$H$5:$H$143,CT!$D$5:$D$143,DMTK!$B40) -> 0 | H40: =SUMIFS(CT!$H$5:$H$143,CT!$E$5:$E$143,DMTK!$B40) -> 0 | J40: =IF(C40="N",F40+G40-H40,F40+H40-G40) -> 0 | M40: =IF(AND(LEFT(B40,4)="1311",F40<0),"300.310.312",IF(AND(LEFT(B40,3)="138",F40<0),"300.310.319",IF(AND(LEFT(B40,4)="3311",F40<0),"100.130.132",IF(AND(LEFT(B40,3)="333",F40<0),"100.150.153",IF(AND(LEFT(B40,3)="337",F40<0),"100.130.134",A40))))) -> 200.210.216 | N40: =IF(OR(AND(LEFT(B40,4)="1311",F40<0),AND(LEFT(B40,3)="138",F40<0),AND(LEFT(B40,4)="3311",F40<0),AND(LEFT(B40,3)="333",F40<0),AND(LEFT(B40,3)="337",F40<0),LEFT(B40,3)="214",LEFT(B40,3)="229",LEFT(B40,3)="419",AND(LEFT(B40,3)="421",F40<0)),-1,1)*F40 -> 0 | O40: =IF(AND(LEFT(B40,4)="1311",J40<0),"300.310.312",IF(AND(LEFT(B40,3)="138",J40<0),"300.310.319",IF(AND(LEFT(B40,4)="3311",J40<0),"100.130.132",IF(AND(LEFT(B40,3)="333",J40<0),"100.150.153",IF(AND(LEFT(B40,3)="337",J40<0),"100.130.134",A40))))) -> 200.210.216 | P40: =IF(OR(AND(LEFT(B40,4)="1311",J40<0),AND(LEFT(B40,3)="138",J40<0),AND(LEFT(B40,4)="3311",J40<0),AND(LEFT(B40,3)="333",J40<0),AND(LEFT(B40,3)="337",J40<0),LEFT(B40,3)="214",LEFT(B40,3)="229",LEFT(B40,3)="419",AND(LEFT(B40,3)="421",F40<0)),-1,1)*J40 -> 0
A41: 100.130.136 | B41: 13881 | C41: N | D41: Phải thu khác (không quá 12 tháng) | F41: 52200000 | G41: =SUMIFS(CT!$H$5:$H$143,CT!$D$5:$D$143,DMTK!$B41) -> 0 | H41: =SUMIFS(CT!$H$5:$H$143,CT!$E$5:$E$143,DMTK!$B41) -> 0 | J41: =IF(C41="N",F41+G41-H41,F41+H41-G41) -> 52200000 | M41: =IF(AND(LEFT(B41,4)="1311",F41<0),"300.310.312",IF(AND(LEFT(B41,3)="138",F41<0),"300.310.319",IF(AND(LEFT(B41,4)="3311",F41<0),"100.130.132",IF(AND(LEFT(B41,3)="333",F41<0),"100.150.153",IF(AND(LEFT(B41,3)="337",F41<0),"100.130.134",A41))))) -> 100.130.136 | N41: =IF(OR(AND(LEFT(B41,4)="1311",F41<0),AND(LEFT(B41,3)="138",F41<0),AND(LEFT(B41,4)="3311",F41<0),AND(LEFT(B41,3)="333",F41<0),AND(LEFT(B41,3)="337",F41<0),LEFT(B41,3)="214",LEFT(B41,3)="229",LEFT(B41,3)="419",AND(LEFT(B41,3)="421",F41<0)),-1,1)*F41 -> 52200000 | O41: =IF(AND(LEFT(B41,4)="1311",J41<0),"300.310.312",IF(AND(LEFT(B41,3)="138",J41<0),"300.310.319",IF(AND(LEFT(B41,4)="3311",J41<0),"100.130.132",IF(AND(LEFT(B41,3)="333",J41<0),"100.150.153",IF(AND(LEFT(B41,3)="337",J41<0),"100.130.134",A41))))) -> 100.130.136 | P41: =IF(OR(AND(LEFT(B41,4)="1311",J41<0),AND(LEFT(B41,3)="138",J41<0),AND(LEFT(B41,4)="3311",J41<0),AND(LEFT(B41,3)="333",J41<0),AND(LEFT(B41,3)="337",J41<0),LEFT(B41,3)="214",LEFT(B41,3)="229",LEFT(B41,3)="419",AND(LEFT(B41,3)="421",F41<0)),-1,1)*J41 -> 52200000
...

Sheet CT
A1: SỔ TẬP HỢP NGHIỆP VỤ KẾ TOÁN
A3: NGÀY | B3: SỐCT | C3: DIỄN GIẢI | D3: TKNO | E3: TKCO | F3: SL | G3: ĐƠN GIÁ | H3: SỐ TIỀN | I3: GHI CHÚ
A4: [1] | B4: [2] | C4: [3] | D4: [4] | E4: [5] | F4: [6] | G4: [7] | H4: [8] | I4: [9]
A5: 45293 | B5: 01/PT | C5: Thu nợ lô hàng 200 | D5: 1111 | E5: 1311.03 | H5: 5000000
A6: 45293 | B6: 02/PT | C6: Thu nợ lô hàng 212 | D6: 1111 | E6: 1311.01 | H6: 20000000
A7: 45295 | B7: 01/PC | C7: Chi tạm ứng cho Hồ Sĩ Nhật | D7: 141.0102 | E7: 1111 | H7: 2000000
A8: 45295 | B8: 01/NVL | C8: Thuế GTGT mua gỗ tràm bông vàng | D8: 1331 | E8: 3311.02 | H8: 1125000
A9: 45295 | B9: 01/NVL | C9: Mua gỗ tràm bông vàng | D9: 1521.0102 | E9: 3311.02 | F9: 5 | G9: 4500000 | H9: 22500000
A10: 45296 | B10: 02/PC | C10: Thuế GTGT mua VPP | D10: 1331 | E10: 1111 | H10: 100000
A11: 45296 | B11: 02/PC | C11: Mua VPP cho BPVP | D11: 6428 | E11: 1111 | H11: 1000000
A12: 45301 | B12: 02/NVL | C12: Thuế GTGT mua AC chuối, Dầu thông | D12: 1331 | E12: 3311.01 | H12: 235000
A13: 45301 | B13: 02/NVL | C13: Mua Dầu thông | D13: 1521.0403 | E13: 3311.01 | F13: 100 | G13: 15000 | H13: 1500000
A14: 45301 | B14: 02/NVL | C14: Mua AC chuối | D14: 1521.0401 | E14: 3311.01 | F14: 200 | G14: 16000 | H14: 3200000
A15: 45302 | B15: 03/NVL | C15: Thuế GTGT Nhập kho keo AB | D15: 1331 | E15: 3311.03 | H15: 500000
A16: 45302 | B16: 03/NVL | C16: Nhập kho keo AB | D16: 1521.0301 | E16: 3311.03 | F16: 200 | G16: 25000 | H16: 5000000
A17: 45306 | B17: 01/XVL | C17: Xuất keo ghép sx GTV | D17: 6211.01 | E17: 1521.0302 | F17: 10 | G17: 48000 | H17: 480000
A18: 45306 | B18: 03/PC | C18: Chi lương cho NVBH | D18: 3348.02 | E18: 1111 | H18: 5000000
A19: 45306 | B19: 03/PC | C19: Chi lương cho CB QLDN | D19: 3348.03 | E19: 1111 | H19: 7000000
A20: 45306 | B20: 01/XVL | C20: Xuất gỗ cao su sx GTV | D20: 6211.01 | E20: 1521.0101 | F20: 4 | G20: 3300000 | H20: 13200000
A21: 45306 | B21: 01/BC | C21: Cty Mai Anh trả nợ lô hàng 189 | D21: 1121.02 | E21: 1311.02 | H21: 30000000
A22: 45306 | B22: 03/PC | C22: Chi lương cho NV QLPX | D22: 3348.01 | E22: 1111 | H22: 35000000
A23: 45306 | B23: 03/PC | C23: Chi lương cho CNSX GTV | D23: 3341.01 | E23: 1111 | H23: 40000000
A24: 45306 | B24: 03/PC | C24: Chi lương cho CNSX GKT | D24: 3341.02 | E24: 1111 | H24: 40000000
A25: 45306 | B25: 03/PC | C25: Chi lương cho CNSX GTV | D25: 3341.03 | E25: 1111 | H25: 40000000
A26: 45306 | B26: 03/PC | C26: Chi lương cho CNSX BT | D26: 3341.04 | E26: 1111 | H26: 40000000
A27: 45306 | B27: 03/PC | C27: Chi lương cho CNSX BO | D27: 3341.05 | E27: 1111 | H27: 40000000
A28: 45307 | B28: 01/BN | C28: Trả Cty CP Mai Lan HĐ1170 | D28: 3311.01 | E28: 1121.01 | H28: 40000000
A29: 45307 | B29: 02/BN | C29: Chi đặt cọc mua hàng | D29: 3311.03 | E29: 1121.01 | H29: 50000000
A30: 45308 | B30: 02/XVL | C30: Xuất ván keo 502 sx BTròn | D30: 6211.03 | E30: 1521.0303 | F30: 20 | G30: 2300 | H30: 46000
A31: 45308 | B31: 03/XVL | C31: Xuất dầu thông sx GTV | D31: 6211.01 | E31: 1521.0403 | F31: 20 | G31: 14111 | H31: 282220
A32: 45308 | B32: 03/XVL | C32: Xuất AC chuối sx GTV | D32: 6211.01 | E32: 1521.0401 | F32: 30 | G32: 15666 | H32: 469980
A33: 45308 | B33: 02/XVL | C33: Xuất ván MDF 9x6x8 sx BTròn | D33: 6211.03 | E33: 1521.0201 | F33: 30 | G33: 120000 | H33: 3600000
A34: 45309 | B34: 01/XCC | C34: Xuất kệ tủ | D34: 2421.02 | E34: 1531.02 | F34: 4 | G34: 250000 | H34: 1000000
A35: 45309 | B35: 01/XCC | C35: Xuất máy tính Casio | D35: 2421.01 | E35: 1531.01 | F35: 5 | G35: 500000 | H35: 2500000
A36: 45310 | B36: 02/XCC | C36: Xuất lưỡi cưa cho PXSX | D36: 6273 | E36: 1531.03 | F36: 10 | G36: 10000 | H36: 100000
A37: 45310 | B37: 02/XCC | C37: Xuất mũi khoan cho PXSX | D37: 6273 | E37: 1531.04 | F37: 20 | G37: 5000 | H37: 100000
A38: 45310 | B38: 02/XCC | C38: Xuất dao thép cho PXSX | D38: 6273 | E38: 1531.05 | F38: 30 | G38: 10000 | H38: 300000
A39: 45314 | B39: 02/NTP | C39: Tạm nhập kho BT | D39: 1551.0201 | E39: 154.03 | F39: 200 | G39: 300000 | H39: 60000000
A40: 45314 | B40: 01/NTP | C40: Tạm nhập kho GTV | D40: 1551.0101 | E40: 154.01 | F40: 405 | G40: 250000 | H40: 101250000
A41: 45315 | B41: 03/NTP | C41: Tạm nhập kho GKT | D41: 1551.0102 | E41: 154.02 | F41: 300 | G41: 200000 | H41: 60000000
...

Sheet CDKT
A1: Đơn vị báo cáo: | D1: Mẫu số B 01 - DN
A2: Địa chỉ: | D2: (Ban hành theo thông tư số 200/2014/TT-BTC
D3: ngày 22/12/2014 của Bộ Tài Chính)
B4: BẢNG CÂN ĐỐI KẾ TOÁN
A6: TÀI SẢN | B6: Mã số | C6: Thuyết minh | D6: Số cuối kỳ | E6: Số đầu năm
A7: 1 | B7: 2 | C7: 3 | D7: 4 | E7: 5
A8: A. TÀI SẢN NGẮN HẠN | B8: 100 | D8: =SUMIFS(DMTK!$P$5:$P$191,DMTK!$O$5:$O$191,"*"&B8&"*") -> 1409682900 | E8: =SUMIFS(DMTK!$N$5:$N$191,DMTK!$M$5:$M$191,"*"&B8&"*") -> 1614461000
A9: I. Tiền và các khoản tương đương tiền | B9: 110 | D9: =SUMIFS(DMTK!$P$5:$P$191,DMTK!$O$5:$O$191,"*"&B9&"*") -> 419321000 | E9: =SUMIFS(DMTK!$N$5:$N$191,DMTK!$M$5:$M$191,"*"&B9&"*") -> 858221000
A10: 1. Tiền | B10: 111 | D10: =SUMIFS(DMTK!$P$5:$P$191,DMTK!$O$5:$O$191,"*"&B10&"*") -> 319321000 | E10: =SUMIFS(DMTK!$N$5:$N$191,DMTK!$M$5:$M$191,"*"&B10&"*") -> 758221000
A11: 2. Các khoản tương đương tiền | B11: 112 | D11: =SUMIFS(DMTK!$P$5:$P$191,DMTK!$O$5:$O$191,"*"&B11&"*") -> 100000000 | E11: =SUMIFS(DMTK!$N$5:$N$191,DMTK!$M$5:$M$191,"*"&B11&"*") -> 100000000
A12: II. Đầu tư tài chính ngắn hạn | B12: 120 | D12: =SUMIFS(DMTK!$P$5:$P$191,DMTK!$O$5:$O$191,"*"&B12&"*") -> 0 | E12: =SUMIFS(DMTK!$N$5:$N$191,DMTK!$M$5:$M$191,"*"&B12&"*") -> 0
A13: 1. Chứng khoán kinh doanh | B13: 121 | D13: =SUMIFS(DMTK!$P$5:$P$191,DMTK!$O$5:$O$191,"*"&B13&"*") -> 0 | E13: =SUMIFS(DMTK!$N$5:$N$191,DMTK!$M$5:$M$191,"*"&B13&"*") -> 0
A14: 2. Dự phòng giảm giá chứng khoán kinh doanh | B14: 122 | D14: =SUMIFS(DMTK!$P$5:$P$191,DMTK!$O$5:$O$191,"*"&B14&"*") -> 0 | E14: =SUMIFS(DMTK!$N$5:$N$191,DMTK!$M$5:$M$191,"*"&B14&"*") -> 0
A15: 3. Đầu tư nắm giữ đến ngày đáo hạn | B15: 123 | D15: =SUMIFS(DMTK!$P$5:$P$191,DMTK!$O$5:$O$191,"*"&B15&"*") -> 0 | E15: =SUMIFS(DMTK!$N$5:$N$191,DMTK!$M$5:$M$191,"*"&B15&"*") -> 0
A16: III. Các khoản phải thu ngắn hạn | B16: 130 | D16: =SUMIFS(DMTK!$P$5:$P$191,DMTK!$O$5:$O$191,"*"&B16&"*") -> 433100000 | E16: =SUMIFS(DMTK!$N$5:$N$191,DMTK!$M$5:$M$191,"*"&B16&"*") -> 382700000
A17: 1. Phải thu ngắn hạn của khách hàng | B17: 131 | D17: =SUMIFS(DMTK!$P$5:$P$191,DMTK!$O$5:$O$191,"*"&B17&"*") -> 232900000 | E17: =SUMIFS(DMTK!$N$5:$N$191,DMTK!$M$5:$M$191,"*"&B17&"*") -> 227000000
A18: 2. Trả trước cho người bán ngắn hạn | B18: 132 | D18: =SUMIFS(DMTK!$P$5:$P$191,DMTK!$O$5:$O$191,"*"&B18&"*") -> 44500000 | E18: =SUMIFS(DMTK!$N$5:$N$191,DMTK!$M$5:$M$191,"*"&B18&"*") -> 0
A19: 3. Phải thu nội bộ ngắn hạn | B19: 133 | D19: =SUMIFS(DMTK!$P$5:$P$191,DMTK!$O$5:$O$191,"*"&B19&"*") -> 0 | E19: =SUMIFS(DMTK!$N$5:$N$191,DMTK!$M$5:$M$191,"*"&B19&"*") -> 0
A20: 4. Phải thu theo tiến độ kế hoạch hợp đồng xây dựng | B20: 134 | D20: =SUMIFS(DMTK!$P$5:$P$191,DMTK!$O$5:$O$191,"*"&B20&"*") -> 0 | E20: =SUMIFS(DMTK!$N$5:$N$191,DMTK!$M$5:$M$191,"*"&B20&"*") -> 0
A21: 5. Phải thu về cho vay ngắn hạn | B21: 135 | D21: =SUMIFS(DMTK!$P$5:$P$191,DMTK!$O$5:$O$191,"*"&B21&"*") -> 0 | E21: =SUMIFS(DMTK!$N$5:$N$191,DMTK!$M$5:$M$191,"*"&B21&"*") -> 0
A22: 6. Phải thu ngắn hạn khác | B22: 136 | D22: =SUMIFS(DMTK!$P$5:$P$191,DMTK!$O$5:$O$191,"*"&B22&"*") -> 185700000 | E22: =SUMIFS(DMTK!$N$5:$N$191,DMTK!$M$5:$M$191,"*"&B22&"*") -> 185700000
A23: 7. Dự phòng phải thu ngắn hạn khó đòi (*) | B23: 137 | D23: =SUMIFS(DMTK!$P$5:$P$191,DMTK!$O$5:$O$191,"*"&B23&"*") -> -30000000 | E23: =SUMIFS(DMTK!$N$5:$N$191,DMTK!$M$5:$M$191,"*"&B23&"*") -> -30000000
A24: 8. Tài sản thiếu chờ xử lý | B24: 139 | D24: =SUMIFS(DMTK!$P$5:$P$191,DMTK!$O$5:$O$191,"*"&B24&"*") -> 0 | E24: =SUMIFS(DMTK!$N$5:$N$191,DMTK!$M$5:$M$191,"*"&B24&"*") -> 0
A25: IV. Hàng tồn kho | B25: 140 | D25: =SUMIFS(DMTK!$P$5:$P$191,DMTK!$O$5:$O$191,"*"&B25&"*") -> 495551900 | E25: =SUMIFS(DMTK!$N$5:$N$191,DMTK!$M$5:$M$191,"*"&B25&"*") -> 330540000
A26: 1. Hàng tồn kho | B26: 141 | D26: =SUMIFS(DMTK!$P$5:$P$191,DMTK!$O$5:$O$191,"*"&B26&"*") -> 575551900 | E26: =SUMIFS(DMTK!$N$5:$N$191,DMTK!$M$5:$M$191,"*"&B26&"*") -> 410540000
A27: 2. Dự phòng giảm giá hàng tồn kho | B27: 149 | D27: =SUMIFS(DMTK!$P$5:$P$191,DMTK!$O$5:$O$191,"*"&B27&"*") -> -80000000 | E27: =SUMIFS(DMTK!$N$5:$N$191,DMTK!$M$5:$M$191,"*"&B27&"*") -> -80000000
... A42: 7. Dự phòng phải thu dài hạn khó đòi (*) | B42: 219 | D42: =SUMIFS(DMTK!$P$5:$P$191,DMTK!$O$5:$O$191,"*"&B42&"*") -> 0 | E42: =SUMIFS(DMTK!$N$5:$N$191,DMTK!$M$5:$M$191,"*"&B42&"*") -> 0
A43: II. Tài sản cố định | B43: 220 | D43: =SUMIFS(DMTK!$P$5:$P$191,DMTK!$O$5:$O$191,"*"&B43&"*") -> 981654001 | E43: =SUMIFS(DMTK!$N$5:$N$191,DMTK!$M$5:$M$191,"*"&B43&"*") -> 843779000
A44: 1. Tài sản cố định hữu hình | B44: 221 | D44: =SUMIFS(DMTK!$P$5:$P$191,DMTK!$O$5:$O$191,"*"&B44&"*") -> 981654001 | E44: =SUMIFS(DMTK!$N$5:$N$191,DMTK!$M$5:$M$191,"*"&B44&"*") -> 843779000
A45: - Nguyên giá | B45: 222 | D45: =SUMIFS(DMTK!$P$5:$P$191,DMTK!$O$5:$O$191,"*"&B45&"*") -> 1073779000 | E45: =SUMIFS(DMTK!$N$5:$N$191,DMTK!$M$5:$M$191,"*"&B45&"*") -> 933779000
A46: - Giá trị hao mòn luỹ kế (*) | B46: 223 | D46: =SUMIFS(DMTK!$P$5:$P$191,DMTK!$O$5:$O$191,"*"&B46&"*") -> -92124999 | E46: =SUMIFS(DMTK!$N$5:$N$191,DMTK!$M$5:$M$191,"*"&B46&"*") -> -90000000
A47: 2. Tài sản cố định thuê tài chính | B47: 224 | D47: =SUMIFS(DMTK!$P$5:$P$191,DMTK!$O$5:$O$191,"*"&B47&"*") -> 0 | E47: =SUMIFS(DMTK!$N$5:$N$191,DMTK!$M$5:$M$191,"*"&B47&"*") -> 0
A48: - Nguyên giá | B48: 225 | D48: =SUMIFS(DMTK!$P$5:$P$191,DMTK!$O$5:$O$191,"*"&B48&"*") -> 0 | E48: =SUMIFS(DMTK!$N$5:$N$191,DMTK!$M$5:$M$191,"*"&B48&"*") -> 0
A49: - Giá trị hao mòn luỹ kế (*) | B49: 226 | D49: =SUMIFS(DMTK!$P$5:$P$191,DMTK!$O$5:$O$191,"*"&B49&"*") -> 0 | E49: =SUMIFS(DMTK!$N$5:$N$191,DMTK!$M$5:$M$191,"*"&B49&"*") -> 0
A50: 3. Tài sản cố định vô hình | B50: 227 | D50: =SUMIFS(DMTK!$P$5:$P$191,DMTK!$O$5:$O$191,"*"&B50&"*") -> 0 | E50: =SUMIFS(DMTK!$N$5:$N$191,DMTK!$M$5:$M$191,"*"&B50&"*") -> 0
A51: - Nguyên giá | B51: 228 | D51: =SUMIFS(DMTK!$P$5:$P$191,DMTK!$O$5:$O$191,"*"&B51&"*") -> 0 | E51: =SUMIFS(DMTK!$N$5:$N$191,DMTK!$M$5:$M$191,"*"&B51&"*") -> 0
A52: - Giá trị hao mòn luỹ kế (*) | B52: 229 | D52: =SUMIFS(DMTK!$P$5:$P$191,DMTK!$O$5:$O$191,"*"&B52&"*") -> 0 | E52: =SUMIFS(DMTK!$N$5:$N$191,DMTK!$M$5:$M$191,"*"&B52&"*") -> 0
A53: III. Bất động sản đầu tư | B53: 230 | D53: =SUMIFS(DMTK!$P$5:$P$191,DMTK!$O$5:$O$191,"*"&B53&"*") -> 0 | E53: =SUMIFS(DMTK!$N$5:$N$191,DMTK!$M$5:$M$191,"*"&B53&"*") -> 0
