Workbook

Sheet DMTK
A1: BẢNG DANH MỤC TÀI KHOẢN
A3: MÃ TS-NV | B3: SHTK | C3: Loại TK | D3: TÊN TK | E3: TỒN DK | F3: SDD | G3: PSNO | H3: PSCO | I3: TỒN CK | J3: SDC | K3: DDNO | L3: DDCO | M3: MaTSNVDN | N3: SODN | O3: MaTSNVCK | P3: SOCK | Q3: ĐVT
A4: 0 | B4: 1 | C4: 2 | D4: 3 | E4: 4 | F4: 5 | G4: 6 | H4: 7 | I4: 8 | J4: 9 | K4: 10 | L4: 11 | M4: 12 | N4: 13 | O4: 14 | P4: 15 | Q4: 16
A5: 100.110.111 | B5: 1111 | C5: N | D5: Tiền Việt Nam | F5: 400000000 | G5: =SUMIFS(CT!$H$5:$H$143,CT!$D$5:$D$143,DMTK!B5) -> 25200000 | H5: =SUMIFS(CT!$H$5:$H$143,CT!$E$5:$E$143,DMTK!B5) -> 404100000 | I5: =IF(OR(LEFT(B5,3)="152",LEFT(B5,3)="153",LEFT(B5,3)="155",LEFT(B5,3)="156",LEFT(B5,3)="157"),E5+SUMIFS(CT!$F$5:$F$143,CT!$D$5:$D$143,DMTK!B5)-SUMIFS(CT!$F$5:$F$143,CT!$E$5:$E$143,DMTK!B5),0) -> 0 | J5: =IF(C5="N",F5+G5-H5,F5+H5-G5) -> 21100000 | K5: =IF(OR(AND(C5="N",F5>0),AND(C5="C",F5<0)),ABS(F5),0) -> 400000000 | L5: =IF(OR(AND(C5="C",F5>0),AND(C5="N",F5<0)),ABS(F5),0) -> 0
A6: 100.110.111 | B6: 1112 | C6: N | D6: Ngoại tệ | F6: 0 | G6: =SUMIFS(CT!$H$5:$H$143,CT!$D$5:$D$143,DMTK!B6) -> 0 | H6: =SUMIFS(CT!$H$5:$H$143,CT!$E$5:$E$143,DMTK!B6) -> 0 | I6: =IF(OR(LEFT(B6,3)="152",LEFT(B6,3)="153",LEFT(B6,3)="155",LEFT(B6,3)="156",LEFT(B6,3)="157"),E6+SUMIFS(CT!$F$5:$F$143,CT!$D$5:$D$143,DMTK!B6)-SUMIFS(CT!$F$5:$F$143,CT!$E$5:$E$143,DMTK!B6),0) -> 0 | J6: =IF(C6="N",F6+G6-H6,F6+H6-G6) -> 0 | K6: =IF(OR(AND(C6="N",F6>0),AND(C6="C",F6<0)),ABS(F6),0) -> 0 | L6: =IF(OR(AND(C6="C",F6>0),AND(C6="N",F6<0)),ABS(F6),0) -> 0
A7: 100.110.111 | B7: 1113 | C7: N | D7: Vàng tiền tệ | F7: 0 | G7: =SUMIFS(CT!$H$5:$H$143,CT!$D$5:$D$143,DMTK!B7) -> 0 | H7: =SUMIFS(CT!$H$5:$H$143,CT!$E$5:$E$143,DMTK!B7) -> 0 | I7: =IF(OR(LEFT(B7,3)="152",LEFT(B7,3)="153",LEFT(B7,3)="155",LEFT(B7,3)="156",LEFT(B7,3)="157"),E7+SUMIFS(CT!$F$5:$F$143,CT!$D$5:$D$143,DMTK!B7)-SUMIFS(CT!$F$5:$F$143,CT!$E$5:$E$143,DMTK!B7),0) -> 0 | J7: =IF(C7="N",F7+G7-H7,F7+H7-G7) -> 0 | K7: =IF(OR(AND(C7="N",F7>0),AND(C7="C",F7<0)),ABS(F7),0) -> 0 | L7: =IF(OR(AND(C7="C",F7>0),AND(C7="N",F7<0)),ABS(F7),0) -> 0
A8: 100.110.111 | B8: 1121.01 | C8: N | D8: Tiền Việt Nam NH Ngoại Thương | F8: 258221000 | G8: =SUMIFS(CT!$H$5:$H$143,CT!$D$5:$D$143,DMTK!B8) -> 0 | H8: =SUMIFS(CT!$H$5:$H$143,CT!$E$5:$E$143,DMTK!B8) -> 90000000 | I8: =IF(OR(LEFT(B8,3)="152",LEFT(B8,3)="153",LEFT(B8,3)="155",LEFT(B8,3)="156",LEFT(B8,3)="157"),E8+SUMIFS(CT!$F$5:$F$143,CT!$D$5:$D$143,DMTK!B8)-SUMIFS(CT!$F$5:$F$143,CT!$E$5:$E$143,DMTK!B8),0) -> 0 | J8: =IF(C8="N",F8+G8-H8,F8+H8-G8) -> 168221000 | K8: =IF(OR(AND(C8="N",F8>0),AND(C8="C",F8<0)),ABS(F8),0) -> 258221000 | L8: =IF(OR(AND(C8="C",F8>0),AND(C8="N",F8<0)),ABS(F8),0) -> 0
A9: 100.110.111 | B9: 1121.02 | C9: N | D9: Tiền Việt Nam NH Đông Á | F9: 60000000 | G9: =SUMIFS(CT!$H$5:$H$143,CT!$D$5:$D$143,DMTK!B9) -> 30000000 | H9: =SUMIFS(CT!$H$5:$H$143,CT!$E$5:$E$143,DMTK!B9) -> 0 | I9: =IF(OR(LEFT(B9,3)="152",LEFT(B9,3)="153",LEFT(B9,3)="155",LEFT(B9,3)="156",LEFT(B9,3)="157"),E9+SUMIFS(CT!$F$5:$F$143,CT!$D$5:$D$143,DMTK!B9)-SUMIFS(CT!$F$5:$F$143,CT!$E$5:$E$143,DMTK!B9),0) -> 0 | J9: =IF(C9="N",F9+G9-H9,F9+H9-G9) -> 90000000 | K9: =IF(OR(AND(C9="N",F9>0),AND(C9="C",F9<0)),ABS(F9),0) -> 60000000 | L9: =IF(OR(AND(C9="C",F9>0),AND(C9="N",F9<0)),ABS(F9),0) -> 0
A10: 100.110.111 | B10: 1121.03 | C10: N | D10: Tiền Việt Nam NH Á Châu | F10: 40000000 | G10: =SUMIFS(CT!$H$5:$H$143,CT!$D$5:$D$143,DMTK!B10) -> 0 | H10: =SUMIFS(CT!$H$5:$H$143,CT!$E$5:$E$143,DMTK!B10) -> 0 | I10: =IF(OR(LEFT(B10,3)="152",LEFT(B10,3)="153",LEFT(B10,3)="155",LEFT(B10,3)="156",LEFT(B10,3)="157"),E10+SUMIFS(CT!$F$5:$F$143,CT!$D$5:$D$143,DMTK!B10)-SUMIFS(CT!$F$5:$F$143,CT!$E$5:$E$143,DMTK!B10),0) -> 0 | J10: =IF(C10="N",F10+G10-H10,F10+H10-G10) -> 40000000 | K10: =IF(OR(AND(C10="N",F10>0),AND(C10="C",F10<0)),ABS(F10),0) -> 40000000 | L10: =IF(OR(AND(C10="C",F10>0),AND(C10="N",F10<0)),ABS(F10),0) -> 0
A11: 100.110.111 | B11: 1122 | C11: N | D11: Ngoại tệ | F11: 0 | G11: =SUMIFS(CT!$H$5:$H$143,CT!$D$5:$D$143,DMTK!B11) -> 0 | H11: =SUMIFS(CT!$H$5:$H$143,CT!$E$5:$E$143,DMTK!B11) -> 0 | I11: =IF(OR(LEFT(B11,3)="152",LEFT(B11,3)="153",LEFT(B11,3)="155",LEFT(B11,3)="156",LEFT(B11,3)="157"),E11+SUMIFS(CT!$F$5:$F$143,CT!$D$5:$D$143,DMTK!B11)-SUMIFS(CT!$F$5:$F$143,CT!$E$5:$E$143,DMTK!B11),0) -> 0 | J11: =IF(C11="N",F11+G11-H11,F11+H11-G11) -> 0 | K11: =IF(OR(AND(C11="N",F11>0),AND(C11="C",F11<0)),ABS(F11),0) -> 0 | L11: =IF(OR(AND(C11="C",F11>0),AND(C11="N",F11<0)),ABS(F11),0) -> 0
A12: 100.110.111 | B12: 1123 | C12: N | D12: Vàng tiền tệ | F12: 0 | G12: =SUMIFS(CT!$H$5:$H$143,CT!$D$5:$D$143,DMTK!B12) -> 0 | H12: =SUMIFS(CT!$H$5:$H$143,CT!$E$5:$E$143,DMTK!B12) -> 0 | I12: =IF(OR(LEFT(B12,3)="152",LEFT(B12,3)="153",LEFT(B12,3)="155",LEFT(B12,3)="156",LEFT(B12,3)="157"),E12+SUMIFS(CT!$F$5:$F$143,CT!$D$5:$D$143,DMTK!B12)-SUMIFS(CT!$F$5:$F$143,CT!$E$5:$E$143,DMTK!B12),0) -> 0 | J12: =IF(C12="N",F12+G12-H12,F12+H12-G12) -> 0 | K12: =IF(OR(AND(C12="N",F12>0),AND(C12="C",F12<0)),ABS(F12),0) -> 0 | L12: =IF(OR(AND(C12="C",F12>0),AND(C12="N",F12<0)),ABS(F12),0) -> 0
A13: 100.110.111 | B13: 1131 | C13: N | D13: Tiền Việt Nam | F13: 0 | G13: =SUMIFS(CT!$H$5:$H$143,CT!$D$5:$D$143,DMTK!B13) -> 0 | H13: =SUMIFS(CT!$H$5:$H$143,CT!$E$5:$E$143,DMTK!B13) -> 0 | I13: =IF(OR(LEFT(B13,3)="152",LEFT(B13,3)="153",LEFT(B13,3)="155",LEFT(B13,3)="156",LEFT(B13,3)="157"),E13+SUMIFS(CT!$F$5:$F$143,CT!$D$5:$D$143,DMTK!B13)-SUMIFS(CT!$F$5:$F$143,CT!$E$5:$E$143,DMTK!B13),0) -> 0 | J13: =IF(C13="N",F13+G13-H13,F13+H13-G13) -> 0 | K13: =IF(OR(AND(C13="N",F13>0),AND(C13="C",F13<0)),ABS(F13),0) -> 0 | L13: =IF(OR(AND(C13="C",F13>0),AND(C13="N",F13<0)),ABS(F13),0) -> 0
A14: 100.110.111 | B14: 1132 | C14: N | D14: Ngoại tệ | G14: =SUMIFS(CT!$H$5:$H$143,CT!$D$5:$D$143,DMTK!B14) -> 0 | H14: =SUMIFS(CT!$H$5:$H$143,CT!$E$5:$E$143,DMTK!B14) -> 0 | I14: =IF(OR(LEFT(B14,3)="152",LEFT(B14,3)="153",LEFT(B14,3)="155",LEFT(B14,3)="156",LEFT(B14,3)="157"),E14+SUMIFS(CT!$F$5:$F$143,CT!$D$5:$D$143,DMTK!B14)-SUMIFS(CT!$F$5:$F$143,CT!$E$5:$E$143,DMTK!B14),0) -> 0 | J14: =IF(C14="N",F14+G14-H14,F14+H14-G14) -> 0 | K14: =IF(OR(AND(C14="N",F14>0),AND(C14="C",F14<0)),ABS(F14),0) -> 0 | L14: =IF(OR(AND(C14="C",F14>0),AND(C14="N",F14<0)),ABS(F14),0) -> 0
A15: 100.120.121 | B15: 1211 | C15: N | D15: Cổ phiếu | F15: 0 | G15: =SUMIFS(CT!$H$5:$H$143,CT!$D$5:$D$143,DMTK!B15) -> 0 | H15: =SUMIFS(CT!$H$5:$H$143,CT!$E$5:$E$143,DMTK!B15) -> 0 | I15: =IF(OR(LEFT(B15,3)="152",LEFT(B15,3)="153",LEFT(B15,3)="155",LEFT(B15,3)="156",LEFT(B15,3)="157"),E15+SUMIFS(CT!$F$5:$F$143,CT!$D$5:$D$143,DMTK!B15)-SUMIFS(CT!$F$5:$F$143,CT!$E$5:$E$143,DMTK!B15),0) -> 0 | J15: =IF(C15="N",F15+G15-H15,F15+H15-G15) -> 0 | K15: =IF(OR(AND(C15="N",F15>0),AND(C15="C",F15<0)),ABS(F15),0) -> 0 | L15: =IF(OR(AND(C15="C",F15>0),AND(C15="N",F15<0)),ABS(F15),0) -> 0
A16: 100.120.121 | B16: 1212 | C16: N | D16: Trái phiếu | F16: 0 | G16: =SUMIFS(CT!$H$5:$H$143,CT!$D$5:$D$143,DMTK!B16) -> 0 | H16: =SUMIFS(CT!$H$5:$H$143,CT!$E$5:$E$143,DMTK!B16) -> 0 | I16: =IF(OR(LEFT(B16,3)="152",LEFT(B16,3)="153",LEFT(B16,3)="155",LEFT(B16,3)="156",LEFT(B16,3)="157"),E16+SUMIFS(CT!$F$5:$F$143,CT!$D$5:$D$143,DMTK!B16)-SUMIFS(CT!$F$5:$F$143,CT!$E$5:$E$143,DMTK!B16),0) -> 0 | J16: =IF(C16="N",F16+G16-H16,F16+H16-G16) -> 0 | K16: =IF(OR(AND(C16="N",F16>0),AND(C16="C",F16<0)),ABS(F16),0) -> 0 | L16: =IF(OR(AND(C16="C",F16>0),AND(C16="N",F16<0)),ABS(F16),0) -> 0
A17: 100.110.112 | B17: 12811 | C17: N | D17: Tiền gửi có kỳ hạn (không quá 3 tháng) | F17: 100000000 | G17: =SUMIFS(CT!$H$5:$H$143,CT!$D$5:$D$143,DMTK!B17) -> 0 | H17: =SUMIFS(CT!$H$5:$H$143,CT!$E$5:$E$143,DMTK!B17) -> 0 | I17: =IF(OR(LEFT(B17,3)="152",LEFT(B17,3)="153",LEFT(B17,3)="155",LEFT(B17,3)="156",LEFT(B17,3)="157"),E17+SUMIFS(CT!$F$5:$F$143,CT!$D$5:$D$143,DMTK!B17)-SUMIFS(CT!$F$5:$F$143,CT!$E$5:$E$143,DMTK!B17),0) -> 0 | J17: =IF(C17="N",F17+G17-H17,F17+H17-G17) -> 100000000 | K17: =IF(OR(AND(C17="N",F17>0),AND(C17="C",F17<0)),ABS(F17),0) -> 100000000 | L17: =IF(OR(AND(C17="C",F17>0),AND(C17="N",F17<0)),ABS(F17),0) -> 0
A18: 100.120.123 | B18: 12812 | C18: N | D18: Tiền gửi có kỳ hạn (không quá 12 tháng) | G18: =SUMIFS(CT!$H$5:$H$143,CT!$D$5:$D$143,DMTK!B18) -> 0 | H18: =SUMIFS(CT!$H$5:$H$143,CT!$E$5:$E$143,DMTK!B18) -> 0 | I18: =IF(OR(LEFT(B18,3)="152",LEFT(B18,3)="153",LEFT(B18,3)="155",LEFT(B18,3)="156",LEFT(B18,3)="157"),E18+SUMIFS(CT!$F$5:$F$143,CT!$D$5:$D$143,DMTK!B18)-SUMIFS(CT!$F$5:$F$143,CT!$E$5:$E$143,DMTK!B18),0) -> 0 | J18: =IF(C18="N",F18+G18-H18,F18+H18-G18) -> 0 | K18: =IF(OR(AND(C18="N",F18>0),AND(C18="C",F18<0)),ABS(F18),0) -> 0 | L18: =IF(OR(AND(C18="C",F18>0),AND(C18="N",F18<0)),ABS(F18),0) -> 0
A19: 100.130.135 | B19: 12831 | C19: N | D19: Cho vay (không quá 12 tháng) | G19: =SUMIFS(CT!$H$5:$H$143,CT!$D$5:$D$143,DMTK!B19) -> 0 | H19: =SUMIFS(CT!$H$5:$H$143,CT!$E$5:$E$143,DMTK!B19) -> 0 | I19: =IF(OR(LEFT(B19,3)="152",LEFT(B19,3)="153",LEFT(B19,3)="155",LEFT(B19,3)="156",LEFT(B19,3)="157"),E19+SUMIFS(CT!$F$5:$F$143,CT!$D$5:$D$143,DMTK!B19)-SUMIFS(CT!$F$5:$F$143,CT!$E$5:$E$143,DMTK!B19),0) -> 0 | J19: =IF(C19="N",F19+G19-H19,F19+H19-G19) -> 0 | K19: =IF(OR(AND(C19="N",F19>0),AND(C19="C",F19<0)),ABS(F19),0) -> 0 | L19: =IF(OR(AND(C19="C",F19>0),AND(C19="N",F19<0)),ABS(F19),0) -> 0
A20: 200.210.215 | B20: 12832 | C20: N | D20: Cho vay (trên 12 tháng) | G20: =SUMIFS(CT!$H$5:$H$143,CT!$D$5:$D$143,DMTK!B20) -> 0 | H20: =SUMIFS(CT!$H$5:$H$143,CT!$E$5:$E$143,DMTK!B20) -> 0 | I20: =IF(OR(LEFT(B20,3)="152",LEFT(B20,3)="153",LEFT(B20,3)="155",LEFT(B20,3)="156",LEFT(B20,3)="157"),E20+SUMIFS(CT!$F$5:$F$143,CT!$D$5:$D$143,DMTK!B20)-SUMIFS(CT!$F$5:$F$143,CT!$E$5:$E$143,DMTK!B20),0) -> 0 | J20: =IF(C20="N",F20+G20-H20,F20+H20-G20) -> 0 | K20: =IF(OR(AND(C20="N",F20>0),AND(C20="C",F20<0)),ABS(F20),0) -> 0 | L20: =IF(OR(AND(C20="C",F20>0),AND(C20="N",F20<0)),ABS(F20),0) -> 0
A21: 100.110.112 | B21: 12881 | C21: N | D21: Các khoản đầu tư khác nắm giữ đến ngày đáo hạn | F21: 0 | G21: =SUMIFS(CT!$H$5:$H$143,CT!$D$5:$D$143,DMTK!B21) -> 0 | H21: =SUMIFS(CT!$H$5:$H$143,CT!$E$5:$E$143,DMTK!B21) -> 0 | I21: =IF(OR(LEFT(B21,3)="152",LEFT(B21,3)="153",LEFT(B21,3)="155",LEFT(B21,3)="156",LEFT(B21,3)="157"),E21+SUMIFS(CT!$F$5:$F$143,CT!$D$5:$D$143,DMTK!B21)-SUMIFS(CT!$F$5:$F$143,CT!$E$5:$E$143,DMTK!B21),0) -> 0 | J21: =IF(C21="N",F21+G21-H21,F21+H21-G21) -> 0 | K21: =IF(OR(AND(C21="N",F21>0),AND(C21="C",F21<0)),ABS(F21),0) -> 0 | L21: =IF(OR(AND(C21="C",F21>0),AND(C21="N",F21<0)),ABS(F21),0) -> 0
A22: 100.120.123 | B22: 12882 | C22: N | D22: Các khoản đầu tư khác nắm giữ đến ngày đáo hạn (không quá 12 tháng) | G22: =SUMIFS(CT!$H$5:$H$143,CT!$D$5:$D$143,DMTK!B22) -> 0 | H22: =SUMIFS(CT!$H$5:$H$143,CT!$E$5:$E$143,DMTK!B22) -> 0 | I22: =IF(OR(LEFT(B22,3)="152",LEFT(B22,3)="153",LEFT(B22,3)="155",LEFT(B22,3)="156",LEFT(B22,3)="157"),E22+SUMIFS(CT!$F$5:$F$143,CT!$D$5:$D$143,DMTK!B22)-SUMIFS(CT!$F$5:$F$143,CT!$E$5:$E$143,DMTK!B22),0) -> 0 | J22: =IF(C22="N",F22+G22-H22,F22+H22-G22) -> 0 | K22: =IF(OR(AND(C22="N",F22>0),AND(C22="C",F22<0)),ABS(F22),0) -> 0 | L22: =IF(OR(AND(C22="C",F22>0),AND(C22="N",F22<0)),ABS(F22),0) -> 0
A23: 100.130.131 | B23: 1311.01 | C23: N | D23: Công ty Quang Minh (ngắn hạn) | F23: 100000000 | G23: =SUMIFS(CT!$H$5:$H$143,CT!$D$5:$D$143,DMTK!B23) -> 0 | H23: =SUMIFS(CT!$H$5:$H$143,CT!$E$5:$E$143,DMTK!B23) -> 20000000 | I23: =IF(OR(LEFT(B23,3)="152",LEFT(B23,3)="153",LEFT(B23,3)="155",LEFT(B23,3)="156",LEFT(B23,3)="157"),E23+SUMIFS(CT!$F$5:$F$143,CT!$D$5:$D$143,DMTK!B23)-SUMIFS(CT!$F$5:$F$143,CT!$E$5:$E$143,DMTK!B23),0) -> 0 | J23: =IF(C23="N",F23+G23-H23,F23+H23-G23) -> 80000000 | K23: =IF(OR(AND(C23="N",F23>0),AND(C23="C",F23<0)),ABS(F23),0) -> 100000000 | L23: =IF(OR(AND(C23="C",F23>0),AND(C23="N",F23<0)),ABS(F23),0) -> 0
A24: 100.130.131 | B24: 1311.02 | C24: N | D24: Cty TNHH TMDV Mai Anh (ngắn hạn) | F24: 70000000 | G24: =SUMIFS(CT!$H$5:$H$143,CT!$D$5:$D$143,DMTK!B24) -> 0 | H24: =SUMIFS(CT!$H$5:$H$143,CT!$E$5:$E$143,DMTK!B24) -> 30000000 | I24: =IF(OR(LEFT(B24,3)="152",LEFT(B24,3)="153",LEFT(B24,3)="155",LEFT(B24,3)="156",LEFT(B24,3)="157"),E24+SUMIFS(CT!$F$5:$F$143,CT!$D$5:$D$143,DMTK!B24)-SUMIFS(CT!$F$5:$F$143,CT!$E$5:$E$143,DMTK!B24),0) -> 0 | J24: =IF(C24="N",F24+G24-H24,F24+H24-G24) -> 40000000 | K24: =IF(OR(AND(C24="N",F24>0),AND(C24="C",F24<0)),ABS(F24),0) -> 70000000 | L24: =IF(OR(AND(C24="C",F24>0),AND(C24="N",F24<0)),ABS(F24),0) -> 0
A25: 100.130.131 | B25: 1311.03 | C25: N | D25: Cty TNHH Phương Nam (ngắn hạn) | F25: 57000000 | G25: =SUMIFS(CT!$H$5:$H$143,CT!$D$5:$D$143,DMTK!B25) -> 0 | H25: =SUMIFS(CT!$H$5:$H$143,CT!$E$5:$E$143,DMTK!B25) -> 5000000 | I25: =IF(OR(LEFT(B25,3)="152",LEFT(B25,3)="153",LEFT(B25,3)="155",LEFT(B25,3)="156",LEFT(B25,3)="157"),E25+SUMIFS(CT!$F$5:$F$143,CT!$D$5:$D$143,DMTK!B25)-SUMIFS(CT!$F$5:$F$143,CT!$E$5:$E$143,DMTK!B25),0) -> 0 | J25: =IF(C25="N",F25+G25-H25,F25+H25-G25) -> 52000000 | K25: =IF(OR(AND(C25="N",F25>0),AND(C25="C",F25<0)),ABS(F25),0) -> 57000000 | L25: =IF(OR(AND(C25="C",F25>0),AND(C25="N",F25<0)),ABS(F25),0) -> 0
A26: 100.130.131 | B26: 1311.04 | C26: N | D26: Cty TNHH Kim Tín (ngắn hạn) | F26: -52000000 | G26: =SUMIFS(CT!$H$5:$H$143,CT!$D$5:$D$143,DMTK!B26) -> 0 | H26: =SUMIFS(CT!$H$5:$H$143,CT!$E$5:$E$143,DMTK!B26) -> 0 | I26: =IF(OR(LEFT(B26,3)="152",LEFT(B26,3)="153",LEFT(B26,3)="155",LEFT(B26,3)="156",LEFT(B26,3)="157"),E26+SUMIFS(CT!$F$5:$F$143,CT!$D$5:$D$143,DMTK!B26)-SUMIFS(CT!$F$5:$F$143,CT!$E$5:$E$143,DMTK!B26),0) -> 0 | J26: =IF(C26="N",F26+G26-H26,F26+H26-G26) -> -52000000 | K26: =IF(OR(AND(C26="N",F26>0),AND(C26="C",F26<0)),ABS(F26),0) -> 0 | L26: =IF(OR(AND(C26="C",F26>0),AND(C26="N",F26<0)),ABS(F26),0) -> 52000000
A27: 100.130.131 | B27: 1311.05 | C27: N | D27: Cty TNHH Nam Việt (ngắn hạn) | G27: =SUMIFS(CT!$H$5:$H$143,CT!$D$5:$D$143,DMTK!B27) -> 30150000 | H27: =SUMIFS(CT!$H$5:$H$143,CT!$E$5:$E$143,DMTK!B27) -> 0 | I27: =IF(OR(LEFT(B27,3)="152",LEFT(B27,3)="153",LEFT(B27,3)="155",LEFT(B27,3)="156",LEFT(B27,3)="157"),E27+SUMIFS(CT!$F$5:$F$143,CT!$D$5:$D$143,DMTK!B27)-SUMIFS(CT!$F$5:$F$143,CT!$E$5:$E$143,DMTK!B27),0) -> 0 | J27: =IF(C27="N",F27+G27-H27,F27+H27-G27) -> 30150000 | K27: =IF(OR(AND(C27="N",F27>0),AND(C27="C",F27<0)),ABS(F27),0) -> 0 | L27: =IF(OR(AND(C27="C",F27>0),AND(C27="N",F27<0)),ABS(F27),0) -> 0
A28: 100.130.131 | B28: 1311.06 | C28: N | D28: Cty XNK Vật Tư (ngắn hạn) | F28: 0 | G28: =SUMIFS(CT!$H$5:$H$143,CT!$D$5:$D$143,DMTK!B28) -> 61007500 | H28: =SUMIFS(CT!$H$5:$H$143,CT!$E$5:$E$143,DMTK!B28) -> 0 | I28: =IF(OR(LEFT(B28,3)="152",LEFT(B28,3)="153",LEFT(B28,3)="155",LEFT(B28,3)="156",LEFT(B28,3)="157"),E28+SUMIFS(CT!$F$5:$F$143,CT!$D$5:$D$143,DMTK!B28)-SUMIFS(CT!$F$5:$F$143,CT!$E$5:$E$143,DMTK!B28),0) -> 0 | J28: =IF(C28="N",F28+G28-H28,F28+H28-G28) -> 61007500 | K28: =IF(OR(AND(C28="N",F28>0),AND(C28="C",F28<0)),ABS(F28),0) -> 0 | L28: =IF(OR(AND(C28="C",F28>0),AND(C28="N",F28<0)),ABS(F28),0) -> 0
A29: 100.150.152 | B29: 1331 | C29: N | D29: Thuế GTGT được khấu trừ của hàng hóa, dịch vụ | F29: 0 | G29: =SUMIFS(CT!$H$5:$H$143,CT!$D$5:$D$143,DMTK!B29) -> 1655000 | H29: =SUMIFS(CT!$H$5:$H$143,CT!$E$5:$E$143,DMTK!B29) -> 0 | I29: =IF(OR(LEFT(B29,3)="152",LEFT(B29,3)="153",LEFT(B29,3)="155",LEFT(B29,3)="156",LEFT(B29,3)="157"),E29+SUMIFS(CT!$F$5:$F$143,CT!$D$5:$D$143,DMTK!B29)-SUMIFS(CT!$F$5:$F$143,CT!$E$5:$E$143,DMTK!B29),0) -> 0 | J29: =IF(C29="N",F29+G29-H29,F29+H29-G29) -> 1655000 | K29: =IF(OR(AND(C29="N",F29>0),AND(C29="C",F29<0)),ABS(F29),0) -> 0 | L29: =IF(OR(AND(C29="C",F29>0),AND(C29="N",F29<0)),ABS(F29),0) -> 0
A30: 100.150.152 | B30: 1332 | C30: N | D30: Thuế GTGT được khấu trừ của TSCĐ | F30: 0 | G30: =SUMIFS(CT!$H$5:$H$143,CT!$D$5:$D$143,DMTK!B30) -> 14000000 | H30: =SUMIFS(CT!$H$5:$H$143,CT!$E$5:$E$143,DMTK!B30) -> 0 | I30: =IF(OR(LEFT(B30,3)="152",LEFT(B30,3)="153",LEFT(B30,3)="155",LEFT(B30,3)="156",LEFT(B30,3)="157"),E30+SUMIFS(CT!$F$5:$F$143,CT!$D$5:$D$143,DMTK!B30)-SUMIFS(CT!$F$5:$F$143,CT!$E$5:$E$143,DMTK!B30),0) -> 0 | J30: =IF(C30="N",F30+G30-H30,F30+H30-G30) -> 14000000 | K30: =IF(OR(AND(C30="N",F30>0),AND(C30="C",F30<0)),ABS(F30),0) -> 0 | L30: =IF(OR(AND(C30="C",F30>0),AND(C30="N",F30<0)),ABS(F30),0) -> 0
A31: 200.210.213 | B31: 1361 | C31: N | D31: Vốn kinh doanh ở các đơn vị trực thuộc | G31: =SUMIFS(CT!$H$5:$H$143,CT!$D$5:$D$143,DMTK!B31) -> 0 | H31: =SUMIFS(CT!$H$5:$H$143,CT!$E$5:$E$143,DMTK!B31) -> 0 | I31: =IF(OR(LEFT(B31,3)="152",LEFT(B31,3)="153",LEFT(B31,3)="155",LEFT(B31,3)="156",LEFT(B31,3)="157"),E31+SUMIFS(CT!$F$5:$F$143,CT!$D$5:$D$143,DMTK!B31)-SUMIFS(CT!$F$5:$F$143,CT!$E$5:$E$143,DMTK!B31),0) -> 0 | J31: =IF(C31="N",F31+G31-H31,F31+H31-G31) -> 0 | K31: =IF(OR(AND(C31="N",F31>0),AND(C31="C",F31<0)),ABS(F31),0) -> 0 | L31: =IF(OR(AND(C31="C",F31>0),AND(C31="N",F31<0)),ABS(F31),0) -> 0
A32: 100.130.133 | B32: 13621 | C32: N | D32: Phải thu nội bộ về chênh lệch tỷ giá (không quá 12 tháng) | G32: =SUMIFS(CT!$H$5:$H$143,CT!$D$5:$D$143,DMTK!B32) -> 0 | H32: =SUMIFS(CT!$H$5:$H$143,CT!$E$5:$E$143,DMTK!B32) -> 0 | I32: =IF(OR(LEFT(B32,3)="152",LEFT(B32,3)="153",LEFT(B32,3)="155",LEFT(B32,3)="156",LEFT(B32,3)="157"),E32+SUMIFS(CT!$F$5:$F$143,CT!$D$5:$D$143,DMTK!B32)-SUMIFS(CT!$F$5:$F$143,CT!$E$5:$E$143,DMTK!B32),0) -> 0 | J32: =IF(C32="N",F32+G32-H32,F32+H32-G32) -> 0 | K32: =IF(OR(AND(C32="N",F32>0),AND(C32="C",F32<0)),ABS(F32),0) -> 0 | L32: =IF(OR(AND(C32="C",F32>0),AND(C32="N",F32<0)),ABS(F32),0) -> 0
A33: 200.210.214 | B33: 13622 | C33: N | D33: Phải thu nội bộ về chênh lệch tỷ giá (trên 12 tháng) | G33: =SUMIFS(CT!$H$5:$H$143,CT!$D$5:$D$143,DMTK!B33) -> 0 | H33: =SUMIFS(CT!$H$5:$H$143,CT!$E$5:$E$143,DMTK!B33) -> 0 | I33: =IF(OR(LEFT(B33,3)="152",LEFT(B33,3)="153",LEFT(B33,3)="155",LEFT(B33,3)="156",LEFT(B33,3)="157"),E33+SUMIFS(CT!$F$5:$F$143,CT!$D$5:$D$143,DMTK!B33)-SUMIFS(CT!$F$5:$F$143,CT!$E$5:$E$143,DMTK!B33),0) -> 0 | J33: =IF(C33="N",F33+G33-H33,F33+H33-G33) -> 0 | K33: =IF(OR(AND(C33="N",F33>0),AND(C33="C",F33<0)),ABS(F33),0) -> 0 | L33: =IF(OR(AND(C33="C",F33>0),AND(C33="N",F33<0)),ABS(F33),0) -> 0
A34: 100.130.133 | B34: 13631 | C34: N | D34: Phải thu nội bộ về chi phí đi vay đủ điều kiện được vốn hóa (không quá 12 tháng) | F34: 0 | G34: =SUMIFS(CT!$H$5:$H$143,CT!$D$5:$D$143,DMTK!B34) -> 0 | H34: =SUMIFS(CT!$H$5:$H$143,CT!$E$5:$E$143,DMTK!B34) -> 0 | I34: =IF(OR(LEFT(B34,3)="152",LEFT(B34,3)="153",LEFT(B34,3)="155",LEFT(B34,3)="156",LEFT(B34,3)="157"),E34+SUMIFS(CT!$F$5:$F$143,CT!$D$5:$D$143,DMTK!B34)-SUMIFS(CT!$F$5:$F$143,CT!$E$5:$E$143,DMTK!B34),0) -> 0 | J34: =IF(C34="N",F34+G34-H34,F34+H34-G34) -> 0 | K34: =IF(OR(AND(C34="N",F34>0),AND(C34="C",F34<0)),ABS(F34),0) -> 0 | L34: =IF(OR(AND(C34="C",F34>0),AND(C34="N",F34<0)),ABS(F34),0) -> 0
A35: 200.210.214 | B35: 13632 | C35: N | D35: Phải thu nội bộ về chi phí đi vay đủ điều kiện được vốn hóa (trên 12 tháng) | G35: =SUMIFS(CT!$H$5:$H$143,CT!$D$5:$D$143,DMTK!B35) -> 0 | H35: =SUMIFS(CT!$H$5:$H$143,CT!$E$5:$E$143,DMTK!B35) -> 0 | I35: =IF(OR(LEFT(B35,3)="152",LEFT(B35,3)="153",LEFT(B35,3)="155",LEFT(B35,3)="156",LEFT(B35,3)="157"),E35+SUMIFS(CT!$F$5:$F$143,CT!$D$5:$D$143,DMTK!B35)-SUMIFS(CT!$F$5:$F$143,CT!$E$5:$E$143,DMTK!B35),0) -> 0 | J35: =IF(C35="N",F35+G35-H35,F35+H35-G35) -> 0 | K35: =IF(OR(AND(C35="N",F35>0),AND(C35="C",F35<0)),ABS(F35),0) -> 0 | L35: =IF(OR(AND(C35="C",F35>0),AND(C35="N",F35<0)),ABS(F35),0) -> 0
A36: 100.130.133 | B36: 13681 | C36: N | D36: Phải thu nội bộ khác (không quá 12 tháng) | G36: =SUMIFS(CT!$H$5:$H$143,CT!$D$5:$D$143,DMTK!B36) -> 0 | H36: =SUMIFS(CT!$H$5:$H$143,CT!$E$5:$E$143,DMTK!B36) -> 0 | I36: =IF(OR(LEFT(B36,3)="152",LEFT(B36,3)="153",LEFT(B36,3)="155",LEFT(B36,3)="156",LEFT(B36,3)="157"),E36+SUMIFS(CT!$F$5:$F$143,CT!$D$5:$D$143,DMTK!B36)-SUMIFS(CT!$F$5:$F$143,CT!$E$5:$E$143,DMTK!B36),0) -> 0 | J36: =IF(C36="N",F36+G36-H36,F36+H36-G36) -> 0 | K36: =IF(OR(AND(C36="N",F36>0),AND(C36="C",F36<0)),ABS(F36),0) -> 0 | L36: =IF(OR(AND(C36="C",F36>0),AND(C36="N",F36<0)),ABS(F36),0) -> 0
A37: 200.210.214 | B37: 13682 | C37: N | D37: Phải thu nội bộ khác (trên 12 tháng) | G37: =SUMIFS(CT!$H$5:$H$143,CT!$D$5:$D$143,DMTK!B37) -> 0 | H37: =SUMIFS(CT!$H$5:$H$143,CT!$E$5:$E$143,DMTK!B37) -> 0 | I37: =IF(OR(LEFT(B37,3)="152",LEFT(B37,3)="153",LEFT(B37,3)="155",LEFT(B37,3)="156",LEFT(B37,3)="157"),E37+SUMIFS(CT!$F$5:$F$143,CT!$D$5:$D$143,DMTK!B37)-SUMIFS(CT!$F$5:$F$143,CT!$E$5:$E$143,DMTK!B37),0) -> 0 | J37: =IF(C37="N",F37+G37-H37,F37+H37-G37) -> 0 | K37: =IF(OR(AND(C37="N",F37>0),AND(C37="C",F37<0)),ABS(F37),0) -> 0 | L37: =IF(OR(AND(C37="C",F37>0),AND(C37="N",F37<0)),ABS(F37),0) -> 0
A38: 100.130.139 | B38: 1381 | C38: N | D38: Tài sản thiếu chờ xử lý | G38: =SUMIFS(CT!$H$5:$H$143,CT!$D$5:$D$143,DMTK!B38) -> 0 | H38: =SUMIFS(CT!$H$5:$H$143,CT!$E$5:$E$143,DMTK!B38) -> 0 | I38: =IF(OR(LEFT(B38,3)="152",LEFT(B38,3)="153",LEFT(B38,3)="155",LEFT(B38,3)="156",LEFT(B38,3)="157"),E38+SUMIFS(CT!$F$5:$F$143,CT!$D$5:$D$143,DMTK!B38)-SUMIFS(CT!$F$5:$F$143,CT!$E$5:$E$143,DMTK!B38),0) -> 0 | J38: =IF(C38="N",F38+G38-H38,F38+H38-G38) -> 0 | K38: =IF(OR(AND(C38="N",F38>0),AND(C38="C",F38<0)),ABS(F38),0) -> 0 | L38: =IF(OR(AND(C38="C",F38>0),AND(C38="N",F38<0)),ABS(F38),0) -> 0
A39: 100.130.136 | B39: 13851 | C39: N | D39: Phải thu về cổ phần hóa (không quá 12 tháng) | G39: =SUMIFS(CT!$H$5:$H$143,CT!$D$5:$D$143,DMTK!B39) -> 0 | H39: =SUMIFS(CT!$H$5:$H$143,CT!$E$5:$E$143,DMTK!B39) -> 0 | I39: =IF(OR(LEFT(B39,3)="152",LEFT(B39,3)="153",LEFT(B39,3)="155",LEFT(B39,3)="156",LEFT(B39,3)="157"),E39+SUMIFS(CT!$F$5:$F$143,CT!$D$5:$D$143,DMTK!B39)-SUMIFS(CT!$F$5:$F$143,CT!$E$5:$E$143,DMTK!B39),0) -> 0 | J39: =IF(C39="N",F39+G39-H39,F39+H39-G39) -> 0 | K39: =IF(OR(AND(C39="N",F39>0),AND(C39="C",F39<0)),ABS(F39),0) -> 0 | L39: =IF(OR(AND(C39="C",F39>0),AND(C39="N",F39<0)),ABS(F39),0) -> 0
A40: 200.210.216 | B40: 13852 | C40: N | D40: Phải thu về cổ phần hóa | F40: 0 | G40: =SUMIFS(CT!$H$5:$H$143,CT!$D$5:$D$143,DMTK!B40) -> 0 | H40: =SUMIFS(CT!$H$5:$H$143,CT!$E$5:$E$143,DMTK!B40) -> 0 | I40: =IF(OR(LEFT(B40,3)="152",LEFT(B40,3)="153",LEFT(B40,3)="155",LEFT(B40,3)="156",LEFT(B40,3)="157"),E40+SUMIFS(CT!$F$5:$F$143,CT!$D$5:$D$143,DMTK!B40)-SUMIFS(CT!$F$5:$F$143,CT!$E$5:$E$143,DMTK!B40),0) -> 0 | J40: =IF(C40="N",F40+G40-H40,F40+H40-G40) -> 0 | K40: =IF(OR(AND(C40="N",F40>0),AND(C40="C",F40<0)),ABS(F40),0) -> 0 | L40: =IF(OR(AND(C40="C",F40>0),AND(C40="N",F40<0)),ABS(F40),0) -> 0
A41: 100.130.136 | B41: 13881 | C41: N | D41: Phải thu khác (không quá 12 tháng) | F41: 52200000 | G41: =SUMIFS(CT!$H$5:$H$143,CT!$D$5:$D$143,DMTK!B41) -> 0 | H41: =SUMIFS(CT!$H$5:$H$143,CT!$E$5:$E$143,DMTK!B41) -> 0 | I41: =IF(OR(LEFT(B41,3)="152",LEFT(B41,3)="153",LEFT(B41,3)="155",LEFT(B41,3)="156",LEFT(B41,3)="157"),E41+SUMIFS(CT!$F$5:$F$143,CT!$D$5:$D$143,DMTK!B41)-SUMIFS(CT!$F$5:$F$143,CT!$E$5:$E$143,DMTK!B41),0) -> 0 | J41: =IF(C41="N",F41+G41-H41,F41+H41-G41) -> 52200000 | K41: =IF(OR(AND(C41="N",F41>0),AND(C41="C",F41<0)),ABS(F41),0) -> 52200000 | L41: =IF(OR(AND(C41="C",F41>0),AND(C41="N",F41<0)),ABS(F41),0) -> 0
...

Sheet CT
A1: SỔ TẬP HỢP NGHIỆP VỤ KẾ TOÁN
A3: NGÀY | B3: SỐCT | C3: DIỄN GIẢI | D3: TKNO | E3: TKCO | F3: SỐ LƯƠNG | G3: ĐƠN GIÁ | H3: SỐ TIỀN | I3: GHI CHÚ | J3: KT TKNO | K3: KT TKCO | L3: TÊN TKNO | M3: TÊN TKCO | N3: GHI SỔ NKC | O3: Loại sổ
A4: [1] | B4: [2] | C4: [3] | D4: [4] | E4: [5] | F4: [6] | G4: [7] | H4: [8] | I4: 9 | J4: 10 | K4: 11 | L4: 12 | M4: 13 | N4: 14 | O4: 15
A5: 45293 | B5: 01/PT | C5: Thu nợ lô hàng 200 | D5: 1111 | E5: 1311.03 | H5: 5000000 | J5: =IF(ISNA(VLOOKUP(D5,DMTK!$B$5:$B$263,1,0)),"Sai","Đúng") -> Đúng | K5: =IF(ISNA(VLOOKUP(E5,DMTK!$B$5:$B$263,1,0)),"Sai","Đúng") -> Đúng | L5: =VLOOKUP(D5,DMTK!$B$5:$D$263,3,0) -> Tiền Việt Nam | M5: =VLOOKUP(E5,DMTK!$B$5:$D$263,3,0) -> Cty TNHH Phương Nam (ngắn hạn) | N5: =IF(OR(LEFT($D5,3)="111",AND(LEFT(CT!$D5,3)="131",LEFT(CT!$E5,3)="511"),LEFT(CT!$E5,3)="111",LEFT(CT!$E5,3)="331"),"No","Yes") -> No | P5: =IF(LEN(D5)>3,"TKCT","TKTH") -> TKCT | Q5: =IF(LEN(E5)>3,"TKCT","TKTH") -> TKCT
A6: 45293 | B6: 02/PT | C6: Thu nợ lô hàng 212 | D6: 1111 | E6: 1311.01 | H6: 20000000 | J6: =IF(ISNA(VLOOKUP(D6,DMTK!$B$5:$B$263,1,0)),"Sai","Đúng") -> Đúng | K6: =IF(ISNA(VLOOKUP(E6,DMTK!$B$5:$B$263,1,0)),"Sai","Đúng") -> Đúng | L6: =VLOOKUP(D6,DMTK!$B$5:$D$263,3,0) -> Tiền Việt Nam | M6: =VLOOKUP(E6,DMTK!$B$5:$D$263,3,0) -> Công ty Quang Minh (ngắn hạn) | N6: =IF(OR(LEFT($D6,3)="111",AND(LEFT(CT!$D6,3)="131",LEFT(CT!$E6,3)="511"),LEFT(CT!$E6,3)="111",LEFT(CT!$E6,3)="331"),"No","Yes") -> No | P6: =IF(LEN(D6)>3,"TKCT","TKTH") -> TKCT | Q6: =IF(LEN(E6)>3,"TKCT","TKTH") -> TKCT | R6: =SUMIFS($H$5:$H$143,$D$5:$D$143,1111) -> 25200000 | S6: =COUNTIFS($D$5:$D$143,1111) -> 3
A7: 45295 | B7: 01/PC | C7: Chi tạm ứng cho Hồ Sĩ Nhật | D7: 141.0102 | E7: 1111 | H7: 2000000 | J7: =IF(ISNA(VLOOKUP(D7,DMTK!$B$5:$B$263,1,0)),"Sai","Đúng") -> Đúng | K7: =IF(ISNA(VLOOKUP(E7,DMTK!$B$5:$B$263,1,0)),"Sai","Đúng") -> Đúng | L7: =VLOOKUP(D7,DMTK!$B$5:$D$263,3,0) -> Hồ Sĩ Nhật | M7: =VLOOKUP(E7,DMTK!$B$5:$D$263,3,0) -> Tiền Việt Nam | N7: =IF(OR(LEFT($D7,3)="111",AND(LEFT(CT!$D7,3)="131",LEFT(CT!$E7,3)="511"),LEFT(CT!$E7,3)="111",LEFT(CT!$E7,3)="331"),"No","Yes") -> No | P7: =IF(LEN(D7)>3,"TKCT","TKTH") -> TKCT | Q7: =IF(LEN(E7)>3,"TKCT","TKTH") -> TKCT
A8: 45295 | B8: 01/NVL | C8: Thuế GTGT mua gỗ tràm bông vàng | D8: 1331 | E8: 3311.02 | H8: =H6*5% -> 1000000 | J8: =IF(ISNA(VLOOKUP(D8,DMTK!$B$5:$B$263,1,0)),"Sai","Đúng") -> Đúng | K8: =IF(ISNA(VLOOKUP(E8,DMTK!$B$5:$B$263,1,0)),"Sai","Đúng") -> Đúng | L8: =VLOOKUP(D8,DMTK!$B$5:$D$263,3,0) -> Thuế GTGT được khấu trừ của hàng hóa, dịch vụ | M8: =VLOOKUP(E8,DMTK!$B$5:$D$263,3,0) -> Cty TNHH Cường Phát | N8: =IF(OR(LEFT($D8,3)="111",AND(LEFT(CT!$D8,3)="131",LEFT(CT!$E8,3)="511"),LEFT(CT!$E8,3)="111",LEFT(CT!$E8,3)="331"),"No","Yes") -> No | P8: =IF(LEN(D8)>3,"TKCT","TKTH") -> TKCT | Q8: =IF(LEN(E8)>3,"TKCT","TKTH") -> TKCT
A9: 45295 | B9: 01/NVL | C9: Mua gỗ tràm bông vàng | D9: 1521.0102 | E9: 3311.02 | F9: 5 | G9: 4500000 | H9: =F9*G9 -> 22500000 | J9: =IF(ISNA(VLOOKUP(D9,DMTK!$B$5:$B$263,1,0)),"Sai","Đúng") -> Đúng | K9: =IF(ISNA(VLOOKUP(E9,DMTK!$B$5:$B$263,1,0)),"Sai","Đúng") -> Đúng | L9: =VLOOKUP(D9,DMTK!$B$5:$D$263,3,0) -> Gỗ tràm bông vàng | M9: =VLOOKUP(E9,DMTK!$B$5:$D$263,3,0) -> Cty TNHH Cường Phát | N9: =IF(OR(LEFT($D9,3)="111",AND(LEFT(CT!$D9,3)="131",LEFT(CT!$E9,3)="511"),LEFT(CT!$E9,3)="111",LEFT(CT!$E9,3)="331"),"No","Yes") -> No | P9: =IF(LEN(D9)>3,"TKCT","TKTH") -> TKCT | Q9: =IF(LEN(E9)>3,"TKCT","TKTH") -> TKCT
A10: 45296 | B10: 02/PC | C10: Thuế GTGT mua VPP | D10: 1331 | E10: 1111 | H10: 100000 | J10: =IF(ISNA(VLOOKUP(D10,DMTK!$B$5:$B$263,1,0)),"Sai","Đúng") -> Đúng | K10: =IF(ISNA(VLOOKUP(E10,DMTK!$B$5:$B$263,1,0)),"Sai","Đúng") -> Đúng | L10: =VLOOKUP(D10,DMTK!$B$5:$D$263,3,0) -> Thuế GTGT được khấu trừ của hàng hóa, dịch vụ | M10: =VLOOKUP(E10,DMTK!$B$5:$D$263,3,0) -> Tiền Việt Nam | N10: =IF(OR(LEFT($D10,3)="111",AND(LEFT(CT!$D10,3)="131",LEFT(CT!$E10,3)="511"),LEFT(CT!$E10,3)="111",LEFT(CT!$E10,3)="331"),"No","Yes") -> No | P10: =IF(LEN(D10)>3,"TKCT","TKTH") -> TKCT | Q10: =IF(LEN(E10)>3,"TKCT","TKTH") -> TKCT
A11: 45296 | B11: 02/PC | C11: Mua VPP cho BPVP | D11: 6428 | E11: 1111 | H11: 1000000 | J11: =IF(ISNA(VLOOKUP(D11,DMTK!$B$5:$B$263,1,0)),"Sai","Đúng") -> Đúng | K11: =IF(ISNA(VLOOKUP(E11,DMTK!$B$5:$B$263,1,0)),"Sai","Đúng") -> Đúng | L11: =VLOOKUP(D11,DMTK!$B$5:$D$263,3,0) -> Chi phí bằng tiền khác | M11: =VLOOKUP(E11,DMTK!$B$5:$D$263,3,0) -> Tiền Việt Nam | N11: =IF(OR(LEFT($D11,3)="111",AND(LEFT(CT!$D11,3)="131",LEFT(CT!$E11,3)="511"),LEFT(CT!$E11,3)="111",LEFT(CT!$E11,3)="331"),"No","Yes") -> No | P11: =IF(LEN(D11)>3,"TKCT","TKTH") -> TKCT | Q11: =IF(LEN(E11)>3,"TKCT","TKTH") -> TKCT
A12: 45301 | B12: 02/NVL | C12: Thuế GTGT mua AC chuối, Dầu thông | D12: 1331 | E12: 3311.01 | H12: =5%*(H10+H11) -> 55000 | J12: =IF(ISNA(VLOOKUP(D12,DMTK!$B$5:$B$263,1,0)),"Sai","Đúng") -> Đúng | K12: =IF(ISNA(VLOOKUP(E12,DMTK!$B$5:$B$263,1,0)),"Sai","Đúng") -> Đúng | L12: =VLOOKUP(D12,DMTK!$B$5:$D$263,3,0) -> Thuế GTGT được khấu trừ của hàng hóa, dịch vụ | M12: =VLOOKUP(E12,DMTK!$B$5:$D$263,3,0) -> Cty CP Mai Lan | N12: =IF(OR(LEFT($D12,3)="111",AND(LEFT(CT!$D12,3)="131",LEFT(CT!$E12,3)="511"),LEFT(CT!$E12,3)="111",LEFT(CT!$E12,3)="331"),"No","Yes") -> No | P12: =IF(LEN(D12)>3,"TKCT","TKTH") -> TKCT | Q12: =IF(LEN(E12)>3,"TKCT","TKTH") -> TKCT
A13: 45301 | B13: 02/NVL | C13: Mua Dầu thông | D13: 1521.0403 | E13: 3311.01 | F13: 100 | G13: 15000 | H13: =F13*G13 -> 1500000 | J13: =IF(ISNA(VLOOKUP(D13,DMTK!$B$5:$B$263,1,0)),"Sai","Đúng") -> Đúng | K13: =IF(ISNA(VLOOKUP(E13,DMTK!$B$5:$B$263,1,0)),"Sai","Đúng") -> Đúng | L13: =VLOOKUP(D13,DMTK!$B$5:$D$263,3,0) -> Dầu thông | M13: =VLOOKUP(E13,DMTK!$B$5:$D$263,3,0) -> Cty CP Mai Lan | N13: =IF(OR(LEFT($D13,3)="111",AND(LEFT(CT!$D13,3)="131",LEFT(CT!$E13,3)="511"),LEFT(CT!$E13,3)="111",LEFT(CT!$E13,3)="331"),"No","Yes") -> No | P13: =IF(LEN(D13)>3,"TKCT","TKTH") -> TKCT | Q13: =IF(LEN(E13)>3,"TKCT","TKTH") -> TKCT
A14: 45301 | B14: 02/NVL | C14: Mua AC chuối | D14: 1521.0401 | E14: 3311.01 | F14: 200 | G14: 16000 | H14: =F14*G14 -> 3200000 | J14: =IF(ISNA(VLOOKUP(D14,DMTK!$B$5:$B$263,1,0)),"Sai","Đúng") -> Đúng | K14: =IF(ISNA(VLOOKUP(E14,DMTK!$B$5:$B$263,1,0)),"Sai","Đúng") -> Đúng | L14: =VLOOKUP(D14,DMTK!$B$5:$D$263,3,0) -> AC chuối | M14: =VLOOKUP(E14,DMTK!$B$5:$D$263,3,0) -> Cty CP Mai Lan | N14: =IF(OR(LEFT($D14,3)="111",AND(LEFT(CT!$D14,3)="131",LEFT(CT!$E14,3)="511"),LEFT(CT!$E14,3)="111",LEFT(CT!$E14,3)="331"),"No","Yes") -> No | P14: =IF(LEN(D14)>3,"TKCT","TKTH") -> TKCT | Q14: =IF(LEN(E14)>3,"TKCT","TKTH") -> TKCT
A15: 45302 | B15: 03/NVL | C15: Thuế GTGT Nhập kho keo AB | D15: 1331 | E15: 3311.03 | H15: 500000 | J15: =IF(ISNA(VLOOKUP(D15,DMTK!$B$5:$B$263,1,0)),"Sai","Đúng") -> Đúng | K15: =IF(ISNA(VLOOKUP(E15,DMTK!$B$5:$B$263,1,0)),"Sai","Đúng") -> Đúng | L15: =VLOOKUP(D15,DMTK!$B$5:$D$263,3,0) -> Thuế GTGT được khấu trừ của hàng hóa, dịch vụ | M15: =VLOOKUP(E15,DMTK!$B$5:$D$263,3,0) -> Cty TNHH Minh Gia Phát | N15: =IF(OR(LEFT($D15,3)="111",AND(LEFT(CT!$D15,3)="131",LEFT(CT!$E15,3)="511"),LEFT(CT!$E15,3)="111",LEFT(CT!$E15,3)="331"),"No","Yes") -> No | P15: =IF(LEN(D15)>3,"TKCT","TKTH") -> TKCT | Q15: =IF(LEN(E15)>3,"TKCT","TKTH") -> TKCT
A16: 45302 | B16: 03/NVL | C16: Nhập kho keo AB | D16: 1521.0301 | E16: 3311.03 | F16: 200 | G16: 25000 | H16: 5000000 | J16: =IF(ISNA(VLOOKUP(D16,DMTK!$B$5:$B$263,1,0)),"Sai","Đúng") -> Đúng | K16: =IF(ISNA(VLOOKUP(E16,DMTK!$B$5:$B$263,1,0)),"Sai","Đúng") -> Đúng | L16: =VLOOKUP(D16,DMTK!$B$5:$D$263,3,0) -> Keo AB | M16: =VLOOKUP(E16,DMTK!$B$5:$D$263,3,0) -> Cty TNHH Minh Gia Phát | N16: =IF(OR(LEFT($D16,3)="111",AND(LEFT(CT!$D16,3)="131",LEFT(CT!$E16,3)="511"),LEFT(CT!$E16,3)="111",LEFT(CT!$E16,3)="331"),"No","Yes") -> No | P16: =IF(LEN(D16)>3,"TKCT","TKTH") -> TKCT | Q16: =IF(LEN(E16)>3,"TKCT","TKTH") -> TKCT
A17: 45306 | B17: 01/XVL | C17: Xuất keo ghép sx GTV | D17: 6211.01 | E17: 1521.0302 | F17: 10 | G17: 48000 | H17: =F17*G17 -> 480000 | J17: =IF(ISNA(VLOOKUP(D17,DMTK!$B$5:$B$263,1,0)),"Sai","Đúng") -> Đúng | K17: =IF(ISNA(VLOOKUP(E17,DMTK!$B$5:$B$263,1,0)),"Sai","Đúng") -> Đúng | L17: =VLOOKUP(D17,DMTK!$B$5:$D$263,3,0) -> CFNVL Ghế tay vịn | M17: =VLOOKUP(E17,DMTK!$B$5:$D$263,3,0) -> Keo ghép | N17: =IF(OR(LEFT($D17,3)="111",AND(LEFT(CT!$D17,3)="131",LEFT(CT!$E17,3)="511"),LEFT(CT!$E17,3)="111",LEFT(CT!$E17,3)="331"),"No","Yes") -> Yes | P17: =IF(LEN(D17)>3,"TKCT","TKTH") -> TKCT | Q17: =IF(LEN(E17)>3,"TKCT","TKTH") -> TKCT
A18: 45306 | B18: 03/PC | C18: Chi lương cho NVBH | D18: 3348.02 | E18: 1111 | H18: 5000000 | J18: =IF(ISNA(VLOOKUP(D18,DMTK!$B$5:$B$263,1,0)),"Sai","Đúng") -> Đúng | K18: =IF(ISNA(VLOOKUP(E18,DMTK!$B$5:$B$263,1,0)),"Sai","Đúng") -> Đúng | L18: =VLOOKUP(D18,DMTK!$B$5:$D$263,3,0) -> Lương NV bán hàng | M18: =VLOOKUP(E18,DMTK!$B$5:$D$263,3,0) -> Tiền Việt Nam | N18: =IF(OR(LEFT($D18,3)="111",AND(LEFT(CT!$D18,3)="131",LEFT(CT!$E18,3)="511"),LEFT(CT!$E18,3)="111",LEFT(CT!$E18,3)="331"),"No","Yes") -> No | P18: =IF(LEN(D18)>3,"TKCT","TKTH") -> TKCT | Q18: =IF(LEN(E18)>3,"TKCT","TKTH") -> TKCT
A19: 45306 | B19: 03/PC | C19: Chi lương cho CB QLDN | D19: 3348.03 | E19: 1111 | H19: 7000000 | J19: =IF(ISNA(VLOOKUP(D19,DMTK!$B$5:$B$263,1,0)),"Sai","Đúng") -> Đúng | K19: =IF(ISNA(VLOOKUP(E19,DMTK!$B$5:$B$263,1,0)),"Sai","Đúng") -> Đúng | L19: =VLOOKUP(D19,DMTK!$B$5:$D$263,3,0) -> Lương CB QLDN | M19: =VLOOKUP(E19,DMTK!$B$5:$D$263,3,0) -> Tiền Việt Nam | N19: =IF(OR(LEFT($D19,3)="111",AND(LEFT(CT!$D19,3)="131",LEFT(CT!$E19,3)="511"),LEFT(CT!$E19,3)="111",LEFT(CT!$E19,3)="331"),"No","Yes") -> No | P19: =IF(LEN(D19)>3,"TKCT","TKTH") -> TKCT | Q19: =IF(LEN(E19)>3,"TKCT","TKTH") -> TKCT
A20: 45306 | B20: 01/XVL | C20: Xuất gỗ cao su sx GTV | D20: 6211.01 | E20: 1521.0101 | F20: 4 | G20: 3300000 | H20: =F20*G20 -> 13200000 | J20: =IF(ISNA(VLOOKUP(D20,DMTK!$B$5:$B$263,1,0)),"Sai","Đúng") -> Đúng | K20: =IF(ISNA(VLOOKUP(E20,DMTK!$B$5:$B$263,1,0)),"Sai","Đúng") -> Đúng | L20: =VLOOKUP(D20,DMTK!$B$5:$D$263,3,0) -> CFNVL Ghế tay vịn | M20: =VLOOKUP(E20,DMTK!$B$5:$D$263,3,0) -> Gỗ cao su | N20: =IF(OR(LEFT($D20,3)="111",AND(LEFT(CT!$D20,3)="131",LEFT(CT!$E20,3)="511"),LEFT(CT!$E20,3)="111",LEFT(CT!$E20,3)="331"),"No","Yes") -> Yes | P20: =IF(LEN(D20)>3,"TKCT","TKTH") -> TKCT | Q20: =IF(LEN(E20)>3,"TKCT","TKTH") -> TKCT
A21: 45306 | B21: 01/BC | C21: Cty Mai Anh trả nợ lô hàng 189 | D21: 1121.02 | E21: 1311.02 | H21: 30000000 | J21: =IF(ISNA(VLOOKUP(D21,DMTK!$B$5:$B$263,1,0)),"Sai","Đúng") -> Đúng | K21: =IF(ISNA(VLOOKUP(E21,DMTK!$B$5:$B$263,1,0)),"Sai","Đúng") -> Đúng | L21: =VLOOKUP(D21,DMTK!$B$5:$D$263,3,0) -> Tiền Việt Nam NH Đông Á | M21: =VLOOKUP(E21,DMTK!$B$5:$D$263,3,0) -> Cty TNHH TMDV Mai Anh (ngắn hạn) | N21: =IF(OR(LEFT($D21,3)="111",AND(LEFT(CT!$D21,3)="131",LEFT(CT!$E21,3)="511"),LEFT(CT!$E21,3)="111",LEFT(CT!$E21,3)="331"),"No","Yes") -> Yes | P21: =IF(LEN(D21)>3,"TKCT","TKTH") -> TKCT | Q21: =IF(LEN(E21)>3,"TKCT","TKTH") -> TKCT
A22: 45306 | B22: 03/PC | C22: Chi lương cho NV QLPX | D22: 3348.01 | E22: 1111 | H22: 35000000 | J22: =IF(ISNA(VLOOKUP(D22,DMTK!$B$5:$B$263,1,0)),"Sai","Đúng") -> Đúng | K22: =IF(ISNA(VLOOKUP(E22,DMTK!$B$5:$B$263,1,0)),"Sai","Đúng") -> Đúng | L22: =VLOOKUP(D22,DMTK!$B$5:$D$263,3,0) -> Lương NV QLPX | M22: =VLOOKUP(E22,DMTK!$B$5:$D$263,3,0) -> Tiền Việt Nam | N22: =IF(OR(LEFT($D22,3)="111",AND(LEFT(CT!$D22,3)="131",LEFT(CT!$E22,3)="511"),LEFT(CT!$E22,3)="111",LEFT(CT!$E22,3)="331"),"No","Yes") -> No | P22: =IF(LEN(D22)>3,"TKCT","TKTH") -> TKCT | Q22: =IF(LEN(E22)>3,"TKCT","TKTH") -> TKCT
A23: 45306 | B23: 03/PC | C23: Chi lương cho CNSX GTV | D23: 3341.01 | E23: 1111 | H23: 40000000 | J23: =IF(ISNA(VLOOKUP(D23,DMTK!$B$5:$B$263,1,0)),"Sai","Đúng") -> Đúng | K23: =IF(ISNA(VLOOKUP(E23,DMTK!$B$5:$B$263,1,0)),"Sai","Đúng") -> Đúng | L23: =VLOOKUP(D23,DMTK!$B$5:$D$263,3,0) -> Lương CNSX Ghế tay vịn | M23: =VLOOKUP(E23,DMTK!$B$5:$D$263,3,0) -> Tiền Việt Nam | N23: =IF(OR(LEFT($D23,3)="111",AND(LEFT(CT!$D23,3)="131",LEFT(CT!$E23,3)="511"),LEFT(CT!$E23,3)="111",LEFT(CT!$E23,3)="331"),"No","Yes") -> No | P23: =IF(LEN(D23)>3,"TKCT","TKTH") -> TKCT | Q23: =IF(LEN(E23)>3,"TKCT","TKTH") -> TKCT
A24: 45306 | B24: 03/PC | C24: Chi lương cho CNSX GKT | D24: 3341.02 | E24: 1111 | H24: 40000000 | J24: =IF(ISNA(VLOOKUP(D24,DMTK!$B$5:$B$263,1,0)),"Sai","Đúng") -> Đúng | K24: =IF(ISNA(VLOOKUP(E24,DMTK!$B$5:$B$263,1,0)),"Sai","Đúng") -> Đúng | L24: =VLOOKUP(D24,DMTK!$B$5:$D$263,3,0) -> Lương CNSX Ghế không tay | M24: =VLOOKUP(E24,DMTK!$B$5:$D$263,3,0) -> Tiền Việt Nam | N24: =IF(OR(LEFT($D24,3)="111",AND(LEFT(CT!$D24,3)="131",LEFT(CT!$E24,3)="511"),LEFT(CT!$E24,3)="111",LEFT(CT!$E24,3)="331"),"No","Yes") -> No | P24: =IF(LEN(D24)>3,"TKCT","TKTH") -> TKCT | Q24: =IF(LEN(E24)>3,"TKCT","TKTH") -> TKCT
A25: 45306 | B25: 03/PC | C25: Chi lương cho CNSX GTV | D25: 3341.03 | E25: 1111 | H25: 40000000 | J25: =IF(ISNA(VLOOKUP(D25,DMTK!$B$5:$B$263,1,0)),"Sai","Đúng") -> Đúng | K25: =IF(ISNA(VLOOKUP(E25,DMTK!$B$5:$B$263,1,0)),"Sai","Đúng") -> Đúng | L25: =VLOOKUP(D25,DMTK!$B$5:$D$263,3,0) -> Lương CNSX Bàn tròn | M25: =VLOOKUP(E25,DMTK!$B$5:$D$263,3,0) -> Tiền Việt Nam | N25: =IF(OR(LEFT($D25,3)="111",AND(LEFT(CT!$D25,3)="131",LEFT(CT!$E25,3)="511"),LEFT(CT!$E25,3)="111",LEFT(CT!$E25,3)="331"),"No","Yes") -> No | P25: =IF(LEN(D25)>3,"TKCT","TKTH") -> TKCT | Q25: =IF(LEN(E25)>3,"TKCT","TKTH") -> TKCT
A26: 45306 | B26: 03/PC | C26: Chi lương cho CNSX BT | D26: 3341.04 | E26: 1111 | H26: 40000000 | J26: =IF(ISNA(VLOOKUP(D26,DMTK!$B$5:$B$263,1,0)),"Sai","Đúng") -> Đúng | K26: =IF(ISNA(VLOOKUP(E26,DMTK!$B$5:$B$263,1,0)),"Sai","Đúng") -> Đúng | L26: =VLOOKUP(D26,DMTK!$B$5:$D$263,3,0) -> Lương CNSX Bàn oval | M26: =VLOOKUP(E26,DMTK!$B$5:$D$263,3,0) -> Tiền Việt Nam | N26: =IF(OR(LEFT($D26,3)="111",AND(LEFT(CT!$D26,3)="131",LEFT(CT!$E26,3)="511"),LEFT(CT!$E26,3)="111",LEFT(CT!$E26,3)="331"),"No","Yes") -> No | P26: =IF(LEN(D26)>3,"TKCT","TKTH") -> TKCT | Q26: =IF(LEN(E26)>3,"TKCT","TKTH") -> TKCT
A27: 45306 | B27: 03/PC | C27: Chi lương cho CNSX BO | D27: 3341.05 | E27: 1111 | H27: 40000000 | J27: =IF(ISNA(VLOOKUP(D27,DMTK!$B$5:$B$263,1,0)),"Sai","Đúng") -> Đúng | K27: =IF(ISNA(VLOOKUP(E27,DMTK!$B$5:$B$263,1,0)),"Sai","Đúng") -> Đúng | L27: =VLOOKUP(D27,DMTK!$B$5:$D$263,3,0) -> Lương CNSX Bàn chữ nhật | M27: =VLOOKUP(E27,DMTK!$B$5:$D$263,3,0) -> Tiền Việt Nam | N27: =IF(OR(LEFT($D27,3)="111",AND(LEFT(CT!$D27,3)="131",LEFT(CT!$E27,3)="511"),LEFT(CT!$E27,3)="111",LEFT(CT!$E27,3)="331"),"No","Yes") -> No | P27: =IF(LEN(D27)>3,"TKCT","TKTH") -> TKCT | Q27: =IF(LEN(E27)>3,"TKCT","TKTH") -> TKCT
A28: 45307 | B28: 01/BN | C28: Trả Cty CP Mai Lan HĐ1170 | D28: 3311.01 | E28: 1121.01 | H28: 40000000 | J28: =IF(ISNA(VLOOKUP(D28,DMTK!$B$5:$B$263,1,0)),"Sai","Đúng") -> Đúng | K28: =IF(ISNA(VLOOKUP(E28,DMTK!$B$5:$B$263,1,0)),"Sai","Đúng") -> Đúng | L28: =VLOOKUP(D28,DMTK!$B$5:$D$263,3,0) -> Cty CP Mai Lan | M28: =VLOOKUP(E28,DMTK!$B$5:$D$263,3,0) -> Tiền Việt Nam NH Ngoại Thương | N28: =IF(OR(LEFT($D28,3)="111",AND(LEFT(CT!$D28,3)="131",LEFT(CT!$E28,3)="511"),LEFT(CT!$E28,3)="111",LEFT(CT!$E28,3)="331"),"No","Yes") -> Yes | P28: =IF(LEN(D28)>3,"TKCT","TKTH") -> TKCT | Q28: =IF(LEN(E28)>3,"TKCT","TKTH") -> TKCT
A29: 45307 | B29: 02/BN | C29: Chi đặt cọc mua hàng | D29: 3311.03 | E29: 1121.01 | H29: 50000000 | J29: =IF(ISNA(VLOOKUP(D29,DMTK!$B$5:$B$263,1,0)),"Sai","Đúng") -> Đúng | K29: =IF(ISNA(VLOOKUP(E29,DMTK!$B$5:$B$263,1,0)),"Sai","Đúng") -> Đúng | L29: =VLOOKUP(D29,DMTK!$B$5:$D$263,3,0) -> Cty TNHH Minh Gia Phát | M29: =VLOOKUP(E29,DMTK!$B$5:$D$263,3,0) -> Tiền Việt Nam NH Ngoại Thương | N29: =IF(OR(LEFT($D29,3)="111",AND(LEFT(CT!$D29,3)="131",LEFT(CT!$E29,3)="511"),LEFT(CT!$E29,3)="111",LEFT(CT!$E29,3)="331"),"No","Yes") -> Yes | P29: =IF(LEN(D29)>3,"TKCT","TKTH") -> TKCT | Q29: =IF(LEN(E29)>3,"TKCT","TKTH") -> TKCT
A30: 45308 | B30: 02/XVL | C30: Xuất ván keo 502 sx BTròn | D30: 6211.03 | E30: 1521.0303 | F30: 20 | G30: 2300 | H30: =F30*G30 -> 46000 | J30: =IF(ISNA(VLOOKUP(D30,DMTK!$B$5:$B$263,1,0)),"Sai","Đúng") -> Đúng | K30: =IF(ISNA(VLOOKUP(E30,DMTK!$B$5:$B$263,1,0)),"Sai","Đúng") -> Đúng | L30: =VLOOKUP(D30,DMTK!$B$5:$D$263,3,0) -> CFNVL Bàn tròn | M30: =VLOOKUP(E30,DMTK!$B$5:$D$263,3,0) -> Keo 502 | N30: =IF(OR(LEFT($D30,3)="111",AND(LEFT(CT!$D30,3)="131",LEFT(CT!$E30,3)="511"),LEFT(CT!$E30,3)="111",LEFT(CT!$E30,3)="331"),"No","Yes") -> Yes | P30: =IF(LEN(D30)>3,"TKCT","TKTH") -> TKCT | Q30: =IF(LEN(E30)>3,"TKCT","TKTH") -> TKCT
A31: 45308 | B31: 03/XVL | C31: Xuất dầu thông sx GTV | D31: 6211.01 | E31: 1521.0403 | F31: 20 | G31: 14111 | H31: =F31*G31 -> 282220 | J31: =IF(ISNA(VLOOKUP(D31,DMTK!$B$5:$B$263,1,0)),"Sai","Đúng") -> Đúng | K31: =IF(ISNA(VLOOKUP(E31,DMTK!$B$5:$B$263,1,0)),"Sai","Đúng") -> Đúng | L31: =VLOOKUP(D31,DMTK!$B$5:$D$263,3,0) -> CFNVL Ghế tay vịn | M31: =VLOOKUP(E31,DMTK!$B$5:$D$263,3,0) -> Dầu thông | N31: =IF(OR(LEFT($D31,3)="111",AND(LEFT(CT!$D31,3)="131",LEFT(CT!$E31,3)="511"),LEFT(CT!$E31,3)="111",LEFT(CT!$E31,3)="331"),"No","Yes") -> Yes | P31: =IF(LEN(D31)>3,"TKCT","TKTH") -> TKCT | Q31: =IF(LEN(E31)>3,"TKCT","TKTH") -> TKCT
A32: 45308 | B32: 03/XVL | C32: Xuất AC chuối sx GTV | D32: 6211.01 | E32: 1521.0401 | F32: 30 | G32: 15666 | H32: =F32*G32 -> 469980 | J32: =IF(ISNA(VLOOKUP(D32,DMTK!$B$5:$B$263,1,0)),"Sai","Đúng") -> Đúng | K32: =IF(ISNA(VLOOKUP(E32,DMTK!$B$5:$B$263,1,0)),"Sai","Đúng") -> Đúng | L32: =VLOOKUP(D32,DMTK!$B$5:$D$263,3,0) -> CFNVL Ghế tay vịn | M32: =VLOOKUP(E32,DMTK!$B$5:$D$263,3,0) -> AC chuối | N32: =IF(OR(LEFT($D32,3)="111",AND(LEFT(CT!$D32,3)="131",LEFT(CT!$E32,3)="511"),LEFT(CT!$E32,3)="111",LEFT(CT!$E32,3)="331"),"No","Yes") -> Yes | P32: =IF(LEN(D32)>3,"TKCT","TKTH") -> TKCT | Q32: =IF(LEN(E32)>3,"TKCT","TKTH") -> TKCT
A33: 45308 | B33: 02/XVL | C33: Xuất ván MDF 9x6x8 sx BTròn | D33: 6211.03 | E33: 1521.0201 | F33: 30 | G33: 120000 | H33: =F33*G33 -> 3600000 | J33: =IF(ISNA(VLOOKUP(D33,DMTK!$B$5:$B$263,1,0)),"Sai","Đúng") -> Đúng | K33: =IF(ISNA(VLOOKUP(E33,DMTK!$B$5:$B$263,1,0)),"Sai","Đúng") -> Đúng | L33: =VLOOKUP(D33,DMTK!$B$5:$D$263,3,0) -> CFNVL Bàn tròn | M33: =VLOOKUP(E33,DMTK!$B$5:$D$263,3,0) -> Ván MDF 9x6x8 | N33: =IF(OR(LEFT($D33,3)="111",AND(LEFT(CT!$D33,3)="131",LEFT(CT!$E33,3)="511"),LEFT(CT!$E33,3)="111",LEFT(CT!$E33,3)="331"),"No","Yes") -> Yes | P33: =IF(LEN(D33)>3,"TKCT","TKTH") -> TKCT | Q33: =IF(LEN(E33)>3,"TKCT","TKTH") -> TKCT
A34: 45309 | B34: 01/XCC | C34: Xuất kệ tủ | D34: 2421.02 | E34: 1531.02 | F34: 4 | G34: 250000 | H34: =F34*G34 -> 1000000 | J34: =IF(ISNA(VLOOKUP(D34,DMTK!$B$5:$B$263,1,0)),"Sai","Đúng") -> Đúng | K34: =IF(ISNA(VLOOKUP(E34,DMTK!$B$5:$B$263,1,0)),"Sai","Đúng") -> Đúng | L34: =VLOOKUP(D34,DMTK!$B$5:$D$263,3,0) -> Kệ tủ (không quá 12 tháng) | M34: =VLOOKUP(E34,DMTK!$B$5:$D$263,3,0) -> Kệ tủ | N34: =IF(OR(LEFT($D34,3)="111",AND(LEFT(CT!$D34,3)="131",LEFT(CT!$E34,3)="511"),LEFT(CT!$E34,3)="111",LEFT(CT!$E34,3)="331"),"No","Yes") -> Yes | P34: =IF(LEN(D34)>3,"TKCT","TKTH") -> TKCT | Q34: =IF(LEN(E34)>3,"TKCT","TKTH") -> TKCT
A35: 45309 | B35: 01/XCC | C35: Xuất máy tính Casio | D35: 2421.01 | E35: 1531.01 | F35: 5 | G35: 500000 | H35: =F35*G35 -> 2500000 | J35: =IF(ISNA(VLOOKUP(D35,DMTK!$B$5:$B$263,1,0)),"Sai","Đúng") -> Đúng | K35: =IF(ISNA(VLOOKUP(E35,DMTK!$B$5:$B$263,1,0)),"Sai","Đúng") -> Đúng | L35: =VLOOKUP(D35,DMTK!$B$5:$D$263,3,0) -> Máy tính Casio (không quá 12 tháng) | M35: =VLOOKUP(E35,DMTK!$B$5:$D$263,3,0) -> Máy tính Casio | N35: =IF(OR(LEFT($D35,3)="111",AND(LEFT(CT!$D35,3)="131",LEFT(CT!$E35,3)="511"),LEFT(CT!$E35,3)="111",LEFT(CT!$E35,3)="331"),"No","Yes") -> Yes | P35: =IF(LEN(D35)>3,"TKCT","TKTH") -> TKCT | Q35: =IF(LEN(E35)>3,"TKCT","TKTH") -> TKCT
A36: 45310 | B36: 02/XCC | C36: Xuất lưỡi cưa cho PXSX | D36: 6273 | E36: 1531.03 | F36: 10 | G36: 10000 | H36: =F36*G36 -> 100000 | J36: =IF(ISNA(VLOOKUP(D36,DMTK!$B$5:$B$263,1,0)),"Sai","Đúng") -> Đúng | K36: =IF(ISNA(VLOOKUP(E36,DMTK!$B$5:$B$263,1,0)),"Sai","Đúng") -> Đúng | L36: =VLOOKUP(D36,DMTK!$B$5:$D$263,3,0) -> Chi phí dụng cụ sản xuất | M36: =VLOOKUP(E36,DMTK!$B$5:$D$263,3,0) -> Lưỡi cưa | N36: =IF(OR(LEFT($D36,3)="111",AND(LEFT(CT!$D36,3)="131",LEFT(CT!$E36,3)="511"),LEFT(CT!$E36,3)="111",LEFT(CT!$E36,3)="331"),"No","Yes") -> Yes | P36: =IF(LEN(D36)>3,"TKCT","TKTH") -> TKCT | Q36: =IF(LEN(E36)>3,"TKCT","TKTH") -> TKCT
A37: 45310 | B37: 02/XCC | C37: Xuất mũi khoan cho PXSX | D37: 6273 | E37: 1531.04 | F37: 20 | G37: 5000 | H37: =F37*G37 -> 100000 | J37: =IF(ISNA(VLOOKUP(D37,DMTK!$B$5:$B$263,1,0)),"Sai","Đúng") -> Đúng | K37: =IF(ISNA(VLOOKUP(E37,DMTK!$B$5:$B$263,1,0)),"Sai","Đúng") -> Đúng | L37: =VLOOKUP(D37,DMTK!$B$5:$D$263,3,0) -> Chi phí dụng cụ sản xuất | M37: =VLOOKUP(E37,DMTK!$B$5:$D$263,3,0) -> Mũi khoan | N37: =IF(OR(LEFT($D37,3)="111",AND(LEFT(CT!$D37,3)="131",LEFT(CT!$E37,3)="511"),LEFT(CT!$E37,3)="111",LEFT(CT!$E37,3)="331"),"No","Yes") -> Yes | P37: =IF(LEN(D37)>3,"TKCT","TKTH") -> TKCT | Q37: =IF(LEN(E37)>3,"TKCT","TKTH") -> TKCT
A38: 45310 | B38: 02/XCC | C38: Xuất dao thép cho PXSX | D38: 6273 | E38: 1531.05 | F38: 30 | G38: 10000 | H38: =F38*G38 -> 300000 | J38: =IF(ISNA(VLOOKUP(D38,DMTK!$B$5:$B$263,1,0)),"Sai","Đúng") -> Đúng | K38: =IF(ISNA(VLOOKUP(E38,DMTK!$B$5:$B$263,1,0)),"Sai","Đúng") -> Đúng | L38: =VLOOKUP(D38,DMTK!$B$5:$D$263,3,0) -> Chi phí dụng cụ sản xuất | M38: =VLOOKUP(E38,DMTK!$B$5:$D$263,3,0) -> Dao thép | N38: =IF(OR(LEFT($D38,3)="111",AND(LEFT(CT!$D38,3)="131",LEFT(CT!$E38,3)="511"),LEFT(CT!$E38,3)="111",LEFT(CT!$E38,3)="331"),"No","Yes") -> Yes | P38: =IF(LEN(D38)>3,"TKCT","TKTH") -> TKCT | Q38: =IF(LEN(E38)>3,"TKCT","TKTH") -> TKCT
A39: 45314 | B39: 02/NTP | C39: Tạm nhập kho BT | D39: 1551.0201 | E39: 154.03 | F39: 200 | G39: 300000 | H39: 60000000 | J39: =IF(ISNA(VLOOKUP(D39,DMTK!$B$5:$B$263,1,0)),"Sai","Đúng") -> Đúng | K39: =IF(ISNA(VLOOKUP(E39,DMTK!$B$5:$B$263,1,0)),"Sai","Đúng") -> Đúng | L39: =VLOOKUP(D39,DMTK!$B$5:$D$263,3,0) -> Bàn tròn | M39: =VLOOKUP(E39,DMTK!$B$5:$D$263,3,0) -> Bàn tròn | N39: =IF(OR(LEFT($D39,3)="111",AND(LEFT(CT!$D39,3)="131",LEFT(CT!$E39,3)="511"),LEFT(CT!$E39,3)="111",LEFT(CT!$E39,3)="331"),"No","Yes") -> Yes | P39: =IF(LEN(D39)>3,"TKCT","TKTH") -> TKCT | Q39: =IF(LEN(E39)>3,"TKCT","TKTH") -> TKCT
A40: 45314 | B40: 01/NTP | C40: Tạm nhập kho GTV | D40: 1551.0101 | E40: 154.01 | F40: 405 | G40: 250000 | H40: 101250000 | J40: =IF(ISNA(VLOOKUP(D40,DMTK!$B$5:$B$263,1,0)),"Sai","Đúng") -> Đúng | K40: =IF(ISNA(VLOOKUP(E40,DMTK!$B$5:$B$263,1,0)),"Sai","Đúng") -> Đúng | L40: =VLOOKUP(D40,DMTK!$B$5:$D$263,3,0) -> Ghế tay vịn | M40: =VLOOKUP(E40,DMTK!$B$5:$D$263,3,0) -> Ghế tay vịn | N40: =IF(OR(LEFT($D40,3)="111",AND(LEFT(CT!$D40,3)="131",LEFT(CT!$E40,3)="511"),LEFT(CT!$E40,3)="111",LEFT(CT!$E40,3)="331"),"No","Yes") -> Yes | P40: =IF(LEN(D40)>3,"TKCT","TKTH") -> TKCT | Q40: =IF(LEN(E40)>3,"TKCT","TKTH") -> TKCT
A41: 45315 | B41: 03/NTP | C41: Tạm nhập kho GKT | D41: 1551.0102 | E41: 154.02 | F41: 300 | G41: 200000 | H41: 60000000 | J41: =IF(ISNA(VLOOKUP(D41,DMTK!$B$5:$B$263,1,0)),"Sai","Đúng") -> Đúng | K41: =IF(ISNA(VLOOKUP(E41,DMTK!$B$5:$B$263,1,0)),"Sai","Đúng") -> Đúng | L41: =VLOOKUP(D41,DMTK!$B$5:$D$263,3,0) -> Ghế không tay | M41: =VLOOKUP(E41,DMTK!$B$5:$D$263,3,0) -> Ghế không tay | N41: =IF(OR(LEFT($D41,3)="111",AND(LEFT(CT!$D41,3)="131",LEFT(CT!$E41,3)="511"),LEFT(CT!$E41,3)="111",LEFT(CT!$E41,3)="331"),"No","Yes") -> Yes | P41: =IF(LEN(D41)>3,"TKCT","TKTH") -> TKCT | Q41: =IF(LEN(E41)>3,"TKCT","TKTH") -> TKCT
...

Sheet HTTK1
A1: HỆ THỐNG TÀI KHOẢN CẤP 1
A3: TK | B3: Loại TK | C3: TÊN TK | D3: SDDK1 | E3: DKNO1 | F3: DKCO1
A4: 1 | B4: 2 | C4: 3 | D4: 4 | E4: 5 | F4: 6
A5: 111 | B5: N | C5: Tiền Mặt | D5: =SUMIFS(DMTK!$F$5:$F$263,DMTK!$B$5:$B$263,HTTK1!A5 & "*") -> 400000000 | E5: =IF(OR(AND(B5="N",D5>0),AND(B5="C",D5<0)),ABS(D5),0) -> 400000000 | F5: =IF(OR(AND(B5="C",D5>0),AND(B5="N",D5<0)),ABS(D5),0) -> 0
A6: 112 | B6: N | C6: Tiền gửi Ngân Hàng | D6: =SUMIFS(DMTK!$F$5:$F$263,DMTK!$B$5:$B$263,HTTK1!A6 & "*") -> 358221000 | E6: =IF(OR(AND(B6="N",D6>0),AND(B6="C",D6<0)),ABS(D6),0) -> 358221000 | F6: =IF(OR(AND(B6="C",D6>0),AND(B6="N",D6<0)),ABS(D6),0) -> 0
A7: 113 | B7: N | C7: Tiền đang chuyển | D7: =SUMIFS(DMTK!$F$5:$F$263,DMTK!$B$5:$B$263,HTTK1!A7 & "*") -> 0 | E7: =IF(OR(AND(B7="N",D7>0),AND(B7="C",D7<0)),ABS(D7),0) -> 0 | F7: =IF(OR(AND(B7="C",D7>0),AND(B7="N",D7<0)),ABS(D7),0) -> 0
A8: 121 | B8: N | C8: Chứng khoán kinh doanh | D8: =SUMIFS(DMTK!$F$5:$F$263,DMTK!$B$5:$B$263,HTTK1!A8 & "*") -> 0 | E8: =IF(OR(AND(B8="N",D8>0),AND(B8="C",D8<0)),ABS(D8),0) -> 0 | F8: =IF(OR(AND(B8="C",D8>0),AND(B8="N",D8<0)),ABS(D8),0) -> 0
A9: 128 | B9: N | C9: Đầu tư nắm giữ đến ngày đáo hạn | D9: =SUMIFS(DMTK!$F$5:$F$263,DMTK!$B$5:$B$263,HTTK1!A9 & "*") -> 100000000 | E9: =IF(OR(AND(B9="N",D9>0),AND(B9="C",D9<0)),ABS(D9),0) -> 100000000 | F9: =IF(OR(AND(B9="C",D9>0),AND(B9="N",D9<0)),ABS(D9),0) -> 0
A10: 131 | B10: N | C10: Phải thu của khách hàng | D10: =SUMIFS(DMTK!$F$5:$F$263,DMTK!$B$5:$B$263,HTTK1!A10 & "*") -> 175000000 | E10: =IF(OR(AND(B10="N",D10>0),AND(B10="C",D10<0)),ABS(D10),0) -> 175000000 | F10: =IF(OR(AND(B10="C",D10>0),AND(B10="N",D10<0)),ABS(D10),0) -> 0
A11: 133 | B11: N | C11: Thuế GTGT được khấu trừ | D11: =SUMIFS(DMTK!$F$5:$F$263,DMTK!$B$5:$B$263,HTTK1!A11 & "*") -> 0 | E11: =IF(OR(AND(B11="N",D11>0),AND(B11="C",D11<0)),ABS(D11),0) -> 0 | F11: =IF(OR(AND(B11="C",D11>0),AND(B11="N",D11<0)),ABS(D11),0) -> 0
A12: 136 | B12: N | C12: Phải thu nội bộ | D12: =SUMIFS(DMTK!$F$5:$F$263,DMTK!$B$5:$B$263,HTTK1!A12 & "*") -> 0 | E12: =IF(OR(AND(B12="N",D12>0),AND(B12="C",D12<0)),ABS(D12),0) -> 0 | F12: =IF(OR(AND(B12="C",D12>0),AND(B12="N",D12<0)),ABS(D12),0) -> 0
A13: 138 | B13: N | C13: Phải thu khác | D13: =SUMIFS(DMTK!$F$5:$F$263,DMTK!$B$5:$B$263,HTTK1!A13 & "*") -> 52200000 | E13: =IF(OR(AND(B13="N",D13>0),AND(B13="C",D13<0)),ABS(D13),0) -> 52200000 | F13: =IF(OR(AND(B13="C",D13>0),AND(B13="N",D13<0)),ABS(D13),0) -> 0
A14: 141 | B14: N | C14: Tạm ứng | D14: =SUMIFS(DMTK!$F$5:$F$263,DMTK!$B$5:$B$263,HTTK1!A14 & "*") -> 3500000 | E14: =IF(OR(AND(B14="N",D14>0),AND(B14="C",D14<0)),ABS(D14),0) -> 3500000 | F14: =IF(OR(AND(B14="C",D14>0),AND(B14="N",D14<0)),ABS(D14),0) -> 0
A15: 151 | B15: N | C15: Hàng mua đang đi đường | D15: =SUMIFS(DMTK!$F$5:$F$263,DMTK!$B$5:$B$263,HTTK1!A15 & "*") -> 0 | E15: =IF(OR(AND(B15="N",D15>0),AND(B15="C",D15<0)),ABS(D15),0) -> 0 | F15: =IF(OR(AND(B15="C",D15>0),AND(B15="N",D15<0)),ABS(D15),0) -> 0
A16: 152 | B16: N | C16: Nguyên liệu, vật liệu | D16: =SUMIFS(DMTK!$F$5:$F$263,DMTK!$B$5:$B$263,HTTK1!A16 & "*") -> 147540000 | E16: =IF(OR(AND(B16="N",D16>0),AND(B16="C",D16<0)),ABS(D16),0) -> 147540000 | F16: =IF(OR(AND(B16="C",D16>0),AND(B16="N",D16<0)),ABS(D16),0) -> 0
... A80: 911 | B80: C | C80: Xác định kết quả kinh doanh | D80: =SUMIFS(DMTK!$F$5:$F$263,DMTK!$B$5:$B$263,HTTK1!A80 & "*") -> 0 | E80: =IF(OR(AND(B80="N",D80>0),AND(B80="C",D80<0)),ABS(D80),0) -> 0 | F80: =IF(OR(AND(B80="C",D80>0),AND(B80="N",D80<0)),ABS(D80),0) -> 0
E81: =SUM(E5:E80) -> 3407449000 | F81: =SUM(F5:F80) -> 3407449000

Sheet NKTT
A1: NHẬT KÝ THU TIỀN
F2: Số hiệu | G2: 111
A5: Chứng từ | C5: Diễn giải | D5: Ghi nợ TK 111 | E5: Ghi có các tài khoản
A6: Ngày | B6: Số | E6: 112 | F6: 131 | G6: 141 | H6: 511 | I6: Tài khoản
I7: Số tiền | J7: Số hiệu
A8: [1] | B8: [2] | C8: [3] | D8: [4] | E8: [5] | F8: [6] | G8: [7] | H8: [8] | I8: [9] | J8: [10]
A9: =IF(LEFT(CT!$D5,3)=NKTT!$G$2,CT!A5,"") -> 45293 | B9: =IF(LEFT(CT!$D5,3)=NKTT!$G$2,CT!B5,"") -> 01/PT | C9: =IF(LEFT(CT!$D5,3)=NKTT!$G$2,CT!C5,"") -> Thu nợ lô hàng 200 | D9: =IF(LEFT(CT!$D5,3)=NKTT!$G$2,CT!H5,0) -> 5000000 | E9: =IF(AND(LEFT(CT!$D5,3)=NKTT!$G$2,LEFT(CT!$E5,3)=NKTT!$E$6),CT!$H5,0) -> 0 | F9: =IF(AND(LEFT(CT!$D5,3)=NKTT!$G$2,LEFT(CT!$E5,3)=NKTT!$F$6),CT!$H5,0) -> 5000000 | G9: =IF(AND(LEFT(CT!$D5,3)=NKTT!$G$2,LEFT(CT!$E5,3)=NKTT!$G$6),CT!$H5,0) -> 0 | H9: =IF(AND(LEFT(CT!$D5,3)=NKTT!$G$2,LEFT(CT!$E5,3)=NKTT!$H$6),CT!$H5,0) -> 0 | I9: =IF(SUM(E9:H9)=0,D9,0) -> 0 | J9: =IF(I9>0,CT!E5,"")
A10: =IF(LEFT(CT!$D6,3)=NKTT!$G$2,CT!A6,"") -> 45293 | B10: =IF(LEFT(CT!$D6,3)=NKTT!$G$2,CT!B6,"") -> 02/PT | C10: =IF(LEFT(CT!$D6,3)=NKTT!$G$2,CT!C6,"") -> Thu nợ lô hàng 212 | D10: =IF(LEFT(CT!$D6,3)=NKTT!$G$2,CT!H6,0) -> 20000000 | E10: =IF(AND(LEFT(CT!$D6,3)=NKTT!$G$2,LEFT(CT!$E6,3)=NKTT!$E$6),CT!$H6,0) -> 0 | F10: =IF(AND(LEFT(CT!$D6,3)=NKTT!$G$2,LEFT(CT!$E6,3)=NKTT!$F$6),CT!$H6,0) -> 20000000 | G10: =IF(AND(LEFT(CT!$D6,3)=NKTT!$G$2,LEFT(CT!$E6,3)=NKTT!$G$6),CT!$H6,0) -> 0 | H10: =IF(AND(LEFT(CT!$D6,3)=NKTT!$G$2,LEFT(CT!$E6,3)=NKTT!$H$6),CT!$H6,0) -> 0 | I10: =IF(SUM(E10:H10)=0,D10,0) -> 0 | J10: =IF(I10>0,CT!E6,"")
A11: =IF(LEFT(CT!$D7,3)=NKTT!$G$2,CT!A7,"") | B11: =IF(LEFT(CT!$D7,3)=NKTT!$G$2,CT!B7,"") | C11: =IF(LEFT(CT!$D7,3)=NKTT!$G$2,CT!C7,"") | D11: =IF(LEFT(CT!$D7,3)=NKTT!$G$2,CT!H7,0) -> 0 | E11: =IF(AND(LEFT(CT!$D7,3)=NKTT!$G$2,LEFT(CT!$E7,3)=NKTT!$E$6),CT!$H7,0) -> 0 | F11: =IF(AND(LEFT(CT!$D7,3)=NKTT!$G$2,LEFT(CT!$E7,3)=NKTT!$F$6),CT!$H7,0) -> 0 | G11: =IF(AND(LEFT(CT!$D7,3)=NKTT!$G$2,LEFT(CT!$E7,3)=NKTT!$G$6),CT!$H7,0) -> 0 | H11: =IF(AND(LEFT(CT!$D7,3)=NKTT!$G$2,LEFT(CT!$E7,3)=NKTT!$H$6),CT!$H7,0) -> 0 | I11: =IF(SUM(E11:H11)=0,D11,0) -> 0 | J11: =IF(I11>0,CT!E7,"")
A12: =IF(LEFT(CT!$D8,3)=NKTT!$G$2,CT!A8,"") | B12: =IF(LEFT(CT!$D8,3)=NKTT!$G$2,CT!B8,"") | C12: =IF(LEFT(CT!$D8,3)=NKTT!$G$2,CT!C8,"") | D12: =IF(LEFT(CT!$D8,3)=NKTT!$G$2,CT!H8,0) -> 0 | E12: =IF(AND(LEFT(CT!$D8,3)=NKTT!$G$2,LEFT(CT!$E8,3)=NKTT!$E$6),CT!$H8,0) -> 0 | F12: =IF(AND(LEFT(CT!$D8,3)=NKTT!$G$2,LEFT(CT!$E8,3)=NKTT!$F$6),CT!$H8,0) -> 0 | G12: =IF(AND(LEFT(CT!$D8,3)=NKTT!$G$2,LEFT(CT!$E8,3)=NKTT!$G$6),CT!$H8,0) -> 0 | H12: =IF(AND(LEFT(CT!$D8,3)=NKTT!$G$2,LEFT(CT!$E8,3)=NKTT!$H$6),CT!$H8,0) -> 0 | I12: =IF(SUM(E12:H12)=0,D12,0) -> 0 | J12: =IF(I12>0,CT!E8,"")
A13: =IF(LEFT(CT!$D9,3)=NKTT!$G$2,CT!A9,"") | B13: =IF(LEFT(CT!$D9,3)=NKTT!$G$2,CT!B9,"") | C13: =IF(LEFT(CT!$D9,3)=NKTT!$G$2,CT!C9,"") | D13: =IF(LEFT(CT!$D9,3)=NKTT!$G$2,CT!H9,0) -> 0 | E13: =IF(AND(LEFT(CT!$D9,3)=NKTT!$G$2,LEFT(CT!$E9,3)=NKTT!$E$6),CT!$H9,0) -> 0 | F13: =IF(AND(LEFT(CT!$D9,3)=NKTT!$G$2,LEFT(CT!$E9,3)=NKTT!$F$6),CT!$H9,0) -> 0 | G13: =IF(AND(LEFT(CT!$D9,3)=NKTT!$G$2,LEFT(CT!$E9,3)=NKTT!$G$6),CT!$H9,0) -> 0 | H13: =IF(AND(LEFT(CT!$D9,3)=NKTT!$G$2,LEFT(CT!$E9,3)=NKTT!$H$6),CT!$H9,0) -> 0 | I13: =IF(SUM(E13:H13)=0,D13,0) -> 0 | J13: =IF(I13>0,CT!E9,"")
A14: =IF(LEFT(CT!$D10,3)=NKTT!$G$2,CT!A10,"") | B14: =IF(LEFT(CT!$D10,3)=NKTT!$G$2,CT!B10,"") | C14: =IF(LEFT(CT!$D10,3)=NKTT!$G$2,CT!C10,"") | D14: =IF(LEFT(CT!$D10,3)=NKTT!$G$2,CT!H10,0) -> 0 | E14: =IF(AND(LEFT(CT!$D10,3)=NKTT!$G$2,LEFT(CT!$E10,3)=NKTT!$E$6),CT!$H10,0) -> 0 | F14: =IF(AND(LEFT(CT!$D10,3)=NKTT!$G$2,LEFT(CT!$E10,3)=NKTT!$F$6),CT!$H10,0) -> 0 | G14: =IF(AND(LEFT(CT!$D10,3)=NKTT!$G$2,LEFT(CT!$E10,3)=NKTT!$G$6),CT!$H10,0) -> 0 | H14: =IF(AND(LEFT(CT!$D10,3)=NKTT!$G$2,LEFT(CT!$E10,3)=NKTT!$H$6),CT!$H10,0) -> 0 | I14: =IF(SUM(E14:H14)=0,D14,0) -> 0 | J14: =IF(I14>0,CT!E10,"")
A15: =IF(LEFT(CT!$D11,3)=NKTT!$G$2,CT!A11,"") | B15: =IF(LEFT(CT!$D11,3)=NKTT!$G$2,CT!B11,"") | C15: =IF(LEFT(CT!$D11,3)=NKTT!$G$2,CT!C11,"") | D15: =IF(LEFT(CT!$D11,3)=NKTT!$G$2,CT!H11,0) -> 0 | E15: =IF(AND(LEFT(CT!$D11,3)=NKTT!$G$2,LEFT(CT!$E11,3)=NKTT!$E$6),CT!$H11,0) -> 0 | F15: =IF(AND(LEFT(CT!$D11,3)=NKTT!$G$2,LEFT(CT!$E11,3)=NKTT!$F$6),CT!$H11,0) -> 0 | G15: =IF(AND(LEFT(CT!$D11,3)=NKTT!$G$2,LEFT(CT!$E11,3)=NKTT!$G$6),CT!$H11,0) -> 0 | H15: =IF(AND(LEFT(CT!$D11,3)=NKTT!$G$2,LEFT(CT!$E11,3)=NKTT!$H$6),CT!$H11,0) -> 0 | I15: =IF(SUM(E15:H15)=0,D15,0) -> 0 | J15: =IF(I15>0,CT!E11,"")
A16: =IF(LEFT(CT!$D12,3)=NKTT!$G$2,CT!A12,"") | B16: =IF(LEFT(CT!$D12,3)=NKTT!$G$2,CT!B12,"") | C16: =IF(LEFT(CT!$D12,3)=NKTT!$G$2,CT!C12,"") | D16: =IF(LEFT(CT!$D12,3)=NKTT!$G$2,CT!H12,0) -> 0 | E16: =IF(AND(LEFT(CT!$D12,3)=NKTT!$G$2,LEFT(CT!$E12,3)=NKTT!$E$6),CT!$H12,0) -> 0 | F16: =IF(AND(LEFT(CT!$D12,3)=NKTT!$G$2,LEFT(CT!$E12,3)=NKTT!$F$6),CT!$H12,0) -> 0 | G16: =IF(AND(LEFT(CT!$D12,3)=NKTT!$G$2,LEFT(CT!$E12,3)=NKTT!$G$6),CT!$H12,0) -> 0 | H16: =IF(AND(LEFT(CT!$D12,3)=NKTT!$G$2,LEFT(CT!$E12,3)=NKTT!$H$6),CT!$H12,0) -> 0 | I16: =IF(SUM(E16:H16)=0,D16,0) -> 0 | J16: =IF(I16>0,CT!E12,"")
A17: =IF(LEFT(CT!$D13,3)=NKTT!$G$2,CT!A13,"") | B17: =IF(LEFT(CT!$D13,3)=NKTT!$G$2,CT!B13,"") | C17: =IF(LEFT(CT!$D13,3)=NKTT!$G$2,CT!C13,"") | D17: =IF(LEFT(CT!$D13,3)=NKTT!$G$2,CT!H13,0) -> 0 | E17: =IF(AND(LEFT(CT!$D13,3)=NKTT!$G$2,LEFT(CT!$E13,3)=NKTT!$E$6),CT!$H13,0) -> 0 | F17: =IF(AND(LEFT(CT!$D13,3)=NKTT!$G$2,LEFT(CT!$E13,3)=NKTT!$F$6),CT!$H13,0) -> 0 | G17: =IF(AND(LEFT(CT!$D13,3)=NKTT!$G$2,LEFT(CT!$E13,3)=NKTT!$G$6),CT!$H13,0) -> 0 | H17: =IF(AND(LEFT(CT!$D13,3)=NKTT!$G$2,LEFT(CT!$E13,3)=NKTT!$H$6),CT!$H13,0) -> 0 | I17: =IF(SUM(E17:H17)=0,D17,0) -> 0 | J17: =IF(I17>0,CT!E13,"")
A18: =IF(LEFT(CT!$D14,3)=NKTT!$G$2,CT!A14,"") | B18: =IF(LEFT(CT!$D14,3)=NKTT!$G$2,CT!B14,"") | C18: =IF(LEFT(CT!$D14,3)=NKTT!$G$2,CT!C14,"") | D18: =IF(LEFT(CT!$D14,3)=NKTT!$G$2,CT!H14,0) -> 0 | E18: =IF(AND(LEFT(CT!$D14,3)=NKTT!$G$2,LEFT(CT!$E14,3)=NKTT!$E$6),CT!$H14,0) -> 0 | F18: =IF(AND(LEFT(CT!$D14,3)=NKTT!$G$2,LEFT(CT!$E14,3)=NKTT!$F$6),CT!$H14,0) -> 0 | G18: =IF(AND(LEFT(CT!$D14,3)=NKTT!$G$2,LEFT(CT!$E14,3)=NKTT!$G$6),CT!$H14,0) -> 0 | H18: =IF(AND(LEFT(CT!$D14,3)=NKTT!$G$2,LEFT(CT!$E14,3)=NKTT!$H$6),CT!$H14,0) -> 0 | I18: =IF(SUM(E18:H18)=0,D18,0) -> 0 | J18: =IF(I18>0,CT!E14,"")
A19: =IF(LEFT(CT!$D15,3)=NKTT!$G$2,CT!A15,"") | B19: =IF(LEFT(CT!$D15,3)=NKTT!$G$2,CT!B15,"") | C19: =IF(LEFT(CT!$D15,3)=NKTT!$G$2,CT!C15,"") | D19: =IF(LEFT(CT!$D15,3)=NKTT!$G$2,CT!H15,0) -> 0 | E19: =IF(AND(LEFT(CT!$D15,3)=NKTT!$G$2,LEFT(CT!$E15,3)=NKTT!$E$6),CT!$H15,0) -> 0 | F19: =IF(AND(LEFT(CT!$D15,3)=NKTT!$G$2,LEFT(CT!$E15,3)=NKTT!$F$6),CT!$H15,0) -> 0 | G19: =IF(AND(LEFT(CT!$D15,3)=NKTT!$G$2,LEFT(CT!$E15,3)=NKTT!$G$6),CT!$H15,0) -> 0 | H19: =IF(AND(LEFT(CT!$D15,3)=NKTT!$G$2,LEFT(CT!$E15,3)=NKTT!$H$6),CT!$H15,0) -> 0 | I19: =IF(SUM(E19:H19)=0,D19,0) -> 0 | J19: =IF(I19>0,CT!E15,"")
A20: =IF(LEFT(CT!$D16,3)=NKTT!$G$2,CT!A16,"") | B20: =IF(LEFT(CT!$D16,3)=NKTT!$G$2,CT!B16,"") | C20: =IF(LEFT(CT!$D16,3)=NKTT!$G$2,CT!C16,"") | D20: =IF(LEFT(CT!$D16,3)=NKTT!$G$2,CT!H16,0) -> 0 | E20: =IF(AND(LEFT(CT!$D16,3)=NKTT!$G$2,LEFT(CT!$E16,3)=NKTT!$E$6),CT!$H16,0) -> 0 | F20: =IF(AND(LEFT(CT!$D16,3)=NKTT!$G$2,LEFT(CT!$E16,3)=NKTT!$F$6),CT!$H16,0) -> 0 | G20: =IF(AND(LEFT(CT!$D16,3)=NKTT!$G$2,LEFT(CT!$E16,3)=NKTT!$G$6),CT!$H16,0) -> 0 | H20: =IF(AND(LEFT(CT!$D16,3)=NKTT!$G$2,LEFT(CT!$E16,3)=NKTT!$H$6),CT!$H16,0) -> 0 | I20: =IF(SUM(E20:H20)=0,D20,0) -> 0 | J20: =IF(I20>0,CT!E16,"")
... A147: =IF(LEFT(CT!$D143,3)=NKTT!$G$2,CT!A143,"") | B147: =IF(LEFT(CT!$D143,3)=NKTT!$G$2,CT!B143,"") | C147: =IF(LEFT(CT!$D143,3)=NKTT!$G$2,CT!C143,"") | D147: =IF(LEFT(CT!$D143,3)=NKTT!$G$2,CT!H143,0) -> 0 | E147: =IF(AND(LEFT(CT!$D143,3)=NKTT!$G$2,LEFT(CT!$E143,3)=NKTT!$E$6),CT!$H143,0) -> 0 | F147: =IF(AND(LEFT(CT!$D143,3)=NKTT!$G$2,LEFT(CT!$E143,3)=NKTT!$F$6),CT!$H143,0) -> 0 | G147: =IF(AND(LEFT(CT!$D143,3)=NKTT!$G$2,LEFT(CT!$E143,3)=NKTT!$G$6),CT!$H143,0) -> 0 | H147: =IF(AND(LEFT(CT!$D143,3)=NKTT!$G$2,LEFT(CT!$E143,3)=NKTT!$H$6),CT!$H143,0) -> 0 | I147: =IF(SUM(E147:H147)=0,D147,0) -> 0 | J147: =IF(I147>0,CT!E143,"")
C148: Tổng cộng: | D148: =SUM(D9:D147) -> 25200000 | E148: =SUM(E9:E147) -> 0 | F148: =SUM(F9:F147) -> 25000000 | G148: =SUM(G9:G147) -> 200000 | H148: =SUM(H9:H147) -> 0 | I148: =SUM(I9:I147) -> 0

Sheet NKBH
A1: NHẬT KÝ BÁN HÀNG
D2: Số hiệu: | E2: 131
A4: Chứng từ | C4: Diễn giải | D4: Phải thu từ người mua | E4: Ghi có tài khoản doanh thu
A5: Ngày | B5: Số | E5: Hàng hóa | F5: thành phẩm | G5: Dịch vụ
A6: 1 | B6: 2 | C6: 3 | D6: 4 | E6: 5 | F6: 6 | G6: 7
A7: =IF(AND(LEFT(CT!$D5,3)=NKBH!$E$2,LEFT(CT!$E5,3)="511"),CT!A5,"") | B7: =IF(AND(LEFT(CT!$D5,3)=NKBH!$E$2,LEFT(CT!$E5,3)="511"),CT!B5,"") | C7: =IF(AND(LEFT(CT!$D5,3)=NKBH!$E$2,LEFT(CT!$E5,3)="511"),CT!C5,"") | D7: =IF(AND(LEFT(CT!$D5,3)=NKBH!$E$2,LEFT(CT!$E5,3)="511"),CT!H5,"") | E7: =IF(LEFT(CT!$E5,4)="5111",CT!$H5,0) -> 0 | F7: =IF(LEFT(CT!$E5,4)="5112",CT!$H5,0) -> 0 | G7: =IF(LEFT(CT!$E5,4)="5113",CT!$H5,0) -> 0
A8: =IF(AND(LEFT(CT!$D6,3)=NKBH!$E$2,LEFT(CT!$E6,3)="511"),CT!A6,"") | B8: =IF(AND(LEFT(CT!$D6,3)=NKBH!$E$2,LEFT(CT!$E6,3)="511"),CT!B6,"") | C8: =IF(AND(LEFT(CT!$D6,3)=NKBH!$E$2,LEFT(CT!$E6,3)="511"),CT!C6,"") | D8: =IF(AND(LEFT(CT!$D6,3)=NKBH!$E$2,LEFT(CT!$E6,3)="511"),CT!H6,"") | E8: =IF(LEFT(CT!$E6,4)="5111",CT!$H6,0) -> 0 | F8: =IF(LEFT(CT!$E6,4)="5112",CT!$H6,0) -> 0 | G8: =IF(LEFT(CT!$E6,4)="5113",CT!$H6,0) -> 0
A9: =IF(AND(LEFT(CT!$D7,3)=NKBH!$E$2,LEFT(CT!$E7,3)="511"),CT!A7,"") | B9: =IF(AND(LEFT(CT!$D7,3)=NKBH!$E$2,LEFT(CT!$E7,3)="511"),CT!B7,"") | C9: =IF(AND(LEFT(CT!$D7,3)=NKBH!$E$2,LEFT(CT!$E7,3)="511"),CT!C7,"") | D9: =IF(AND(LEFT(CT!$D7,3)=NKBH!$E$2,LEFT(CT!$E7,3)="511"),CT!H7,"") | E9: =IF(LEFT(CT!$E7,4)="5111",CT!$H7,0) -> 0 | F9: =IF(LEFT(CT!$E7,4)="5112",CT!$H7,0) -> 0 | G9: =IF(LEFT(CT!$E7,4)="5113",CT!$H7,0) -> 0
